Workbook

Sheet GAS CAL
B5: GAS FACTOR
B6: Measured temperature | E6: 45.33 | F6: Range (0°C-50°C)
B7: Density (20°C) | E7: 0.5534 | F7: Range (0.5-0.590)
B8: FACTOR @(20°C) | E8: =E128 -> 0.94036
B10: DENSITY @15°C to @20°C
B11: Density @15°C | E11: 0.5578 | F11: Range (0.5-0.6)
B12: Density @20°C | E12: =(E11-ROUNDDOWN(E11,3))+VLOOKUP((ROUNDDOWN(E11,3)),B138:C502,2,FALSE) -> 0.5516
A19: ©Kaiza|Muhidini
B21: DENSITY (KG/LITRE)
A22: TEMP | B22: 0.5 | C22: 0.51 | D22: 0.52 | E22: 0.53 | F22: 0.54 | G22: 0.55 | H22: 0.56 | I22: 0.57 | J22: 0.58 | K22: 0.59
A23: 0 | B23: 1.058 | C23: 1.055 | D23: 1.052 | E23: 1.049 | F23: 1.047 | G23: 1.044 | H23: 1.042 | I23: 1.04 | J23: 1.038 | K23: 1.036
A24: 0.5 | B24: 1.057 | C24: 1.054 | D24: 1.051 | E24: 1.048 | F24: 1.046 | G24: 1.043 | H24: 1.041 | I24: 1.039 | J24: 1.037 | K24: 1.035
A25: 1 | B25: 1.055 | C25: 1.052 | D25: 1.05 | E25: 1.047 | F25: 1.044 | G25: 1.042 | H25: 1.04 | I25: 1.038 | J25: 1.036 | K25: 1.034
A26: 1.5 | B26: 1.054 | C26: 1.051 | D26: 1.046 | E26: 1.046 | F26: 1.043 | G26: 1.041 | H26: 1.039 | I26: 1.037 | J26: 1.035 | K26: 1.033
A27: 2 | B27: 1.052 | C27: 1.05 | D27: 1.047 | E27: 1.045 | F27: 1.042 | G27: 1.04 | H27: 1.038 | I27: 1.036 | J27: 1.034 | K27: 1.032
A28: 2.5 | B28: 1.051 | C28: 1.048 | D28: 1.46 | E28: 1.043 | F28: 1.041 | G28: 1.039 | H28: 1.037 | I28: 1.035 | J28: 1.033 | K28: 1.032
A29: 3 | B29: 1.05 | C29: 1.047 | D29: 1.045 | E29: 1.042 | F29: 1.04 | G29: 1.038 | H29: 1.036 | I29: 1.034 | J29: 1.033 | K29: 1.031
A30: 3.5 | B30: 1.048 | C30: 1.046 | D30: 1.043 | E30: 1.041 | F30: 1.039 | G30: 1.037 | H30: 1.035 | I30: 1.033 | J30: 1.032 | K30: 1.03
A31: 4 | B31: 1.047 | C31: 1.044 | D31: 1.042 | E31: 1.04 | F31: 1.038 | G31: 1.036 | H31: 1.034 | I31: 1.032 | J31: 1.031 | K31: 1.029
A32: 4.5 | B32: 1.045 | C32: 1.043 | D32: 1.041 | E32: 1.039 | F32: 1.037 | G32: 1.035 | H32: 1.033 | I32: 1.031 | J32: 1.03 | K32: 1.028
A33: 5 | B33: 1.044 | C33: 1.042 | D33: 1.039 | E33: 1.037 | F33: 1.035 | G33: 1.034 | H33: 1.032 | I33: 1.03 | J33: 1.029 | K33: 1.027
A34: 5.5 | B34: 1.043 | C34: 1.04 | D34: 1.038 | E34: 1.036 | F34: 1.034 | G34: 1.032 | H34: 1.031 | I34: 1.029 | J34: 1.028 | K34: 1.026
... A123: 50 | B123: 0.9 | C123: 0.906 | D123: 0.912 | E123: 0.917 | F123: 0.923 | G123: 0.927 | H123: 0.931 | I123: 0.935 | J123: 0.939 | K123: 0.944
D126: =ROUND(ROUNDDOWN(E126,2),2) -> 0.55 | E126: =E7 -> 0.5534 | F126: =ROUND(ROUNDUP(E126,2),2) -> 0.56 | J126: DENSITY | K126: 0.573
C127: =ROUNDDOWN($C$128*2,0)/2 -> 45 | D127: =INDEX($B$23:$K$123,MATCH($C127,$A$23:$A$123,0),MATCH(D$126,$B$22:$K$22,0)) -> 0.94 | E127: =F127-((F127-D127)*(F126-E126))/(IF((F126-D126)=0,1,(F126-D126))) -> 0.94102 | F127: =INDEX($B$23:$K$123,MATCH($C127,$A$23:$A$123,0),MATCH(F$126,$B$22:$K$22,0)) -> 0.943 | J127: TEMP | K127: 24.25
C128: =E6 -> 45.33 | E128: =E127+(C128-C127)*(E129-E127)/(IF((C129-C127)=0,1,(C129-C127))) -> 0.94036
C129: =ROUNDUP(C128*2,0)/2 -> 45.5 | D129: =INDEX($B$23:$K$123,MATCH($C129,$A$23:$A$123,0),MATCH(D$126,$B$22:$K$22,0)) -> 0.939 | E129: =F129-((F129-D129)*(F126-E126))/(IF((F126-D126)=0,1,(F126-D126))) -> 0.94002 | F129: =INDEX($B$23:$K$123,MATCH($C129,$A$23:$A$123,0),MATCH(F$126,$B$22:$K$22,0)) -> 0.942 | J129: VCF @20C | K129: =E128 -> 0.94036
B133: DENSITY | C133: DENSITY
C134: KG
B135: KG/LITRE | C135: PER
C136: LITRE
B137: 15 ⁰C | C137: AT 20⁰ C
B138: 0.5 | C138: 0.4922
B139: 0.501 | C139: 0.4932
B140: 0.502 | C140: 0.4943
B141: 0.503 | C141: 0.4953
B142: 0.504 | C142: 0.4963
B143: 0.505 | C143: 0.4974
B144: 0.506 | C144: 0.4984
B145: 0.507 | C145: 0.4994
...

Sheet OIL-S.Tank
B5: Calculation of Density @20 °C
B6: Sample Temperature | D6: 28.5 | F6: °C | K6: °C | L6: =IF(K6=F6,D6,L7) -> 28.5 | N6: kg/litre | O6: =IF(N6=F7,D7,O7) -> 0.721
B7: Sample Density | D7: 0.721 | F7: kg/litre | K7: °F | L7: =IF(K6=F6," ",(D6-32)*5/9) | M7: °F to °C | N7: API Gravity | O7: =IF(N6=F7," ",141.5/(131.5+D7)) | P7: API to kg/litre
B8: Corrected Density | D8: =IFERROR('Table 59B'!E4,"Unit&Range!") -> 0.72869 | F8: Table 59B (at 20 °C) in kg/litre
B10: Factors Calculator
B11: Corrected Density | D11: 0.7288 | F11: kg/litre
B12: Tank Temperature | D12: 29 | F12: °C | K12: °C | L12: =IF(K12=F12,D12,L13) -> 29
B13: Correction Factor (VCF) | D13: ='Table 60B'!E4 -> 0.988664 | F13: Table 60B | K13: °F | L13: =IF(K12=F12," ",(D12-32)*5/9) | M13: °F to °C
B14: Ltrs @ 20°C to USGAL | D14: =VLOOKUP(D11,'Table D'!B2:D54,3,TRUE) -> 3.8045 | F14: Table D
B15: Ltrs @ 20°C to USBBL | D15: =VLOOKUP(D11,'Table D'!B2:D54,2,TRUE) -> 159.79 | F15: Table D
B16: LongTon | D16: 0.984206
B18: Interpolation
B19: Lower Parameter 01 | D19: 1755 | F19: Parameter 02 | I19: 8500
B20: Actual Parameter 01 | D20: 1757 | F20: Calculated Parameter 02 | I20: =IFERROR(I19+(((D20-D19)*(I21-I19))/(D21-D19))," ") -> 8509.434
B21: Higher Parameter 01 | D21: 1861 | F21: Parameter 02 | I21: 9000
B23: Density at 15°C to Density at 20°C
B24: Density at 15°C | D24: 0.7834
B25: Density at 20°C | D25: =(D24-ROUNDDOWN(D24,3))+VLOOKUP((ROUNDDOWN(D24,3)),'Table D'!G7:H371,2,FALSE) -> 0.7796
B27: ©Godlove Kaiza

Sheet OIL-V.Tanks
C4: Density @15°C | D4: Density @20°C
C5: 0.8426 | D5: 0.8381
B7: Temp OC | C7: V.C.F T-54B | D7: V.C.F T-60B | E7: Tank # | G7: Density at 15°C to Density at 20°C
B8: 28.8 | C8: =Z8 -> 0.9884 | D8: =AA8 -> 0.9925 | E8: 1P | G8: Density at 15°C | I8: 0.8426 | L8: =$C$5 -> 0.8426 | M8: =ROUND(B8*4,0)/4 -> 28.75 | N8: =2*ROUND((L8*1000/2),0) -> 842 | O8: =ROUND((186.9696/N8^2)+(0.4862/N8),7) -> 0.0008412 | P8: =ROUND((594.5418/N8^2)+(0/N8),7) -> 0.0008386 | Q8: =ROUND(-0.00336312+2680.3206/N8^2,7) -> 0.0004175 | R8: =ROUND((346.4228/N8^2)+(0.4388/N8),7) -> 0.0010098 | S8: =ROUND(M8-15,2) -> 13.75 | T8: =IF(L8<0.7705,R8,IF(L8<0.7875,Q8,IF(L8<0.839,P8,IF(L8<1.075,O8,"ERR")))) -> 0.0008412 | U8: =ROUND(T8*S8,8) -> 0.0115665 | V8: =ROUND(T8*S8*0.8,8) -> 0.0092532 | W8: =ROUND(T8^2*S8^2*0.8,9) -> 0.000107027 | X8: =ROUND(-U8-W8,8) -> -0.01167353 | Y8: =EXP(X8) -> 0.98839434 | Z8: =ROUND(Y8,4) -> 0.9884 | AA8: =IF($D$5=0,0,TRUNC(EXP(-AF8*(B8-20)-0.8*(AF8*(B8-20))^2)*10^4+0.5)/10^4) -> 0.9925 | AB8: =IF($D$5>=0.653,IF($D$5<=0.77,TRUNC((346.4228/($D$5*1000)^2+0.4388/($D$5*1000))*10^7+0.5)/10^7,0),0) -> 0 | AC8: =IF($D$5>0.77,IF($D$5<0.788,TRUNC((-0.00336312+2680.3206/($D$5*1000)^2)*10^7+0.5)/10^7,0),0) -> 0 | AD8: =IF($D$5>=0.788,IF($D$5<0.839,TRUNC(594.5418/($D$5*1000)^2*10^7+0.5)/10^7,0),0) -> 0.0008464 | AE8: =IF($D$5>=0.839,IF($D$5<1.075,TRUNC((186.9696/($D$5*1000)^2+0.4862/($D$5*1000))*10^7+0.5)/10^7,0),0) -> 0 | AF8: =SUM(AB8:AE8) -> 0.0008464
B9: 31 | C9: =Z9 -> 0.9865 | D9: =AA9 -> 0.9907 | E9: 1S | G9: Density at 20°C | I9: =(I8-ROUNDDOWN(I8,3))+VLOOKUP((ROUNDDOWN(I8,3)),'Table D'!G7:H371,2,FALSE) -> 0.8392 | L9: =$C$5 -> 0.8426 | M9: =ROUND(B9*4,0)/4 -> 31 | N9: =2*ROUND((L9*1000/2),0) -> 842 | O9: =ROUND((186.9696/N9^2)+(0.4862/N9),7) -> 0.0008412 | P9: =ROUND((594.5418/N9^2)+(0/N9),7) -> 0.0008386 | Q9: =ROUND(-0.00336312+2680.3206/N9^2,7) -> 0.0004175 | R9: =ROUND((346.4228/N9^2)+(0.4388/N9),7) -> 0.0010098 | S9: =ROUND(M9-15,2) -> 16 | T9: =IF(L9<0.7705,R9,IF(L9<0.7875,Q9,IF(L9<0.839,P9,IF(L9<1.075,O9,"ERR")))) -> 0.0008412 | U9: =ROUND(T9*S9,8) -> 0.0134592 | V9: =ROUND(T9*S9*0.8,8) -> 0.01076736 | W9: =ROUND(T9^2*S9^2*0.8,9) -> 0.00014492 | X9: =ROUND(-U9-W9,8) -> -0.01360412 | Y9: =EXP(X9) -> 0.986488 | Z9: =ROUND(Y9,4) -> 0.9865 | AA9: =IF($D$5=0,0,TRUNC(EXP(-AF9*(B9-20)-0.8*(AF9*(B9-20))^2)*10^4+0.5)/10^4) -> 0.9907 | AB9: =IF($D$5>=0.653,IF($D$5<=0.77,TRUNC((346.4228/($D$5*1000)^2+0.4388/($D$5*1000))*10^7+0.5)/10^7,0),0) -> 0 | AC9: =IF($D$5>0.77,IF($D$5<0.788,TRUNC((-0.00336312+2680.3206/($D$5*1000)^2)*10^7+0.5)/10^7,0),0) -> 0 | AD9: =IF($D$5>=0.788,IF($D$5<0.839,TRUNC(594.5418/($D$5*1000)^2*10^7+0.5)/10^7,0),0) -> 0.0008464 | AE9: =IF($D$5>=0.839,IF($D$5<1.075,TRUNC((186.9696/($D$5*1000)^2+0.4862/($D$5*1000))*10^7+0.5)/10^7,0),0) -> 0 | AF9: =SUM(AB9:AE9) -> 0.0008464
B10: 34 | C10: =Z10 -> 0.9839 | D10: =AA10 -> 0.9881 | E10: 2P | L10: =$C$5 -> 0.8426 | M10: =ROUND(B10*4,0)/4 -> 34 | N10: =2*ROUND((L10*1000/2),0) -> 842 | O10: =ROUND((186.9696/N10^2)+(0.4862/N10),7) -> 0.0008412 | P10: =ROUND((594.5418/N10^2)+(0/N10),7) -> 0.0008386 | Q10: =ROUND(-0.00336312+2680.3206/N10^2,7) -> 0.0004175 | R10: =ROUND((346.4228/N10^2)+(0.4388/N10),7) -> 0.0010098 | S10: =ROUND(M10-15,2) -> 19 | T10: =IF(L10<0.7705,R10,IF(L10<0.7875,Q10,IF(L10<0.839,P10,IF(L10<1.075,O10,"ERR")))) -> 0.0008412 | U10: =ROUND(T10*S10,8) -> 0.0159828 | V10: =ROUND(T10*S10*0.8,8) -> 0.01278624 | W10: =ROUND(T10^2*S10^2*0.8,9) -> 0.00020436 | X10: =ROUND(-U10-W10,8) -> -0.01618716 | Y10: =EXP(X10) -> 0.98394315 | Z10: =ROUND(Y10,4) -> 0.9839 | AA10: =IF($D$5=0,0,TRUNC(EXP(-AF10*(B10-20)-0.8*(AF10*(B10-20))^2)*10^4+0.5)/10^4) -> 0.9881 | AB10: =IF($D$5>=0.653,IF($D$5<=0.77,TRUNC((346.4228/($D$5*1000)^2+0.4388/($D$5*1000))*10^7+0.5)/10^7,0),0) -> 0 | AC10: =IF($D$5>0.77,IF($D$5<0.788,TRUNC((-0.00336312+2680.3206/($D$5*1000)^2)*10^7+0.5)/10^7,0),0) -> 0 | AD10: =IF($D$5>=0.788,IF($D$5<0.839,TRUNC(594.5418/($D$5*1000)^2*10^7+0.5)/10^7,0),0) -> 0.0008464 | AE10: =IF($D$5>=0.839,IF($D$5<1.075,TRUNC((186.9696/($D$5*1000)^2+0.4862/($D$5*1000))*10^7+0.5)/10^7,0),0) -> 0 | AF10: =SUM(AB10:AE10) -> 0.0008464
B11: 11 | C11: =Z11 -> 1.0034 | D11: =AA11 -> 1.0076 | E11: 2S | G11: Table D | L11: =$C$5 -> 0.8426 | M11: =ROUND(B11*4,0)/4 -> 11 | N11: =2*ROUND((L11*1000/2),0) -> 842 | O11: =ROUND((186.9696/N11^2)+(0.4862/N11),7) -> 0.0008412 | P11: =ROUND((594.5418/N11^2)+(0/N11),7) -> 0.0008386 | Q11: =ROUND(-0.00336312+2680.3206/N11^2,7) -> 0.0004175 | R11: =ROUND((346.4228/N11^2)+(0.4388/N11),7) -> 0.0010098 | S11: =ROUND(M11-15,2) -> -4 | T11: =IF(L11<0.7705,R11,IF(L11<0.7875,Q11,IF(L11<0.839,P11,IF(L11<1.075,O11,"ERR")))) -> 0.0008412 | U11: =ROUND(T11*S11,8) -> -0.0033648 | V11: =ROUND(T11*S11*0.8,8) -> -0.00269184 | W11: =ROUND(T11^2*S11^2*0.8,9) -> 9.058e-06 | X11: =ROUND(-U11-W11,8) -> 0.00335574 | Y11: =EXP(X11) -> 1.0033614 | Z11: =ROUND(Y11,4) -> 1.0034 | AA11: =IF($D$5=0,0,TRUNC(EXP(-AF11*(B11-20)-0.8*(AF11*(B11-20))^2)*10^4+0.5)/10^4) -> 1.0076 | AB11: =IF($D$5>=0.653,IF($D$5<=0.77,TRUNC((346.4228/($D$5*1000)^2+0.4388/($D$5*1000))*10^7+0.5)/10^7,0),0) -> 0 | AC11: =IF($D$5>0.77,IF($D$5<0.788,TRUNC((-0.00336312+2680.3206/($D$5*1000)^2)*10^7+0.5)/10^7,0),0) -> 0 | AD11: =IF($D$5>=0.788,IF($D$5<0.839,TRUNC(594.5418/($D$5*1000)^2*10^7+0.5)/10^7,0),0) -> 0.0008464 | AE11: =IF($D$5>=0.839,IF($D$5<1.075,TRUNC((186.9696/($D$5*1000)^2+0.4862/($D$5*1000))*10^7+0.5)/10^7,0),0) -> 0 | AF11: =SUM(AB11:AE11) -> 0.0008464
B12: 23 | C12: =Z12 -> 0.9933 | D12: =AA12 -> 0.9975 | E12: 3P | G12: Corrected Density | I12: 0.8392 | L12: =$C$5 -> 0.8426 | M12: =ROUND(B12*4,0)/4 -> 23 | N12: =2*ROUND((L12*1000/2),0) -> 842 | O12: =ROUND((186.9696/N12^2)+(0.4862/N12),7) -> 0.0008412 | P12: =ROUND((594.5418/N12^2)+(0/N12),7) -> 0.0008386 | Q12: =ROUND(-0.00336312+2680.3206/N12^2,7) -> 0.0004175 | R12: =ROUND((346.4228/N12^2)+(0.4388/N12),7) -> 0.0010098 | S12: =ROUND(M12-15,2) -> 8 | T12: =IF(L12<0.7705,R12,IF(L12<0.7875,Q12,IF(L12<0.839,P12,IF(L12<1.075,O12,"ERR")))) -> 0.0008412 | U12: =ROUND(T12*S12,8) -> 0.0067296 | V12: =ROUND(T12*S12*0.8,8) -> 0.00538368 | W12: =ROUND(T12^2*S12^2*0.8,9) -> 3.623e-05 | X12: =ROUND(-U12-W12,8) -> -0.00676583 | Y12: =EXP(X12) -> 0.99325701 | Z12: =ROUND(Y12,4) -> 0.9933 | AA12: =IF($D$5=0,0,TRUNC(EXP(-AF12*(B12-20)-0.8*(AF12*(B12-20))^2)*10^4+0.5)/10^4) -> 0.9975 | AB12: =IF($D$5>=0.653,IF($D$5<=0.77,TRUNC((346.4228/($D$5*1000)^2+0.4388/($D$5*1000))*10^7+0.5)/10^7,0),0) -> 0 | AC12: =IF($D$5>0.77,IF($D$5<0.788,TRUNC((-0.00336312+2680.3206/($D$5*1000)^2)*10^7+0.5)/10^7,0),0) -> 0 | AD12: =IF($D$5>=0.788,IF($D$5<0.839,TRUNC(594.5418/($D$5*1000)^2*10^7+0.5)/10^7,0),0) -> 0.0008464 | AE12: =IF($D$5>=0.839,IF($D$5<1.075,TRUNC((186.9696/($D$5*1000)^2+0.4862/($D$5*1000))*10^7+0.5)/10^7,0),0) -> 0 | AF12: =SUM(AB12:AE12) -> 0.0008464
B13: 34 | C13: =Z13 -> 0.9839 | D13: =AA13 -> 0.9881 | E13: 3S | G13: Ltrs @ 20°C to USGAL | I13: =VLOOKUP(I12,'Table D'!B1:D53,3,TRUE) -> 3.7991 | L13: =$C$5 -> 0.8426 | M13: =ROUND(B13*4,0)/4 -> 34 | N13: =2*ROUND((L13*1000/2),0) -> 842 | O13: =ROUND((186.9696/N13^2)+(0.4862/N13),7) -> 0.0008412 | P13: =ROUND((594.5418/N13^2)+(0/N13),7) -> 0.0008386 | Q13: =ROUND(-0.00336312+2680.3206/N13^2,7) -> 0.0004175 | R13: =ROUND((346.4228/N13^2)+(0.4388/N13),7) -> 0.0010098 | S13: =ROUND(M13-15,2) -> 19 | T13: =IF(L13<0.7705,R13,IF(L13<0.7875,Q13,IF(L13<0.839,P13,IF(L13<1.075,O13,"ERR")))) -> 0.0008412 | U13: =ROUND(T13*S13,8) -> 0.0159828 | V13: =ROUND(T13*S13*0.8,8) -> 0.01278624 | W13: =ROUND(T13^2*S13^2*0.8,9) -> 0.00020436 | X13: =ROUND(-U13-W13,8) -> -0.01618716 | Y13: =EXP(X13) -> 0.98394315 | Z13: =ROUND(Y13,4) -> 0.9839 | AA13: =IF($D$5=0,0,TRUNC(EXP(-AF13*(B13-20)-0.8*(AF13*(B13-20))^2)*10^4+0.5)/10^4) -> 0.9881 | AB13: =IF($D$5>=0.653,IF($D$5<=0.77,TRUNC((346.4228/($D$5*1000)^2+0.4388/($D$5*1000))*10^7+0.5)/10^7,0),0) -> 0 | AC13: =IF($D$5>0.77,IF($D$5<0.788,TRUNC((-0.00336312+2680.3206/($D$5*1000)^2)*10^7+0.5)/10^7,0),0) -> 0 | AD13: =IF($D$5>=0.788,IF($D$5<0.839,TRUNC(594.5418/($D$5*1000)^2*10^7+0.5)/10^7,0),0) -> 0.0008464 | AE13: =IF($D$5>=0.839,IF($D$5<1.075,TRUNC((186.9696/($D$5*1000)^2+0.4862/($D$5*1000))*10^7+0.5)/10^7,0),0) -> 0 | AF13: =SUM(AB13:AE13) -> 0.0008464
B14: 31 | C14: =Z14 -> 0.9865 | D14: =AA14 -> 0.9907 | E14: 4P | G14: Ltrs @ 20°C to USBBL | I14: =VLOOKUP(I12,'Table D'!B1:D53,2,TRUE) -> 159.56 | L14: =$C$5 -> 0.8426 | M14: =ROUND(B14*4,0)/4 -> 31 | N14: =2*ROUND((L14*1000/2),0) -> 842 | O14: =ROUND((186.9696/N14^2)+(0.4862/N14),7) -> 0.0008412 | P14: =ROUND((594.5418/N14^2)+(0/N14),7) -> 0.0008386 | Q14: =ROUND(-0.00336312+2680.3206/N14^2,7) -> 0.0004175 | R14: =ROUND((346.4228/N14^2)+(0.4388/N14),7) -> 0.0010098 | S14: =ROUND(M14-15,2) -> 16 | T14: =IF(L14<0.7705,R14,IF(L14<0.7875,Q14,IF(L14<0.839,P14,IF(L14<1.075,O14,"ERR")))) -> 0.0008412 | U14: =ROUND(T14*S14,8) -> 0.0134592 | V14: =ROUND(T14*S14*0.8,8) -> 0.01076736 | W14: =ROUND(T14^2*S14^2*0.8,9) -> 0.00014492 | X14: =ROUND(-U14-W14,8) -> -0.01360412 | Y14: =EXP(X14) -> 0.986488 | Z14: =ROUND(Y14,4) -> 0.9865 | AA14: =IF($D$5=0,0,TRUNC(EXP(-AF14*(B14-20)-0.8*(AF14*(B14-20))^2)*10^4+0.5)/10^4) -> 0.9907 | AB14: =IF($D$5>=0.653,IF($D$5<=0.77,TRUNC((346.4228/($D$5*1000)^2+0.4388/($D$5*1000))*10^7+0.5)/10^7,0),0) -> 0 | AC14: =IF($D$5>0.77,IF($D$5<0.788,TRUNC((-0.00336312+2680.3206/($D$5*1000)^2)*10^7+0.5)/10^7,0),0) -> 0 | AD14: =IF($D$5>=0.788,IF($D$5<0.839,TRUNC(594.5418/($D$5*1000)^2*10^7+0.5)/10^7,0),0) -> 0.0008464 | AE14: =IF($D$5>=0.839,IF($D$5<1.075,TRUNC((186.9696/($D$5*1000)^2+0.4862/($D$5*1000))*10^7+0.5)/10^7,0),0) -> 0 | AF14: =SUM(AB14:AE14) -> 0.0008464
B15: 28.8 | C15: =Z15 -> 0.9884 | D15: =AA15 -> 0.9925 | E15: 4S | G15: LongTon | I15: 0.984206 | L15: =$C$5 -> 0.8426 | M15: =ROUND(B15*4,0)/4 -> 28.75 | N15: =2*ROUND((L15*1000/2),0) -> 842 | O15: =ROUND((186.9696/N15^2)+(0.4862/N15),7) -> 0.0008412 | P15: =ROUND((594.5418/N15^2)+(0/N15),7) -> 0.0008386 | Q15: =ROUND(-0.00336312+2680.3206/N15^2,7) -> 0.0004175 | R15: =ROUND((346.4228/N15^2)+(0.4388/N15),7) -> 0.0010098 | S15: =ROUND(M15-15,2) -> 13.75 | T15: =IF(L15<0.7705,R15,IF(L15<0.7875,Q15,IF(L15<0.839,P15,IF(L15<1.075,O15,"ERR")))) -> 0.0008412 | U15: =ROUND(T15*S15,8) -> 0.0115665 | V15: =ROUND(T15*S15*0.8,8) -> 0.0092532 | W15: =ROUND(T15^2*S15^2*0.8,9) -> 0.000107027 | X15: =ROUND(-U15-W15,8) -> -0.01167353 | Y15: =EXP(X15) -> 0.98839434 | Z15: =ROUND(Y15,4) -> 0.9884 | AA15: =IF($D$5=0,0,TRUNC(EXP(-AF15*(B15-20)-0.8*(AF15*(B15-20))^2)*10^4+0.5)/10^4) -> 0.9925 | AB15: =IF($D$5>=0.653,IF($D$5<=0.77,TRUNC((346.4228/($D$5*1000)^2+0.4388/($D$5*1000))*10^7+0.5)/10^7,0),0) -> 0 | AC15: =IF($D$5>0.77,IF($D$5<0.788,TRUNC((-0.00336312+2680.3206/($D$5*1000)^2)*10^7+0.5)/10^7,0),0) -> 0 | AD15: =IF($D$5>=0.788,IF($D$5<0.839,TRUNC(594.5418/($D$5*1000)^2*10^7+0.5)/10^7,0),0) -> 0.0008464 | AE15: =IF($D$5>=0.839,IF($D$5<1.075,TRUNC((186.9696/($D$5*1000)^2+0.4862/($D$5*1000))*10^7+0.5)/10^7,0),0) -> 0 | AF15: =SUM(AB15:AE15) -> 0.0008464
B16: 28.8 | C16: =Z16 -> 0.9884 | D16: =AA16 -> 0.9925 | E16: 5P | L16: =$C$5 -> 0.8426 | M16: =ROUND(B16*4,0)/4 -> 28.75 | N16: =2*ROUND((L16*1000/2),0) -> 842 | O16: =ROUND((186.9696/N16^2)+(0.4862/N16),7) -> 0.0008412 | P16: =ROUND((594.5418/N16^2)+(0/N16),7) -> 0.0008386 | Q16: =ROUND(-0.00336312+2680.3206/N16^2,7) -> 0.0004175 | R16: =ROUND((346.4228/N16^2)+(0.4388/N16),7) -> 0.0010098 | S16: =ROUND(M16-15,2) -> 13.75 | T16: =IF(L16<0.7705,R16,IF(L16<0.7875,Q16,IF(L16<0.839,P16,IF(L16<1.075,O16,"ERR")))) -> 0.0008412 | U16: =ROUND(T16*S16,8) -> 0.0115665 | V16: =ROUND(T16*S16*0.8,8) -> 0.0092532 | W16: =ROUND(T16^2*S16^2*0.8,9) -> 0.000107027 | X16: =ROUND(-U16-W16,8) -> -0.01167353 | Y16: =EXP(X16) -> 0.98839434 | Z16: =ROUND(Y16,4) -> 0.9884 | AA16: =IF($D$5=0,0,TRUNC(EXP(-AF16*(B16-20)-0.8*(AF16*(B16-20))^2)*10^4+0.5)/10^4) -> 0.9925 | AB16: =IF($D$5>=0.653,IF($D$5<=0.77,TRUNC((346.4228/($D$5*1000)^2+0.4388/($D$5*1000))*10^7+0.5)/10^7,0),0) -> 0 | AC16: =IF($D$5>0.77,IF($D$5<0.788,TRUNC((-0.00336312+2680.3206/($D$5*1000)^2)*10^7+0.5)/10^7,0),0) -> 0 | AD16: =IF($D$5>=0.788,IF($D$5<0.839,TRUNC(594.5418/($D$5*1000)^2*10^7+0.5)/10^7,0),0) -> 0.0008464 | AE16: =IF($D$5>=0.839,IF($D$5<1.075,TRUNC((186.9696/($D$5*1000)^2+0.4862/($D$5*1000))*10^7+0.5)/10^7,0),0) -> 0 | AF16: =SUM(AB16:AE16) -> 0.0008464
B17: 23 | C17: =Z17 -> 0.9933 | D17: =AA17 -> 0.9975 | E17: 5S | L17: =$C$5 -> 0.8426 | M17: =ROUND(B17*4,0)/4 -> 23 | N17: =2*ROUND((L17*1000/2),0) -> 842 | O17: =ROUND((186.9696/N17^2)+(0.4862/N17),7) -> 0.0008412 | P17: =ROUND((594.5418/N17^2)+(0/N17),7) -> 0.0008386 | Q17: =ROUND(-0.00336312+2680.3206/N17^2,7) -> 0.0004175 | R17: =ROUND((346.4228/N17^2)+(0.4388/N17),7) -> 0.0010098 | S17: =ROUND(M17-15,2) -> 8 | T17: =IF(L17<0.7705,R17,IF(L17<0.7875,Q17,IF(L17<0.839,P17,IF(L17<1.075,O17,"ERR")))) -> 0.0008412 | U17: =ROUND(T17*S17,8) -> 0.0067296 | V17: =ROUND(T17*S17*0.8,8) -> 0.00538368 | W17: =ROUND(T17^2*S17^2*0.8,9) -> 3.623e-05 | X17: =ROUND(-U17-W17,8) -> -0.00676583 | Y17: =EXP(X17) -> 0.99325701 | Z17: =ROUND(Y17,4) -> 0.9933 | AA17: =IF($D$5=0,0,TRUNC(EXP(-AF17*(B17-20)-0.8*(AF17*(B17-20))^2)*10^4+0.5)/10^4) -> 0.9975 | AB17: =IF($D$5>=0.653,IF($D$5<=0.77,TRUNC((346.4228/($D$5*1000)^2+0.4388/($D$5*1000))*10^7+0.5)/10^7,0),0) -> 0 | AC17: =IF($D$5>0.77,IF($D$5<0.788,TRUNC((-0.00336312+2680.3206/($D$5*1000)^2)*10^7+0.5)/10^7,0),0) -> 0 | AD17: =IF($D$5>=0.788,IF($D$5<0.839,TRUNC(594.5418/($D$5*1000)^2*10^7+0.5)/10^7,0),0) -> 0.0008464 | AE17: =IF($D$5>=0.839,IF($D$5<1.075,TRUNC((186.9696/($D$5*1000)^2+0.4862/($D$5*1000))*10^7+0.5)/10^7,0),0) -> 0 | AF17: =SUM(AB17:AE17) -> 0.0008464
B18: 34 | C18: =Z18 -> 0.9839 | D18: =AA18 -> 0.9881 | E18: 6P | L18: =$C$5 -> 0.8426 | M18: =ROUND(B18*4,0)/4 -> 34 | N18: =2*ROUND((L18*1000/2),0) -> 842 | O18: =ROUND((186.9696/N18^2)+(0.4862/N18),7) -> 0.0008412 | P18: =ROUND((594.5418/N18^2)+(0/N18),7) -> 0.0008386 | Q18: =ROUND(-0.00336312+2680.3206/N18^2,7) -> 0.0004175 | R18: =ROUND((346.4228/N18^2)+(0.4388/N18),7) -> 0.0010098 | S18: =ROUND(M18-15,2) -> 19 | T18: =IF(L18<0.7705,R18,IF(L18<0.7875,Q18,IF(L18<0.839,P18,IF(L18<1.075,O18,"ERR")))) -> 0.0008412 | U18: =ROUND(T18*S18,8) -> 0.0159828 | V18: =ROUND(T18*S18*0.8,8) -> 0.01278624 | W18: =ROUND(T18^2*S18^2*0.8,9) -> 0.00020436 | X18: =ROUND(-U18-W18,8) -> -0.01618716 | Y18: =EXP(X18) -> 0.98394315 | Z18: =ROUND(Y18,4) -> 0.9839 | AA18: =IF($D$5=0,0,TRUNC(EXP(-AF18*(B18-20)-0.8*(AF18*(B18-20))^2)*10^4+0.5)/10^4) -> 0.9881 | AB18: =IF($D$5>=0.653,IF($D$5<=0.77,TRUNC((346.4228/($D$5*1000)^2+0.4388/($D$5*1000))*10^7+0.5)/10^7,0),0) -> 0 | AC18: =IF($D$5>0.77,IF($D$5<0.788,TRUNC((-0.00336312+2680.3206/($D$5*1000)^2)*10^7+0.5)/10^7,0),0) -> 0 | AD18: =IF($D$5>=0.788,IF($D$5<0.839,TRUNC(594.5418/($D$5*1000)^2*10^7+0.5)/10^7,0),0) -> 0.0008464 | AE18: =IF($D$5>=0.839,IF($D$5<1.075,TRUNC((186.9696/($D$5*1000)^2+0.4862/($D$5*1000))*10^7+0.5)/10^7,0),0) -> 0 | AF18: =SUM(AB18:AE18) -> 0.0008464
B19: 32 | C19: =Z19 -> 0.9856 | D19: =AA19 -> 0.9898 | E19: 6S | L19: =$C$5 -> 0.8426 | M19: =ROUND(B19*4,0)/4 -> 32 | N19: =2*ROUND((L19*1000/2),0) -> 842 | O19: =ROUND((186.9696/N19^2)+(0.4862/N19),7) -> 0.0008412 | P19: =ROUND((594.5418/N19^2)+(0/N19),7) -> 0.0008386 | Q19: =ROUND(-0.00336312+2680.3206/N19^2,7) -> 0.0004175 | R19: =ROUND((346.4228/N19^2)+(0.4388/N19),7) -> 0.0010098 | S19: =ROUND(M19-15,2) -> 17 | T19: =IF(L19<0.7705,R19,IF(L19<0.7875,Q19,IF(L19<0.839,P19,IF(L19<1.075,O19,"ERR")))) -> 0.0008412 | U19: =ROUND(T19*S19,8) -> 0.0143004 | V19: =ROUND(T19*S19*0.8,8) -> 0.01144032 | W19: =ROUND(T19^2*S19^2*0.8,9) -> 0.000163601 | X19: =ROUND(-U19-W19,8) -> -0.014464 | Y19: =EXP(X19) -> 0.9856401 | Z19: =ROUND(Y19,4) -> 0.9856 | AA19: =IF($D$5=0,0,TRUNC(EXP(-AF19*(B19-20)-0.8*(AF19*(B19-20))^2)*10^4+0.5)/10^4) -> 0.9898 | AB19: =IF($D$5>=0.653,IF($D$5<=0.77,TRUNC((346.4228/($D$5*1000)^2+0.4388/($D$5*1000))*10^7+0.5)/10^7,0),0) -> 0 | AC19: =IF($D$5>0.77,IF($D$5<0.788,TRUNC((-0.00336312+2680.3206/($D$5*1000)^2)*10^7+0.5)/10^7,0),0) -> 0 | AD19: =IF($D$5>=0.788,IF($D$5<0.839,TRUNC(594.5418/($D$5*1000)^2*10^7+0.5)/10^7,0),0) -> 0.0008464 | AE19: =IF($D$5>=0.839,IF($D$5<1.075,TRUNC((186.9696/($D$5*1000)^2+0.4862/($D$5*1000))*10^7+0.5)/10^7,0),0) -> 0 | AF19: =SUM(AB19:AE19) -> 0.0008464
B20: 28.8 | C20: =Z20 -> 0.9884 | D20: =AA20 -> 0.9925 | E20: SLOP P | L20: =$C$5 -> 0.8426 | M20: =ROUND(B20*4,0)/4 -> 28.75 | N20: =2*ROUND((L20*1000/2),0) -> 842 | O20: =ROUND((186.9696/N20^2)+(0.4862/N20),7) -> 0.0008412 | P20: =ROUND((594.5418/N20^2)+(0/N20),7) -> 0.0008386 | Q20: =ROUND(-0.00336312+2680.3206/N20^2,7) -> 0.0004175 | R20: =ROUND((346.4228/N20^2)+(0.4388/N20),7) -> 0.0010098 | S20: =ROUND(M20-15,2) -> 13.75 | T20: =IF(L20<0.7705,R20,IF(L20<0.7875,Q20,IF(L20<0.839,P20,IF(L20<1.075,O20,"ERR")))) -> 0.0008412 | U20: =ROUND(T20*S20,8) -> 0.0115665 | V20: =ROUND(T20*S20*0.8,8) -> 0.0092532 | W20: =ROUND(T20^2*S20^2*0.8,9) -> 0.000107027 | X20: =ROUND(-U20-W20,8) -> -0.01167353 | Y20: =EXP(X20) -> 0.98839434 | Z20: =ROUND(Y20,4) -> 0.9884 | AA20: =IF($D$5=0,0,TRUNC(EXP(-AF20*(B20-20)-0.8*(AF20*(B20-20))^2)*10^4+0.5)/10^4) -> 0.9925 | AB20: =IF($D$5>=0.653,IF($D$5<=0.77,TRUNC((346.4228/($D$5*1000)^2+0.4388/($D$5*1000))*10^7+0.5)/10^7,0),0) -> 0 | AC20: =IF($D$5>0.77,IF($D$5<0.788,TRUNC((-0.00336312+2680.3206/($D$5*1000)^2)*10^7+0.5)/10^7,0),0) -> 0 | AD20: =IF($D$5>=0.788,IF($D$5<0.839,TRUNC(594.5418/($D$5*1000)^2*10^7+0.5)/10^7,0),0) -> 0.0008464 | AE20: =IF($D$5>=0.839,IF($D$5<1.075,TRUNC((186.9696/($D$5*1000)^2+0.4862/($D$5*1000))*10^7+0.5)/10^7,0),0) -> 0 | AF20: =SUM(AB20:AE20) -> 0.0008464
B21: 28.8 | C21: =Z21 -> 0.9884 | D21: =AA21 -> 0.9925 | E21: SLOP S | L21: =$C$5 -> 0.8426 | M21: =ROUND(B21*4,0)/4 -> 28.75 | N21: =2*ROUND((L21*1000/2),0) -> 842 | O21: =ROUND((186.9696/N21^2)+(0.4862/N21),7) -> 0.0008412 | P21: =ROUND((594.5418/N21^2)+(0/N21),7) -> 0.0008386 | Q21: =ROUND(-0.00336312+2680.3206/N21^2,7) -> 0.0004175 | R21: =ROUND((346.4228/N21^2)+(0.4388/N21),7) -> 0.0010098 | S21: =ROUND(M21-15,2) -> 13.75 | T21: =IF(L21<0.7705,R21,IF(L21<0.7875,Q21,IF(L21<0.839,P21,IF(L21<1.075,O21,"ERR")))) -> 0.0008412 | U21: =ROUND(T21*S21,8) -> 0.0115665 | V21: =ROUND(T21*S21*0.8,8) -> 0.0092532 | W21: =ROUND(T21^2*S21^2*0.8,9) -> 0.000107027 | X21: =ROUND(-U21-W21,8) -> -0.01167353 | Y21: =EXP(X21) -> 0.98839434 | Z21: =ROUND(Y21,4) -> 0.9884 | AA21: =IF($D$5=0,0,TRUNC(EXP(-AF21*(B21-20)-0.8*(AF21*(B21-20))^2)*10^4+0.5)/10^4) -> 0.9925 | AB21: =IF($D$5>=0.653,IF($D$5<=0.77,TRUNC((346.4228/($D$5*1000)^2+0.4388/($D$5*1000))*10^7+0.5)/10^7,0),0) -> 0 | AC21: =IF($D$5>0.77,IF($D$5<0.788,TRUNC((-0.00336312+2680.3206/($D$5*1000)^2)*10^7+0.5)/10^7,0),0) -> 0 | AD21: =IF($D$5>=0.788,IF($D$5<0.839,TRUNC(594.5418/($D$5*1000)^2*10^7+0.5)/10^7,0),0) -> 0.0008464 | AE21: =IF($D$5>=0.839,IF($D$5<1.075,TRUNC((186.9696/($D$5*1000)^2+0.4862/($D$5*1000))*10^7+0.5)/10^7,0),0) -> 0 | AF21: =SUM(AB21:AE21) -> 0.0008464
B22: 28.8 | C22: =Z22 -> 0.9884 | D22: =AA22 -> 0.9925 | E22: LINE | L22: =$C$5 -> 0.8426 | M22: =ROUND(B22*4,0)/4 -> 28.75 | N22: =2*ROUND((L22*1000/2),0) -> 842 | O22: =ROUND((186.9696/N22^2)+(0.4862/N22),7) -> 0.0008412 | P22: =ROUND((594.5418/N22^2)+(0/N22),7) -> 0.0008386 | Q22: =ROUND(-0.00336312+2680.3206/N22^2,7) -> 0.0004175 | R22: =ROUND((346.4228/N22^2)+(0.4388/N22),7) -> 0.0010098 | S22: =ROUND(M22-15,2) -> 13.75 | T22: =IF(L22<0.7705,R22,IF(L22<0.7875,Q22,IF(L22<0.839,P22,IF(L22<1.075,O22,"ERR")))) -> 0.0008412 | U22: =ROUND(T22*S22,8) -> 0.0115665 | V22: =ROUND(T22*S22*0.8,8) -> 0.0092532 | W22: =ROUND(T22^2*S22^2*0.8,9) -> 0.000107027 | X22: =ROUND(-U22-W22,8) -> -0.01167353 | Y22: =EXP(X22) -> 0.98839434 | Z22: =ROUND(Y22,4) -> 0.9884 | AA22: =IF($D$5=0,0,TRUNC(EXP(-AF22*(B22-20)-0.8*(AF22*(B22-20))^2)*10^4+0.5)/10^4) -> 0.9925 | AB22: =IF($D$5>=0.653,IF($D$5<=0.77,TRUNC((346.4228/($D$5*1000)^2+0.4388/($D$5*1000))*10^7+0.5)/10^7,0),0) -> 0 | AC22: =IF($D$5>0.77,IF($D$5<0.788,TRUNC((-0.00336312+2680.3206/($D$5*1000)^2)*10^7+0.5)/10^7,0),0) -> 0 | AD22: =IF($D$5>=0.788,IF($D$5<0.839,TRUNC(594.5418/($D$5*1000)^2*10^7+0.5)/10^7,0),0) -> 0.0008464 | AE22: =IF($D$5>=0.839,IF($D$5<1.075,TRUNC((186.9696/($D$5*1000)^2+0.4862/($D$5*1000))*10^7+0.5)/10^7,0),0) -> 0 | AF22: =SUM(AB22:AE22) -> 0.0008464
B24: ©Godlove Kaiza

Sheet Table 59B
D2: =ROUND(ROUNDDOWN(E2,3),3) -> 0.721 | E2: =I3 -> 0.721 | F2: =ROUND(ROUNDUP(E2,3),3) -> 0.721 | H2: ST | I2: ='OIL-S.Tank'!L6 -> 28.5
C3: =ROUNDDOWN(C4*2,0)/2 -> 28.5 | D3: =INDEX($D$10:$DT$420,MATCH(D2,$C$10:$C$420,0),MATCH(C3,$D$9:$DT$9,0)) -> 0.72869 | E3: =F3-((F3-D3)*(F2-E2))/(IF((F2-D2)=0,1,(F2-D2))) -> 0.72869 | F3: =INDEX($D$10:$DT$420,MATCH(F2,$C$10:$C$420,0),MATCH(C3,$D$9:$DT$9,0)) -> 0.72869 | H3: SG | I3: ='OIL-S.Tank'!O6 -> 0.721
C4: =I2 -> 28.5 | E4: =E3+(C4-C3)*(E5-E3)/(IF((C5-C3)=0,1,(C5-C3))) -> 0.72869
C5: =ROUNDUP(C4*2,0)/2 -> 28.5 | D5: =INDEX($D$10:$DT$420,MATCH(D2,$C$10:$C$420,0),MATCH(C5,$D$9:$DT$9,0)) -> 0.72869 | E5: =F5-((F5-D5)*(F2-E2))/(IF((F2-D2)=0,1,(F2-D2))) -> 0.72869 | F5: =INDEX($D$10:$DT$420,MATCH(F2,$C$10:$C$420,0),MATCH(C5,$D$9:$DT$9,0)) -> 0.72869
C7: Density (kg/litre) 20 degrees Celsius - Table 59B
D8: Degrees Celsius
D9: -5 | E9: -4.5 | F9: -4 | G9: -3.5 | H9: -3 | I9: -2.5 | J9: -2 | K9: -1.5 | L9: -1 | M9: -0.5 | N9: 0 | O9: 0.5 | P9: 1 | Q9: 1.5 | R9: 2 | S9: 2.5 | T9: 3 | U9: 3.5 | V9: 4 | W9: 4.5 | X9: 5 | Y9: 5.5 | Z9: 6 | AA9: 6.5 | AB9: 7 | AC9: 7.5 | AD9: 8 | AE9: 8.5 | AF9: 9 | AG9: 9.5 | AH9: 10 | AI9: 10.5 | AJ9: 11 | AK9: 11.5 | AL9: 12 | AM9: 12.5 | AN9: 13 | AO9: 13.5 | AP9: 14 | AQ9: 14.5 | AR9: 15 | AS9: 15.5 | AT9: 16 | AU9: 16.5 | AV9: 17 | AW9: 17.5 | AX9: 18 | AY9: 18.5 | AZ9: 19 | BA9: 19.5 | BB9: 20 | BC9: 20.5 | BD9: 21 | BE9: 21.5 | BF9: 22 | BG9: 22.5 | BH9: 23 | BI9: 23.5 | BJ9: 24 | BK9: 24.5 | BL9: 25 | BM9: 25.5 | BN9: 26 | BO9: 26.5 | BP9: 27 | BQ9: 27.5 | BR9: 28 | BS9: 28.5 | BT9: 29 | BU9: 29.5 | BV9: 30 | BW9: 30.5 | BX9: 31 | BY9: 31.5 | BZ9: 32 | CA9: 32.5 | CB9: 33 | CC9: 33.5 | CD9: 34 | CE9: 34.5 | CF9: 35 | CG9: 35.5 | CH9: 36 | CI9: 36.5 | CJ9: 37 | CK9: 37.5 | CL9: 38 | CM9: 38.5 | CN9: 39 | CO9: 39.5 | CP9: 40 | CQ9: 40.5 | CR9: 41 | CS9: 41.5 | CT9: 42 | CU9: 42.5 | CV9: 43 | CW9: 43.5 | CX9: 44 | CY9: 44.5 | CZ9: 45 | DA9: 45.5 | DB9: 46 | DC9: 46.5 | DD9: 47 | DE9: 47.5 | DF9: 48 | DG9: 48.5 | DH9: 49 | DI9: 49.5 | DJ9: 50 | DK9: 50.5 | DL9: 51 | DM9: 51.5 | DN9: 52 | DO9: 52.5 | DP9: 53 | DQ9: 53.5 | DR9: 54 | DS9: 54.5 | DT9: 55
B10: Density | C10: 0.66 | D10: 0.6361 | E10: 0.6365 | F10: 0.637 | G10: 0.6375 | H10: 0.638 | I10: 0.6385 | J10: 0.639 | K10: 0.6394 | L10: 0.6399 | M10: 0.6404 | N10: 0.6409 | O10: 0.6405 | P10: 0.6418 | Q10: 0.6414 | R10: 0.6428 | S10: 0.6424 | T10: 0.6438 | U10: 0.6433 | V10: 0.6447 | W10: 0.6443 | X10: 0.6457 | Y10: 0.6452 | Z10: 0.6466 | AA10: 0.6462 | AB10: 0.6476 | AC10: 0.6472 | AD10: 0.6486 | AE10: 0.6481 | AF10: 0.6495 | AG10: 0.6491 | AH10: 0.6505 | AI10: 0.65 | AJ10: 0.6514 | AK10: 0.651 | AL10: 0.6524 | AM10: 0.6519 | AN10: 0.6533 | AO10: 0.6529 | AP10: 0.6543 | AQ10: 0.6538 | AR10: 0.6553 | AS10: 0.6548 | AT10: 0.6562 | AU10: 0.6557 | AV10: 0.6572 | AW10: 0.6567 | AX10: 0.6581 | AY10: 0.6576 | AZ10: 0.6591 | BA10: 0.6586 | BB10: 0.66 | BC10: 0.6605 | BD10: 0.6609 | BE10: 0.6614 | BF10: 0.6619 | BG10: 0.6624 | BH10: 0.6628 | BI10: 0.6633 | BJ10: 0.6638 | BK10: 0.6643 | BL10: 0.6647 | BM10: 0.6652 | BN10: 0.6657 | BO10: 0.6662 | BP10: 0.6666 | BQ10: 0.6671 | BR10: 0.6676 | BS10: 0.668 | BT10: 0.6685 | BU10: 0.669 | BV10: 0.6695 | BW10: 0.6699 | BX10: 0.6704 | BY10: 0.6709 | BZ10: 0.6713 | CA10: 0.6718 | CB10: 0.6723 | CC10: 0.6727 | CD10: 0.6732 | CE10: 0.6737 | CF10: 0.6741 | CG10: 0.6746 | CH10: 0.6751 | CI10: 0.6756 | CJ10: 0.676 | CK10: 0.6765 | CL10: 0.677 | CM10: 0.6774 | CN10: 0.6779 | CO10: 0.6784 | CP10: 0.6788 | CQ10: 0.6793 | CR10: 0.6798 | CS10: 0.6802 | CT10: 0.6807 | CU10: 0.6811 | CV10: 0.6816 | CW10: 0.6821 | CX10: 0.6825 | CY10: 0.683 | CZ10: 0.6835 | DA10: 0.6839 | DB10: 0.6844 | DC10: 0.6849 | DD10: 0.6853 | DE10: 0.6858 | DF10: 0.6863 | DG10: 0.6867 | DH10: 0.6872 | DI10: 0.6876 | DJ10: 0.6881 | DK10: 0.6886 | DL10: 0.689 | DM10: 0.6895 | DN10: 0.69 | DO10: 0.6904 | DP10: 0.6909 | DQ10: 0.6913 | DR10: 0.6918 | DS10: 0.6923 | DT10: 0.6927
C11: 0.661 | D11: 0.63712 | E11: 0.63753 | F11: 0.63802 | G11: 0.63852 | H11: 0.63902 | I11: 0.63952 | J11: 0.64001 | K11: 0.64042 | L11: 0.64092 | M11: 0.64142 | N11: 0.64192 | O11: 0.64151 | P11: 0.64282 | Q11: 0.64242 | R11: 0.64382 | S11: 0.64341 | T11: 0.64481 | U11: 0.64432 | V11: 0.64572 | W11: 0.64531 | X11: 0.64671 | Y11: 0.64622 | Z11: 0.64762 | AA11: 0.64721 | AB11: 0.64861 | AC11: 0.64821 | AD11: 0.64961 | AE11: 0.64911 | AF11: 0.65051 | AG11: 0.65011 | AH11: 0.65151 | AI11: 0.65101 | AJ11: 0.65241 | AK11: 0.65201 | AL11: 0.65341 | AM11: 0.65291 | AN11: 0.65431 | AO11: 0.6539 | AP11: 0.6553 | AQ11: 0.65481 | AR11: 0.6563 | AS11: 0.6558 | AT11: 0.6572 | AU11: 0.65671 | AV11: 0.6582 | AW11: 0.6577 | AX11: 0.6591 | AY11: 0.65861 | AZ11: 0.6601 | BA11: 0.6596 | BB11: 0.661 | BC11: 0.6615 | BD11: 0.6619 | BE11: 0.6624 | BF11: 0.6629 | BG11: 0.66339 | BH11: 0.6638 | BI11: 0.6643 | BJ11: 0.6648 | BK11: 0.66529 | BL11: 0.6657 | BM11: 0.6662 | BN11: 0.66669 | BO11: 0.66719 | BP11: 0.6676 | BQ11: 0.66809 | BR11: 0.66859 | BS11: 0.669 | BT11: 0.66949 | BU11: 0.66999 | BV11: 0.67049 | BW11: 0.67089 | BX11: 0.67139 | BY11: 0.67189 | BZ11: 0.67229 | CA11: 0.67279 | CB11: 0.67329 | CC11: 0.67369 | CD11: 0.67419 | CE11: 0.67469 | CF11: 0.67509 | CG11: 0.67559 | CH11: 0.67609 | CI11: 0.67658 | CJ11: 0.67699 | CK11: 0.67749 | CL11: 0.67798 | CM11: 0.67839 | CN11: 0.67888 | CO11: 0.67938 | CP11: 0.67979 | CQ11: 0.68028 | CR11: 0.68078 | CS11: 0.68119 | CT11: 0.68168 | CU11: 0.68209 | CV11: 0.68258 | CW11: 0.68308 | CX11: 0.68349 | CY11: 0.68398 | CZ11: 0.68448 | DA11: 0.68488 | DB11: 0.68538 | DC11: 0.68588 | DD11: 0.68628 | DE11: 0.68678 | DF11: 0.68727 | DG11: 0.68768 | DH11: 0.68818 | DI11: 0.68858 | DJ11: 0.68908 | DK11: 0.68957 | DL11: 0.68998 | DM11: 0.69048 | DN11: 0.69097 | DO11: 0.69138 | DP11: 0.69187 | DQ11: 0.69228 | DR11: 0.69277 | DS11: 0.69327 | DT11: 0.69368
C12: 0.662 | D12: 0.63814 | E12: 0.63856 | F12: 0.63904 | G12: 0.63954 | H12: 0.64004 | I12: 0.64054 | J12: 0.64102 | K12: 0.64144 | L12: 0.64194 | M12: 0.64244 | N12: 0.64294 | O12: 0.64252 | P12: 0.64384 | Q12: 0.64344 | R12: 0.64484 | S12: 0.64442 | T12: 0.64582 | U12: 0.64534 | V12: 0.64674 | W12: 0.64632 | X12: 0.64772 | Y12: 0.64724 | Z12: 0.64864 | AA12: 0.64822 | AB12: 0.64962 | AC12: 0.64922 | AD12: 0.65062 | AE12: 0.65012 | AF12: 0.65152 | AG12: 0.65112 | AH12: 0.65252 | AI12: 0.65202 | AJ12: 0.65342 | AK12: 0.65302 | AL12: 0.65442 | AM12: 0.65392 | AN12: 0.65532 | AO12: 0.6549 | AP12: 0.6563 | AQ12: 0.65582 | AR12: 0.6573 | AS12: 0.6568 | AT12: 0.6582 | AU12: 0.65772 | AV12: 0.6592 | AW12: 0.6587 | AX12: 0.6601 | AY12: 0.65962 | AZ12: 0.6611 | BA12: 0.6606 | BB12: 0.662 | BC12: 0.6625 | BD12: 0.6629 | BE12: 0.6634 | BF12: 0.6639 | BG12: 0.66438 | BH12: 0.6648 | BI12: 0.6653 | BJ12: 0.6658 | BK12: 0.66628 | BL12: 0.6667 | BM12: 0.6672 | BN12: 0.66768 | BO12: 0.66818 | BP12: 0.6686 | BQ12: 0.66908 | BR12: 0.66958 | BS12: 0.67 | BT12: 0.67048 | BU12: 0.67098 | BV12: 0.67148 | BW12: 0.67188 | BX12: 0.67238 | BY12: 0.67288 | BZ12: 0.67328 | CA12: 0.67378 | CB12: 0.67428 | CC12: 0.67468 | CD12: 0.67518 | CE12: 0.67568 | CF12: 0.67608 | CG12: 0.67658 | CH12: 0.67708 | CI12: 0.67756 | CJ12: 0.67798 | CK12: 0.67848 | CL12: 0.67896 | CM12: 0.67938 | CN12: 0.67986 | CO12: 0.68036 | CP12: 0.68078 | CQ12: 0.68126 | CR12: 0.68176 | CS12: 0.68218 | CT12: 0.68266 | CU12: 0.68308 | CV12: 0.68356 | CW12: 0.68406 | CX12: 0.68448 | CY12: 0.68496 | CZ12: 0.68546 | DA12: 0.68586 | DB12: 0.68636 | DC12: 0.68686 | DD12: 0.68726 | DE12: 0.68776 | DF12: 0.68824 | DG12: 0.68866 | DH12: 0.68916 | DI12: 0.68956 | DJ12: 0.69006 | DK12: 0.69054 | DL12: 0.69096 | DM12: 0.69146 | DN12: 0.69194 | DO12: 0.69236 | DP12: 0.69284 | DQ12: 0.69326 | DR12: 0.69374 | DS12: 0.69424 | DT12: 0.69466
C13: 0.663 | D13: 0.63916 | E13: 0.63959 | F13: 0.64006 | G13: 0.64056 | H13: 0.64106 | I13: 0.64156 | J13: 0.64203 | K13: 0.64246 | L13: 0.64296 | M13: 0.64346 | N13: 0.64396 | O13: 0.64353 | P13: 0.64486 | Q13: 0.64446 | R13: 0.64586 | S13: 0.64543 | T13: 0.64683 | U13: 0.64636 | V13: 0.64776 | W13: 0.64733 | X13: 0.64873 | Y13: 0.64826 | Z13: 0.64966 | AA13: 0.64923 | AB13: 0.65063 | AC13: 0.65023 | AD13: 0.65163 | AE13: 0.65113 | AF13: 0.65253 | AG13: 0.65213 | AH13: 0.65353 | AI13: 0.65303 | AJ13: 0.65443 | AK13: 0.65403 | AL13: 0.65543 | AM13: 0.65493 | AN13: 0.65633 | AO13: 0.6559 | AP13: 0.6573 | AQ13: 0.65683 | AR13: 0.6583 | AS13: 0.6578 | AT13: 0.6592 | AU13: 0.65873 | AV13: 0.6602 | AW13: 0.6597 | AX13: 0.6611 | AY13: 0.66063 | AZ13: 0.6621 | BA13: 0.6616 | BB13: 0.663 | BC13: 0.6635 | BD13: 0.6639 | BE13: 0.6644 | BF13: 0.6649 | BG13: 0.66537 | BH13: 0.6658 | BI13: 0.6663 | BJ13: 0.6668 | BK13: 0.66727 | BL13: 0.6677 | BM13: 0.6682 | BN13: 0.66867 | BO13: 0.66917 | BP13: 0.6696 | BQ13: 0.67007 | BR13: 0.67057 | BS13: 0.671 | BT13: 0.67147 | BU13: 0.67197 | BV13: 0.67247 | BW13: 0.67287 | BX13: 0.67337 | BY13: 0.67387 | BZ13: 0.67427 | CA13: 0.67477 | CB13: 0.67527 | CC13: 0.67567 | CD13: 0.67617 | CE13: 0.67667 | CF13: 0.67707 | CG13: 0.67757 | CH13: 0.67807 | CI13: 0.67854 | CJ13: 0.67897 | CK13: 0.67947 | CL13: 0.67994 | CM13: 0.68037 | CN13: 0.68084 | CO13: 0.68134 | CP13: 0.68177 | CQ13: 0.68224 | CR13: 0.68274 | CS13: 0.68317 | CT13: 0.68364 | CU13: 0.68407 | CV13: 0.68454 | CW13: 0.68504 | CX13: 0.68547 | CY13: 0.68594 | CZ13: 0.68644 | DA13: 0.68684 | DB13: 0.68734 | DC13: 0.68784 | DD13: 0.68824 | DE13: 0.68874 | DF13: 0.68921 | DG13: 0.68964 | DH13: 0.69014 | DI13: 0.69054 | DJ13: 0.69104 | DK13: 0.69151 | DL13: 0.69194 | DM13: 0.69244 | DN13: 0.69291 | DO13: 0.69334 | DP13: 0.69381 | DQ13: 0.69424 | DR13: 0.69471 | DS13: 0.69521 | DT13: 0.69564
C14: 0.664 | D14: 0.64018 | E14: 0.64062 | F14: 0.64108 | G14: 0.64158 | H14: 0.64208 | I14: 0.64258 | J14: 0.64304 | K14: 0.64348 | L14: 0.64398 | M14: 0.64448 | N14: 0.64498 | O14: 0.64454 | P14: 0.64588 | Q14: 0.64548 | R14: 0.64688 | S14: 0.64644 | T14: 0.64784 | U14: 0.64738 | V14: 0.64878 | W14: 0.64834 | X14: 0.64974 | Y14: 0.64928 | Z14: 0.65068 | AA14: 0.65024 | AB14: 0.65164 | AC14: 0.65124 | AD14: 0.65264 | AE14: 0.65214 | AF14: 0.65354 | AG14: 0.65314 | AH14: 0.65454 | AI14: 0.65404 | AJ14: 0.65544 | AK14: 0.65504 | AL14: 0.65644 | AM14: 0.65594 | AN14: 0.65734 | AO14: 0.6569 | AP14: 0.6583 | AQ14: 0.65784 | AR14: 0.6593 | AS14: 0.6588 | AT14: 0.6602 | AU14: 0.65974 | AV14: 0.6612 | AW14: 0.6607 | AX14: 0.6621 | AY14: 0.66164 | AZ14: 0.6631 | BA14: 0.6626 | BB14: 0.664 | BC14: 0.6645 | BD14: 0.6649 | BE14: 0.6654 | BF14: 0.6659 | BG14: 0.66636 | BH14: 0.6668 | BI14: 0.6673 | BJ14: 0.6678 | BK14: 0.66826 | BL14: 0.6687 | BM14: 0.6692 | BN14: 0.66966 | BO14: 0.67016 | BP14: 0.6706 | BQ14: 0.67106 | BR14: 0.67156 | BS14: 0.672 | BT14: 0.67246 | BU14: 0.67296 | BV14: 0.67346 | BW14: 0.67386 | BX14: 0.67436 | BY14: 0.67486 | BZ14: 0.67526 | CA14: 0.67576 | CB14: 0.67626 | CC14: 0.67666 | CD14: 0.67716 | CE14: 0.67766 | CF14: 0.67806 | CG14: 0.67856 | CH14: 0.67906 | CI14: 0.67952 | CJ14: 0.67996 | CK14: 0.68046 | CL14: 0.68092 | CM14: 0.68136 | CN14: 0.68182 | CO14: 0.68232 | CP14: 0.68276 | CQ14: 0.68322 | CR14: 0.68372 | CS14: 0.68416 | CT14: 0.68462 | CU14: 0.68506 | CV14: 0.68552 | CW14: 0.68602 | CX14: 0.68646 | CY14: 0.68692 | CZ14: 0.68742 | DA14: 0.68782 | DB14: 0.68832 | DC14: 0.68882 | DD14: 0.68922 | DE14: 0.68972 | DF14: 0.69018 | DG14: 0.69062 | DH14: 0.69112 | DI14: 0.69152 | DJ14: 0.69202 | DK14: 0.69248 | DL14: 0.69292 | DM14: 0.69342 | DN14: 0.69388 | DO14: 0.69432 | DP14: 0.69478 | DQ14: 0.69522 | DR14: 0.69568 | DS14: 0.69618 | DT14: 0.69662
C15: 0.665 | D15: 0.6412 | E15: 0.64165 | F15: 0.6421 | G15: 0.6426 | H15: 0.6431 | I15: 0.6436 | J15: 0.64405 | K15: 0.6445 | L15: 0.645 | M15: 0.6455 | N15: 0.646 | O15: 0.64555 | P15: 0.6469 | Q15: 0.6465 | R15: 0.6479 | S15: 0.64745 | T15: 0.64885 | U15: 0.6484 | V15: 0.6498 | W15: 0.64935 | X15: 0.65075 | Y15: 0.6503 | Z15: 0.6517 | AA15: 0.65125 | AB15: 0.65265 | AC15: 0.65225 | AD15: 0.65365 | AE15: 0.65315 | AF15: 0.65455 | AG15: 0.65415 | AH15: 0.65555 | AI15: 0.65505 | AJ15: 0.65645 | AK15: 0.65605 | AL15: 0.65745 | AM15: 0.65695 | AN15: 0.65835 | AO15: 0.6579 | AP15: 0.6593 | AQ15: 0.65885 | AR15: 0.6603 | AS15: 0.6598 | AT15: 0.6612 | AU15: 0.66075 | AV15: 0.6622 | AW15: 0.6617 | AX15: 0.6631 | AY15: 0.66265 | AZ15: 0.6641 | BA15: 0.6636 | BB15: 0.665 | BC15: 0.6655 | BD15: 0.6659 | BE15: 0.6664 | BF15: 0.6669 | BG15: 0.66735 | BH15: 0.6678 | BI15: 0.6683 | BJ15: 0.6688 | BK15: 0.66925 | BL15: 0.6697 | BM15: 0.6702 | BN15: 0.67065 | BO15: 0.67115 | BP15: 0.6716 | BQ15: 0.67205 | BR15: 0.67255 | BS15: 0.673 | BT15: 0.67345 | BU15: 0.67395 | BV15: 0.67445 | BW15: 0.67485 | BX15: 0.67535 | BY15: 0.67585 | BZ15: 0.67625 | CA15: 0.67675 | CB15: 0.67725 | CC15: 0.67765 | CD15: 0.67815 | CE15: 0.67865 | CF15: 0.67905 | CG15: 0.67955 | CH15: 0.68005 | CI15: 0.6805 | CJ15: 0.68095 | CK15: 0.68145 | CL15: 0.6819 | CM15: 0.68235 | CN15: 0.6828 | CO15: 0.6833 | CP15: 0.68375 | CQ15: 0.6842 | CR15: 0.6847 | CS15: 0.68515 | CT15: 0.6856 | CU15: 0.68605 | CV15: 0.6865 | CW15: 0.687 | CX15: 0.68745 | CY15: 0.6879 | CZ15: 0.6884 | DA15: 0.6888 | DB15: 0.6893 | DC15: 0.6898 | DD15: 0.6902 | DE15: 0.6907 | DF15: 0.69115 | DG15: 0.6916 | DH15: 0.6921 | DI15: 0.6925 | DJ15: 0.693 | DK15: 0.69345 | DL15: 0.6939 | DM15: 0.6944 | DN15: 0.69485 | DO15: 0.6953 | DP15: 0.69575 | DQ15: 0.6962 | DR15: 0.69665 | DS15: 0.69715 | DT15: 0.6976
C16: 0.666 | D16: 0.64222 | E16: 0.64268 | F16: 0.64312 | G16: 0.64362 | H16: 0.64412 | I16: 0.64462 | J16: 0.64506 | K16: 0.64552 | L16: 0.64602 | M16: 0.64652 | N16: 0.64702 | O16: 0.64656 | P16: 0.64792 | Q16: 0.64752 | R16: 0.64892 | S16: 0.64846 | T16: 0.64986 | U16: 0.64942 | V16: 0.65082 | W16: 0.65036 | X16: 0.65176 | Y16: 0.65132 | Z16: 0.65272 | AA16: 0.65226 | AB16: 0.65366 | AC16: 0.65326 | AD16: 0.65466 | AE16: 0.65416 | AF16: 0.65556 | AG16: 0.65516 | AH16: 0.65656 | AI16: 0.65606 | AJ16: 0.65746 | AK16: 0.65706 | AL16: 0.65846 | AM16: 0.65796 | AN16: 0.65936 | AO16: 0.6589 | AP16: 0.6603 | AQ16: 0.65986 | AR16: 0.6613 | AS16: 0.6608 | AT16: 0.6622 | AU16: 0.66176 | AV16: 0.6632 | AW16: 0.6627 | AX16: 0.6641 | AY16: 0.66366 | AZ16: 0.6651 | BA16: 0.6646 | BB16: 0.666 | BC16: 0.6665 | BD16: 0.6669 | BE16: 0.6674 | BF16: 0.6679 | BG16: 0.66834 | BH16: 0.6688 | BI16: 0.6693 | BJ16: 0.6698 | BK16: 0.67024 | BL16: 0.6707 | BM16: 0.6712 | BN16: 0.67164 | BO16: 0.67214 | BP16: 0.6726 | BQ16: 0.67304 | BR16: 0.67354 | BS16: 0.674 | BT16: 0.67444 | BU16: 0.67494 | BV16: 0.67544 | BW16: 0.67584 | BX16: 0.67634 | BY16: 0.67684 | BZ16: 0.67724 | CA16: 0.67774 | CB16: 0.67824 | CC16: 0.67864 | CD16: 0.67914 | CE16: 0.67964 | CF16: 0.68004 | CG16: 0.68054 | CH16: 0.68104 | CI16: 0.68148 | CJ16: 0.68194 | CK16: 0.68244 | CL16: 0.68288 | CM16: 0.68334 | CN16: 0.68378 | CO16: 0.68428 | CP16: 0.68474 | CQ16: 0.68518 | CR16: 0.68568 | CS16: 0.68614 | CT16: 0.68658 | CU16: 0.68704 | CV16: 0.68748 | CW16: 0.68798 | CX16: 0.68844 | CY16: 0.68888 | CZ16: 0.68938 | DA16: 0.68978 | DB16: 0.69028 | DC16: 0.69078 | DD16: 0.69118 | DE16: 0.69168 | DF16: 0.69212 | DG16: 0.69258 | DH16: 0.69308 | DI16: 0.69348 | DJ16: 0.69398 | DK16: 0.69442 | DL16: 0.69488 | DM16: 0.69538 | DN16: 0.69582 | DO16: 0.69628 | DP16: 0.69672 | DQ16: 0.69718 | DR16: 0.69762 | DS16: 0.69812 | DT16: 0.69858
C17: 0.667 | D17: 0.64324 | E17: 0.64371 | F17: 0.64414 | G17: 0.64464 | H17: 0.64514 | I17: 0.64564 | J17: 0.64607 | K17: 0.64654 | L17: 0.64704 | M17: 0.64754 | N17: 0.64804 | O17: 0.64757 | P17: 0.64894 | Q17: 0.64854 | R17: 0.64994 | S17: 0.64947 | T17: 0.65087 | U17: 0.65044 | V17: 0.65184 | W17: 0.65137 | X17: 0.65277 | Y17: 0.65234 | Z17: 0.65374 | AA17: 0.65327 | AB17: 0.65467 | AC17: 0.65427 | AD17: 0.65567 | AE17: 0.65517 | AF17: 0.65657 | AG17: 0.65617 | AH17: 0.65757 | AI17: 0.65707 | AJ17: 0.65847 | AK17: 0.65807 | AL17: 0.65947 | AM17: 0.65897 | AN17: 0.66037 | AO17: 0.6599 | AP17: 0.6613 | AQ17: 0.66087 | AR17: 0.6623 | AS17: 0.6618 | AT17: 0.6632 | AU17: 0.66277 | AV17: 0.6642 | AW17: 0.6637 | AX17: 0.6651 | AY17: 0.66467 | AZ17: 0.6661 | BA17: 0.6656 | BB17: 0.667 | BC17: 0.6675 | BD17: 0.6679 | BE17: 0.6684 | BF17: 0.6689 | BG17: 0.66933 | BH17: 0.6698 | BI17: 0.6703 | BJ17: 0.6708 | BK17: 0.67123 | BL17: 0.6717 | BM17: 0.6722 | BN17: 0.67263 | BO17: 0.67313 | BP17: 0.6736 | BQ17: 0.67403 | BR17: 0.67453 | BS17: 0.675 | BT17: 0.67543 | BU17: 0.67593 | BV17: 0.67643 | BW17: 0.67683 | BX17: 0.67733 | BY17: 0.67783 | BZ17: 0.67823 | CA17: 0.67873 | CB17: 0.67923 | CC17: 0.67963 | CD17: 0.68013 | CE17: 0.68063 | CF17: 0.68103 | CG17: 0.68153 | CH17: 0.68203 | CI17: 0.68246 | CJ17: 0.68293 | CK17: 0.68343 | CL17: 0.68386 | CM17: 0.68433 | CN17: 0.68476 | CO17: 0.68526 | CP17: 0.68573 | CQ17: 0.68616 | CR17: 0.68666 | CS17: 0.68713 | CT17: 0.68756 | CU17: 0.68803 | CV17: 0.68846 | CW17: 0.68896 | CX17: 0.68943 | CY17: 0.68986 | CZ17: 0.69036 | DA17: 0.69076 | DB17: 0.69126 | DC17: 0.69176 | DD17: 0.69216 | DE17: 0.69266 | DF17: 0.69309 | DG17: 0.69356 | DH17: 0.69406 | DI17: 0.69446 | DJ17: 0.69496 | DK17: 0.69539 | DL17: 0.69586 | DM17: 0.69636 | DN17: 0.69679 | DO17: 0.69726 | DP17: 0.69769 | DQ17: 0.69816 | DR17: 0.69859 | DS17: 0.69909 | DT17: 0.69956
C18: 0.668 | D18: 0.64426 | E18: 0.64474 | F18: 0.64516 | G18: 0.64566 | H18: 0.64616 | I18: 0.64666 | J18: 0.64708 | K18: 0.64756 | L18: 0.64806 | M18: 0.64856 | N18: 0.64906 | O18: 0.64858 | P18: 0.64996 | Q18: 0.64956 | R18: 0.65096 | S18: 0.65048 | T18: 0.65188 | U18: 0.65146 | V18: 0.65286 | W18: 0.65238 | X18: 0.65378 | Y18: 0.65336 | Z18: 0.65476 | AA18: 0.65428 | AB18: 0.65568 | AC18: 0.65528 | AD18: 0.65668 | AE18: 0.65618 | AF18: 0.65758 | AG18: 0.65718 | AH18: 0.65858 | AI18: 0.65808 | AJ18: 0.65948 | AK18: 0.65908 | AL18: 0.66048 | AM18: 0.65998 | AN18: 0.66138 | AO18: 0.6609 | AP18: 0.6623 | AQ18: 0.66188 | AR18: 0.6633 | AS18: 0.6628 | AT18: 0.6642 | AU18: 0.66378 | AV18: 0.6652 | AW18: 0.6647 | AX18: 0.6661 | AY18: 0.66568 | AZ18: 0.6671 | BA18: 0.6666 | BB18: 0.668 | BC18: 0.6685 | BD18: 0.6689 | BE18: 0.6694 | BF18: 0.6699 | BG18: 0.67032 | BH18: 0.6708 | BI18: 0.6713 | BJ18: 0.6718 | BK18: 0.67222 | BL18: 0.6727 | BM18: 0.6732 | BN18: 0.67362 | BO18: 0.67412 | BP18: 0.6746 | BQ18: 0.67502 | BR18: 0.67552 | BS18: 0.676 | BT18: 0.67642 | BU18: 0.67692 | BV18: 0.67742 | BW18: 0.67782 | BX18: 0.67832 | BY18: 0.67882 | BZ18: 0.67922 | CA18: 0.67972 | CB18: 0.68022 | CC18: 0.68062 | CD18: 0.68112 | CE18: 0.68162 | CF18: 0.68202 | CG18: 0.68252 | CH18: 0.68302 | CI18: 0.68344 | CJ18: 0.68392 | CK18: 0.68442 | CL18: 0.68484 | CM18: 0.68532 | CN18: 0.68574 | CO18: 0.68624 | CP18: 0.68672 | CQ18: 0.68714 | CR18: 0.68764 | CS18: 0.68812 | CT18: 0.68854 | CU18: 0.68902 | CV18: 0.68944 | CW18: 0.68994 | CX18: 0.69042 | CY18: 0.69084 | CZ18: 0.69134 | DA18: 0.69174 | DB18: 0.69224 | DC18: 0.69274 | DD18: 0.69314 | DE18: 0.69364 | DF18: 0.69406 | DG18: 0.69454 | DH18: 0.69504 | DI18: 0.69544 | DJ18: 0.69594 | DK18: 0.69636 | DL18: 0.69684 | DM18: 0.69734 | DN18: 0.69776 | DO18: 0.69824 | DP18: 0.69866 | DQ18: 0.69914 | DR18: 0.69956 | DS18: 0.70006 | DT18: 0.70054
C19: 0.669 | D19: 0.64528 | E19: 0.64577 | F19: 0.64618 | G19: 0.64668 | H19: 0.64718 | I19: 0.64768 | J19: 0.64809 | K19: 0.64858 | L19: 0.64908 | M19: 0.64958 | N19: 0.65008 | O19: 0.64959 | P19: 0.65098 | Q19: 0.65058 | R19: 0.65198 | S19: 0.65149 | T19: 0.65289 | U19: 0.65248 | V19: 0.65388 | W19: 0.65339 | X19: 0.65479 | Y19: 0.65438 | Z19: 0.65578 | AA19: 0.65529 | AB19: 0.65669 | AC19: 0.65629 | AD19: 0.65769 | AE19: 0.65719 | AF19: 0.65859 | AG19: 0.65819 | AH19: 0.65959 | AI19: 0.65909 | AJ19: 0.66049 | AK19: 0.66009 | AL19: 0.66149 | AM19: 0.66099 | AN19: 0.66239 | AO19: 0.6619 | AP19: 0.6633 | AQ19: 0.66289 | AR19: 0.6643 | AS19: 0.6638 | AT19: 0.6652 | AU19: 0.66479 | AV19: 0.6662 | AW19: 0.6657 | AX19: 0.6671 | AY19: 0.66669 | AZ19: 0.6681 | BA19: 0.6676 | BB19: 0.669 | BC19: 0.6695 | BD19: 0.6699 | BE19: 0.6704 | BF19: 0.6709 | BG19: 0.67131 | BH19: 0.6718 | BI19: 0.6723 | BJ19: 0.6728 | BK19: 0.67321 | BL19: 0.6737 | BM19: 0.6742 | BN19: 0.67461 | BO19: 0.67511 | BP19: 0.6756 | BQ19: 0.67601 | BR19: 0.67651 | BS19: 0.677 | BT19: 0.67741 | BU19: 0.67791 | BV19: 0.67841 | BW19: 0.67881 | BX19: 0.67931 | BY19: 0.67981 | BZ19: 0.68021 | CA19: 0.68071 | CB19: 0.68121 | CC19: 0.68161 | CD19: 0.68211 | CE19: 0.68261 | CF19: 0.68301 | CG19: 0.68351 | CH19: 0.68401 | CI19: 0.68442 | CJ19: 0.68491 | CK19: 0.68541 | CL19: 0.68582 | CM19: 0.68631 | CN19: 0.68672 | CO19: 0.68722 | CP19: 0.68771 | CQ19: 0.68812 | CR19: 0.68862 | CS19: 0.68911 | CT19: 0.68952 | CU19: 0.69001 | CV19: 0.69042 | CW19: 0.69092 | CX19: 0.69141 | CY19: 0.69182 | CZ19: 0.69232 | DA19: 0.69272 | DB19: 0.69322 | DC19: 0.69372 | DD19: 0.69412 | DE19: 0.69462 | DF19: 0.69503 | DG19: 0.69552 | DH19: 0.69602 | DI19: 0.69642 | DJ19: 0.69692 | DK19: 0.69733 | DL19: 0.69782 | DM19: 0.69832 | DN19: 0.69873 | DO19: 0.69922 | DP19: 0.69963 | DQ19: 0.70012 | DR19: 0.70053 | DS19: 0.70103 | DT19: 0.70152
C20: 0.67 | D20: 0.6463 | E20: 0.6468 | F20: 0.6472 | G20: 0.6477 | H20: 0.6482 | I20: 0.6487 | J20: 0.6491 | K20: 0.6496 | L20: 0.6501 | M20: 0.6506 | N20: 0.6511 | O20: 0.6506 | P20: 0.652 | Q20: 0.6516 | R20: 0.653 | S20: 0.6525 | T20: 0.6539 | U20: 0.6535 | V20: 0.6549 | W20: 0.6544 | X20: 0.6558 | Y20: 0.6554 | Z20: 0.6568 | AA20: 0.6563 | AB20: 0.6577 | AC20: 0.6573 | AD20: 0.6587 | AE20: 0.6582 | AF20: 0.6596 | AG20: 0.6592 | AH20: 0.6606 | AI20: 0.6601 | AJ20: 0.6615 | AK20: 0.6611 | AL20: 0.6625 | AM20: 0.662 | AN20: 0.6634 | AO20: 0.6629 | AP20: 0.6643 | AQ20: 0.6639 | AR20: 0.6653 | AS20: 0.6648 | AT20: 0.6662 | AU20: 0.6658 | AV20: 0.6672 | AW20: 0.6667 | AX20: 0.6681 | AY20: 0.6677 | AZ20: 0.6691 | BA20: 0.6686 | BB20: 0.67 | BC20: 0.6705 | BD20: 0.6709 | BE20: 0.6714 | BF20: 0.6719 | BG20: 0.6723 | BH20: 0.6728 | BI20: 0.6733 | BJ20: 0.6738 | BK20: 0.6742 | BL20: 0.6747 | BM20: 0.6752 | BN20: 0.6756 | BO20: 0.6761 | BP20: 0.6766 | BQ20: 0.677 | BR20: 0.6775 | BS20: 0.678 | BT20: 0.6784 | BU20: 0.6789 | BV20: 0.6794 | BW20: 0.6798 | BX20: 0.6803 | BY20: 0.6808 | BZ20: 0.6812 | CA20: 0.6817 | CB20: 0.6822 | CC20: 0.6826 | CD20: 0.6831 | CE20: 0.6836 | CF20: 0.684 | CG20: 0.6845 | CH20: 0.685 | CI20: 0.6854 | CJ20: 0.6859 | CK20: 0.6864 | CL20: 0.6868 | CM20: 0.6873 | CN20: 0.6877 | CO20: 0.6882 | CP20: 0.6887 | CQ20: 0.6891 | CR20: 0.6896 | CS20: 0.6901 | CT20: 0.6905 | CU20: 0.691 | CV20: 0.6914 | CW20: 0.6919 | CX20: 0.6924 | CY20: 0.6928 | CZ20: 0.6933 | DA20: 0.6937 | DB20: 0.6942 | DC20: 0.6947 | DD20: 0.6951 | DE20: 0.6956 | DF20: 0.696 | DG20: 0.6965 | DH20: 0.697 | DI20: 0.6974 | DJ20: 0.6979 | DK20: 0.6983 | DL20: 0.6988 | DM20: 0.6993 | DN20: 0.6997 | DO20: 0.7002 | DP20: 0.7006 | DQ20: 0.7011 | DR20: 0.7015 | DS20: 0.702 | DT20: 0.7025
C21: 0.671 | D21: 0.64732 | E21: 0.64782 | F21: 0.64822 | G21: 0.64872 | H21: 0.64922 | I21: 0.64972 | J21: 0.65012 | K21: 0.65062 | L21: 0.65112 | M21: 0.65161 | N21: 0.65211 | O21: 0.65162 | P21: 0.65302 | Q21: 0.65261 | R21: 0.65401 | S21: 0.65352 | T21: 0.65491 | U21: 0.65451 | V21: 0.65591 | W21: 0.65541 | X21: 0.65681 | Y21: 0.65641 | Z21: 0.65781 | AA21: 0.65731 | AB21: 0.65871 | AC21: 0.65831 | AD21: 0.65971 | AE21: 0.65921 | AF21: 0.66061 | AG21: 0.66021 | AH21: 0.6616 | AI21: 0.66111 | AJ21: 0.66251 | AK21: 0.6621 | AL21: 0.6635 | AM21: 0.66301 | AN21: 0.66441 | AO21: 0.66391 | AP21: 0.66531 | AQ21: 0.6649 | AR21: 0.6663 | AS21: 0.66581 | AT21: 0.66721 | AU21: 0.6668 | AV21: 0.6682 | AW21: 0.6677 | AX21: 0.6691 | AY21: 0.6687 | AZ21: 0.6701 | BA21: 0.6696 | BB21: 0.671 | BC21: 0.6715 | BD21: 0.6719 | BE21: 0.6724 | BF21: 0.6729 | BG21: 0.6733 | BH21: 0.6738 | BI21: 0.6743 | BJ21: 0.67479 | BK21: 0.6752 | BL21: 0.6757 | BM21: 0.67619 | BN21: 0.6766 | BO21: 0.6771 | BP21: 0.67759 | BQ21: 0.678 | BR21: 0.67849 | BS21: 0.67899 | BT21: 0.6794 | BU21: 0.67989 | BV21: 0.68039 | BW21: 0.6808 | BX21: 0.68129 | BY21: 0.68179 | BZ21: 0.68219 | CA21: 0.68269 | CB21: 0.68319 | CC21: 0.68359 | CD21: 0.68409 | CE21: 0.68459 | CF21: 0.68499 | CG21: 0.68549 | CH21: 0.68598 | CI21: 0.68639 | CJ21: 0.68689 | CK21: 0.68738 | CL21: 0.68779 | CM21: 0.68828 | CN21: 0.68869 | CO21: 0.68919 | CP21: 0.68968 | CQ21: 0.69009 | CR21: 0.69058 | CS21: 0.69108 | CT21: 0.69149 | CU21: 0.69198 | CV21: 0.69239 | CW21: 0.69288 | CX21: 0.69338 | CY21: 0.69378 | CZ21: 0.69428 | DA21: 0.69469 | DB21: 0.69518 | DC21: 0.69568 | DD21: 0.69608 | DE21: 0.69658 | DF21: 0.69698 | DG21: 0.69748 | DH21: 0.69798 | DI21: 0.69838 | DJ21: 0.69888 | DK21: 0.69928 | DL21: 0.69978 | DM21: 0.70027 | DN21: 0.70068 | DO21: 0.70117 | DP21: 0.70158 | DQ21: 0.70207 | DR21: 0.70248 | DS21: 0.70298 | DT21: 0.70347
C22: 0.672 | D22: 0.64834 | E22: 0.64884 | F22: 0.64924 | G22: 0.64974 | H22: 0.65024 | I22: 0.65074 | J22: 0.65114 | K22: 0.65164 | L22: 0.65214 | M22: 0.65262 | N22: 0.65312 | O22: 0.65264 | P22: 0.65404 | Q22: 0.65362 | R22: 0.65502 | S22: 0.65454 | T22: 0.65592 | U22: 0.65552 | V22: 0.65692 | W22: 0.65642 | X22: 0.65782 | Y22: 0.65742 | Z22: 0.65882 | AA22: 0.65832 | AB22: 0.65972 | AC22: 0.65932 | AD22: 0.66072 | AE22: 0.66022 | AF22: 0.66162 | AG22: 0.66122 | AH22: 0.6626 | AI22: 0.66212 | AJ22: 0.66352 | AK22: 0.6631 | AL22: 0.6645 | AM22: 0.66402 | AN22: 0.66542 | AO22: 0.66492 | AP22: 0.66632 | AQ22: 0.6659 | AR22: 0.6673 | AS22: 0.66682 | AT22: 0.66822 | AU22: 0.6678 | AV22: 0.6692 | AW22: 0.6687 | AX22: 0.6701 | AY22: 0.6697 | AZ22: 0.6711 | BA22: 0.6706 | BB22: 0.672 | BC22: 0.6725 | BD22: 0.6729 | BE22: 0.6734 | BF22: 0.6739 | BG22: 0.6743 | BH22: 0.6748 | BI22: 0.6753 | BJ22: 0.67578 | BK22: 0.6762 | BL22: 0.6767 | BM22: 0.67718 | BN22: 0.6776 | BO22: 0.6781 | BP22: 0.67858 | BQ22: 0.679 | BR22: 0.67948 | BS22: 0.67998 | BT22: 0.6804 | BU22: 0.68088 | BV22: 0.68138 | BW22: 0.6818 | BX22: 0.68228 | BY22: 0.68278 | BZ22: 0.68318 | CA22: 0.68368 | CB22: 0.68418 | CC22: 0.68458 | CD22: 0.68508 | CE22: 0.68558 | CF22: 0.68598 | CG22: 0.68648 | CH22: 0.68696 | CI22: 0.68738 | CJ22: 0.68788 | CK22: 0.68836 | CL22: 0.68878 | CM22: 0.68926 | CN22: 0.68968 | CO22: 0.69018 | CP22: 0.69066 | CQ22: 0.69108 | CR22: 0.69156 | CS22: 0.69206 | CT22: 0.69248 | CU22: 0.69296 | CV22: 0.69338 | CW22: 0.69386 | CX22: 0.69436 | CY22: 0.69476 | CZ22: 0.69526 | DA22: 0.69568 | DB22: 0.69616 | DC22: 0.69666 | DD22: 0.69706 | DE22: 0.69756 | DF22: 0.69796 | DG22: 0.69846 | DH22: 0.69896 | DI22: 0.69936 | DJ22: 0.69986 | DK22: 0.70026 | DL22: 0.70076 | DM22: 0.70124 | DN22: 0.70166 | DO22: 0.70214 | DP22: 0.70256 | DQ22: 0.70304 | DR22: 0.70346 | DS22: 0.70396 | DT22: 0.70444
... C420: 1.07 | D420: 1.0541 | E420: 1.0544 | F420: 1.0547 | G420: 1.055 | H420: 1.0553 | I420: 1.0557 | J420: 1.056 | K420: 1.0563 | L420: 1.0566 | M420: 1.0569 | N420: 1.0573 | O420: 1.057 | P420: 1.0579 | Q420: 1.0576 | R420: 1.0585 | S420: 1.0582 | T420: 1.0592 | U420: 1.0589 | V420: 1.0598 | W420: 1.0595 | X420: 1.0604 | Y420: 1.0601 | Z420: 1.0611 | AA420: 1.0608 | AB420: 1.0617 | AC420: 1.0614 | AD420: 1.0624 | AE420: 1.062 | AF420: 1.063 | AG420: 1.0627 | AH420: 1.0636 | AI420: 1.0633 | AJ420: 1.0643 | AK420: 1.064 | AL420: 1.0649 | AM420: 1.0646 | AN420: 1.0655 | AO420: 1.0652 | AP420: 1.0662 | AQ420: 1.0659 | AR420: 1.0668 | AS420: 1.0665 | AT420: 1.0675 | AU420: 1.0671 | AV420: 1.0681 | AW420: 1.0678 | AX420: 1.0687 | AY420: 1.0684 | AZ420: 1.0694 | BA420: 1.069 | BB420: 1.07 | BC420: 1.0703 | BD420: 1.0706 | BE420: 1.071 | BF420: 1.0713 | BG420: 1.0716 | BH420: 1.0719 | BI420: 1.0722 | BJ420: 1.0725 | BK420: 1.0729 | BL420: 1.0732 | BM420: 1.0735 | BN420: 1.0738 | BO420: 1.0741 | BP420: 1.0745 | BQ420: 1.0748 | BR420: 1.0751 | BS420: 1.0754 | BT420: 1.0757 | BU420: 1.076 | BV420: 1.0764 | BW420: 1.0767 | BX420: 1.077 | BY420: 1.0773 | BZ420: 1.0776 | CA420: 1.078 | CB420: 1.0783 | CC420: 1.0786 | CD420: 1.0789 | CE420: 1.0792 | CF420: 1.0796 | CG420: 1.0799 | CH420: 1.0802 | CI420: 1.0805 | CJ420: 1.0808 | CK420: 1.0811 | CL420: 1.0815 | CM420: 1.0818 | CN420: 1.0821 | CO420: 1.0824 | CP420: 1.0827 | CQ420: 1.0831 | CR420: 1.0834 | CS420: 1.0837 | CT420: 1.084 | CU420: 1.0843 | CV420: 1.0846 | CW420: 1.085 | CX420: 1.0853 | CY420: 1.0856 | CZ420: 1.0859 | DA420: 1.0862 | DB420: 1.0866 | DC420: 1.0869 | DD420: 1.0872 | DE420: 1.0875 | DF420: 1.0878 | DG420: 1.0881 | DH420: 1.0885 | DI420: 1.0888 | DJ420: 1.0891 | DK420: 1.0894 | DL420: 1.0897 | DM420: 1.09 | DN420: 1.0904 | DO420: 1.0907 | DP420: 1.091 | DQ420: 1.0913 | DR420: 1.0916 | DS420: 1.092 | DT420: 1.0923

Sheet Table 60B
D2: =ROUND(ROUNDDOWN(E2,3),3) -> 0.728 | E2: =I3 -> 0.7288 | F2: =ROUND(ROUNDUP(E2,3),3) -> 0.729 | H2: TT | I2: ='OIL-S.Tank'!L12 -> 29
C3: =ROUNDDOWN(C4*2,0)/2 -> 29 | D3: =INDEX($D$10:$DT$420,MATCH(D2,$C$10:$C$420,0),MATCH(C3,$D$9:$DT$9,0)) -> 0.98864 | E3: =F3-((F3-D3)*(F2-E2))/(IF((F2-D2)=0,1,(F2-D2))) -> 0.988664 | F3: =INDEX($D$10:$DT$420,MATCH(F2,$C$10:$C$420,0),MATCH(C3,$D$9:$DT$9,0)) -> 0.98867 | H3: G @ 20C | I3: ='OIL-S.Tank'!D11 -> 0.7288
C4: =I2 -> 29 | E4: =E3+(C4-C3)*(E5-E3)/(IF((C5-C3)=0,1,(C5-C3))) -> 0.988664
C5: =ROUNDUP(C4*2,0)/2 -> 29 | D5: =INDEX($D$10:$DT$420,MATCH(D2,$C$10:$C$420,0),MATCH(C5,$D$9:$DT$9,0)) -> 0.98864 | E5: =F5-((F5-D5)*(F2-E2))/(IF((F2-D2)=0,1,(F2-D2))) -> 0.988664 | F5: =INDEX($D$10:$DT$420,MATCH(F2,$C$10:$C$420,0),MATCH(C5,$D$9:$DT$9,0)) -> 0.98867
C7: Density (kg/litre) 20 degrees Celsius - Table 60B
D8: Degrees Celsius | Y8: 203
D9: -5 | E9: -4.5 | F9: -4 | G9: -3.5 | H9: -3 | I9: -2.5 | J9: -2 | K9: -1.5 | L9: -1 | M9: -0.5 | N9: 0 | O9: 0.5 | P9: 1 | Q9: 1.5 | R9: 2 | S9: 2.5 | T9: 3 | U9: 3.5 | V9: 4 | W9: 4.5 | X9: 5 | Y9: 5.5 | Z9: 6 | AA9: 6.5 | AB9: 7 | AC9: 7.5 | AD9: 8 | AE9: 8.5 | AF9: 9 | AG9: 9.5 | AH9: 10 | AI9: 10.5 | AJ9: 11 | AK9: 11.5 | AL9: 12 | AM9: 12.5 | AN9: 13 | AO9: 13.5 | AP9: 14 | AQ9: 14.5 | AR9: 15 | AS9: 15.5 | AT9: 16 | AU9: 16.5 | AV9: 17 | AW9: 17.5 | AX9: 18 | AY9: 18.5 | AZ9: 19 | BA9: 19.5 | BB9: 20 | BC9: 20.5 | BD9: 21 | BE9: 21.5 | BF9: 22 | BG9: 22.5 | BH9: 23 | BI9: 23.5 | BJ9: 24 | BK9: 24.5 | BL9: 25 | BM9: 25.5 | BN9: 26 | BO9: 26.5 | BP9: 27 | BQ9: 27.5 | BR9: 28 | BS9: 28.5 | BT9: 29 | BU9: 29.5 | BV9: 30 | BW9: 30.5 | BX9: 31 | BY9: 31.5 | BZ9: 32 | CA9: 32.5 | CB9: 33 | CC9: 33.5 | CD9: 34 | CE9: 34.5 | CF9: 35 | CG9: 35.5 | CH9: 36 | CI9: 36.5 | CJ9: 37 | CK9: 37.5 | CL9: 38 | CM9: 38.5 | CN9: 39 | CO9: 39.5 | CP9: 40 | CQ9: 40.5 | CR9: 41 | CS9: 41.5 | CT9: 42 | CU9: 42.5 | CV9: 43 | CW9: 43.5 | CX9: 44 | CY9: 44.5 | CZ9: 45 | DA9: 45.5 | DB9: 46 | DC9: 46.5 | DD9: 47 | DE9: 47.5 | DF9: 48 | DG9: 48.5 | DH9: 49 | DI9: 49.5 | DJ9: 50 | DK9: 50.5 | DL9: 51 | DM9: 51.5 | DN9: 52 | DO9: 52.5 | DP9: 53 | DQ9: 53.5 | DR9: 54 | DS9: 54.5 | DT9: 55
B10: Density | C10: 0.66 | D10: 1.0361 | E10: 1.0354 | F10: 1.0346 | G10: 1.0339 | H10: 1.0332 | I10: 1.0325 | J10: 1.0317 | K10: 1.031 | L10: 1.0303 | M10: 1.0296 | N10: 1.0289 | O10: 1.0282 | P10: 1.0275 | Q10: 1.0268 | R10: 1.0261 | S10: 1.0253 | T10: 1.0246 | U10: 1.0239 | V10: 1.0232 | W10: 1.0225 | X10: 1.0218 | Y10: 1.0211 | Z10: 1.0202 | AA10: 1.0195 | AB10: 1.0188 | AC10: 1.0181 | AD10: 1.0174 | AE10: 1.0167 | AF10: 1.0159 | AG10: 1.0152 | AH10: 1.0145 | AI10: 1.0138 | AJ10: 1.0131 | AK10: 1.0123 | AL10: 1.0116 | AM10: 1.0109 | AN10: 1.0102 | AO10: 1.0095 | AP10: 1.0087 | AQ10: 1.008 | AR10: 1.0073 | AS10: 1.0065 | AT10: 1.0058 | AU10: 1.005 | AV10: 1.0043 | AW10: 1.0036 | AX10: 1.0029 | AY10: 1.0021 | AZ10: 1.0014 | BA10: 1.0007 | BB10: 1 | BC10: 0.9992 | BD10: 0.9985 | BE10: 0.9978 | BF10: 0.9971 | BG10: 0.9963 | BH10: 0.9956 | BI10: 0.9949 | BJ10: 0.9942 | BK10: 0.9934 | BL10: 0.9926 | BM10: 0.9919 | BN10: 0.9912 | BO10: 0.9904 | BP10: 0.9897 | BQ10: 0.989 | BR10: 0.9882 | BS10: 0.9875 | BT10: 0.9868 | BU10: 0.986 | BV10: 0.9853 | BW10: 0.9846 | BX10: 0.9839 | BY10: 0.9831 | BZ10: 0.9824 | CA10: 0.9817 | CB10: 0.9809 | CC10: 0.9802 | CD10: 0.9795 | CE10: 0.9786 | CF10: 0.9779 | CG10: 0.9772 | CH10: 0.9764 | CI10: 0.9757 | CJ10: 0.975 | CK10: 0.9742 | CL10: 0.9735 | CM10: 0.9728 | CN10: 0.972 | CO10: 0.9713 | CP10: 0.9706 | CQ10: 0.9698 | CR10: 0.9691 | CS10: 0.9684 | CT10: 0.9676 | CU10: 0.9669 | CV10: 0.9661 | CW10: 0.9654 | CX10: 0.9646 | CY10: 0.9638 | CZ10: 0.9631 | DA10: 0.9624 | DB10: 0.9616 | DC10: 0.9609 | DD10: 0.9601 | DE10: 0.9594 | DF10: 0.9587 | DG10: 0.9579 | DH10: 0.9572 | DI10: 0.9564 | DJ10: 0.9557 | DK10: 0.955 | DL10: 0.9542 | DM10: 0.9535 | DN10: 0.9527 | DO10: 0.952 | DP10: 0.9512 | DQ10: 0.9504 | DR10: 0.9497 | DS10: 0.9489 | DT10: 0.9482
C11: 0.661 | D11: 1.03603 | E11: 1.03532 | F11: 1.03453 | G11: 1.03383 | H11: 1.03313 | I11: 1.03243 | J11: 1.03164 | K11: 1.03094 | L11: 1.03024 | M11: 1.02954 | N11: 1.02884 | O11: 1.02814 | P11: 1.02744 | Q11: 1.02674 | R11: 1.02604 | S11: 1.02525 | T11: 1.02455 | U11: 1.02385 | V11: 1.02315 | W11: 1.02245 | X11: 1.02175 | Y11: 1.02104 | Z11: 1.02016 | AA11: 1.01946 | AB11: 1.01876 | AC11: 1.01806 | AD11: 1.01736 | AE11: 1.01666 | AF11: 1.01587 | AG11: 1.01517 | AH11: 1.01447 | AI11: 1.01377 | AJ11: 1.01307 | AK11: 1.01228 | AL11: 1.01158 | AM11: 1.01088 | AN11: 1.01018 | AO11: 1.00948 | AP11: 1.00869 | AQ11: 1.00799 | AR11: 1.00729 | AS11: 1.00649 | AT11: 1.00579 | AU11: 1.005 | AV11: 1.0043 | AW11: 1.0036 | AX11: 1.0029 | AY11: 1.00211 | AZ11: 1.0014 | BA11: 1.0007 | BB11: 1 | BC11: 0.99921 | BD11: 0.99851 | BE11: 0.99781 | BF11: 0.99711 | BG11: 0.99632 | BH11: 0.99562 | BI11: 0.99492 | BJ11: 0.99422 | BK11: 0.99342 | BL11: 0.99262 | BM11: 0.99192 | BN11: 0.99122 | BO11: 0.99043 | BP11: 0.98973 | BQ11: 0.98903 | BR11: 0.98824 | BS11: 0.98754 | BT11: 0.98683 | BU11: 0.98604 | BV11: 0.98534 | BW11: 0.98464 | BX11: 0.98394 | BY11: 0.98315 | BZ11: 0.98245 | CA11: 0.98174 | CB11: 0.98095 | CC11: 0.98025 | CD11: 0.97955 | CE11: 0.97867 | CF11: 0.97796 | CG11: 0.97726 | CH11: 0.97646 | CI11: 0.97576 | CJ11: 0.97506 | CK11: 0.97427 | CL11: 0.97357 | CM11: 0.97286 | CN11: 0.97207 | CO11: 0.97137 | CP11: 0.97067 | CQ11: 0.96988 | CR11: 0.96918 | CS11: 0.96847 | CT11: 0.96768 | CU11: 0.96698 | CV11: 0.96619 | CW11: 0.96549 | CX11: 0.96469 | CY11: 0.96389 | CZ11: 0.96319 | DA11: 0.96249 | DB11: 0.9617 | DC11: 0.96099 | DD11: 0.9602 | DE11: 0.9595 | DF11: 0.9588 | DG11: 0.958 | DH11: 0.9573 | DI11: 0.95651 | DJ11: 0.95581 | DK11: 0.95511 | DL11: 0.95431 | DM11: 0.95361 | DN11: 0.95282 | DO11: 0.95212 | DP11: 0.95132 | DQ11: 0.95053 | DR11: 0.94983 | DS11: 0.94903 | DT11: 0.94832
