Workbook

Sheet Shore Tank Calculations
A1: THE UNITED REPUBLIC OF TANZANIA – PETROLEUM BULK PROCUREMENT AGENCY
A2: SHORE TANK CALCULATIONS
A3: Petroleum Measurement – ASTM D1250 / API MPMS Chapter 12
A5: Vessel Name: | D5: Date:
A6: Product: | D6: Vessel Density (kg/m³):
A7: Terminal: | D7: Vessel Temperature (°C):
A9: PARTICULARS | B9: TANK No. 1 | D9: TANK No. 2 | F9: TANK No. 3 | H9: TANK No. 4 | J9: TANK No. 5 | L9: TANK No. 6 | N9: TANK No. 7 | P9: TANK No. 8 | R9: TANK No. 9 | T9: TANK No. 10 | V9: TANK No. 11 | X9: TANK No. 12 | Z9: TANK No. 13 | AB9: TANK No. 14 | AD9: TANK No. 15
B10: INITIAL | C10: L.DISPL/PROV/FINAL | D10: INITIAL | E10: L.DISPL/PROV/FINAL | F10: INITIAL | G10: L.DISPL/PROV/FINAL | H10: INITIAL | I10: L.DISPL/PROV/FINAL | J10: INITIAL | K10: L.DISPL/PROV/FINAL | L10: INITIAL | M10: L.DISPL/PROV/FINAL | N10: INITIAL | O10: L.DISPL/PROV/FINAL | P10: INITIAL | Q10: L.DISPL/PROV/FINAL | R10: INITIAL | S10: L.DISPL/PROV/FINAL | T10: INITIAL | U10: L.DISPL/PROV/FINAL | V10: INITIAL | W10: L.DISPL/PROV/FINAL | X10: INITIAL | Y10: L.DISPL/PROV/FINAL | Z10: INITIAL | AA10: L.DISPL/PROV/FINAL | AB10: INITIAL | AC10: L.DISPL/PROV/FINAL | AD10: INITIAL | AE10: L.DISPL/PROV/FINAL
A11: SECTION A – MEASURED DIPS
A12: Overall Dip (mm) | B12: 20035 | C12: 20035 | D12: 20045 | E12: 20045 | F12: 20510 | G12: 20510
A13: Water Dip (mm)
A14: Product Dip (mm) | B14: 4471 | C14: 18526 | D14: 912 | E14: 18523 | F14: 1688 | G14: 18233
A15: SECTION B – TEMPERATURE & DENSITY
A16: Tank Temperature (°C) | B16: 30 | C16: 31 | D16: 28 | E16: 31.5 | F16: 29 | G16: 31.5
A17: Sample Temperature (°C) | B17: 30.5 | C17: 31.5 | D17: 27.5 | E17: 31.5 | F17: 28.5 | G17: 31
A18: Density @20°C (kg/m³) [auto from ASTM Calc] | B18: =IF('ASTM Calculator'!G9="","",'ASTM Calculator'!G9) -> 0.8383 | C18: =IF('ASTM Calculator'!G10="","",'ASTM Calculator'!G10) -> 0.836 | F18: =IF('ASTM Calculator'!G15="","",'ASTM Calculator'!G15) -> 0.8369 | G18: =IF('ASTM Calculator'!G16="","",'ASTM Calculator'!G16) -> 0.83463 | H18: =IF('ASTM Calculator'!G18="","",'ASTM Calculator'!G18) | I18: =IF('ASTM Calculator'!G19="","",'ASTM Calculator'!G19) | J18: =IF('ASTM Calculator'!G21="","",'ASTM Calculator'!G21) | K18: =IF('ASTM Calculator'!G22="","",'ASTM Calculator'!G22) | L18: =IF('ASTM Calculator'!G24="","",'ASTM Calculator'!G24) | M18: =IF('ASTM Calculator'!G25="","",'ASTM Calculator'!G25) | N18: =IF('ASTM Calculator'!G27="","",'ASTM Calculator'!G27) | O18: =IF('ASTM Calculator'!G28="","",'ASTM Calculator'!G28) | P18: =IF('ASTM Calculator'!G30="","",'ASTM Calculator'!G30) | Q18: =IF('ASTM Calculator'!G31="","",'ASTM Calculator'!G31) | R18: =IF('ASTM Calculator'!G33="","",'ASTM Calculator'!G33) | S18: =IF('ASTM Calculator'!G34="","",'ASTM Calculator'!G34) | T18: =IF('ASTM Calculator'!G36="","",'ASTM Calculator'!G36) | U18: =IF('ASTM Calculator'!G37="","",'ASTM Calculator'!G37) | V18: =IF('ASTM Calculator'!G39="","",'ASTM Calculator'!G39) | W18: =IF('ASTM Calculator'!G40="","",'ASTM Calculator'!G40) | X18: =IF('ASTM Calculator'!G42="","",'ASTM Calculator'!G42) | Y18: =IF('ASTM Calculator'!G43="","",'ASTM Calculator'!G43) | Z18: =IF('ASTM Calculator'!G45="","",'ASTM Calculator'!G45) | AA18: =IF('ASTM Calculator'!G46="","",'ASTM Calculator'!G46) | AB18: =IF('ASTM Calculator'!G48="","",'ASTM Calculator'!G48) | AC18: =IF('ASTM Calculator'!G49="","",'ASTM Calculator'!G49) | AD18: =IF('ASTM Calculator'!G51="","",'ASTM Calculator'!G51) | AE18: =IF('ASTM Calculator'!G52="","",'ASTM Calculator'!G52)
A19: SECTION C – CORRECTION FACTORS
A20: VCF [auto from ASTM Calc – Table 60B] | B20: =IF('ASTM Calculator'!H9="","",'ASTM Calculator'!H9) -> 0.991566 | C20: =IF('ASTM Calculator'!H10="","",'ASTM Calculator'!H10) -> 0.99066 | D20: =IF('ASTM Calculator'!H12="","",'ASTM Calculator'!H12) -> 0.993224 | E20: =IF('ASTM Calculator'!H13="","",'ASTM Calculator'!H13) -> 0.99022 | F20: =IF('ASTM Calculator'!H15="","",'ASTM Calculator'!H15) -> 0.992369 | G20: =IF('ASTM Calculator'!H16="","",'ASTM Calculator'!H16) -> 0.9901926 | H20: =IF('ASTM Calculator'!H18="","",'ASTM Calculator'!H18) | I20: =IF('ASTM Calculator'!H19="","",'ASTM Calculator'!H19) | J20: =IF('ASTM Calculator'!H21="","",'ASTM Calculator'!H21) | K20: =IF('ASTM Calculator'!H22="","",'ASTM Calculator'!H22) | L20: =IF('ASTM Calculator'!H24="","",'ASTM Calculator'!H24) | M20: =IF('ASTM Calculator'!H25="","",'ASTM Calculator'!H25) | N20: =IF('ASTM Calculator'!H27="","",'ASTM Calculator'!H27) | O20: =IF('ASTM Calculator'!H28="","",'ASTM Calculator'!H28) | P20: =IF('ASTM Calculator'!H30="","",'ASTM Calculator'!H30) | Q20: =IF('ASTM Calculator'!H31="","",'ASTM Calculator'!H31) | R20: =IF('ASTM Calculator'!H33="","",'ASTM Calculator'!H33) | S20: =IF('ASTM Calculator'!H34="","",'ASTM Calculator'!H34) | T20: =IF('ASTM Calculator'!H36="","",'ASTM Calculator'!H36) | U20: =IF('ASTM Calculator'!H37="","",'ASTM Calculator'!H37) | V20: =IF('ASTM Calculator'!H39="","",'ASTM Calculator'!H39) | W20: =IF('ASTM Calculator'!H40="","",'ASTM Calculator'!H40) | X20: =IF('ASTM Calculator'!H42="","",'ASTM Calculator'!H42) | Y20: =IF('ASTM Calculator'!H43="","",'ASTM Calculator'!H43) | Z20: =IF('ASTM Calculator'!H45="","",'ASTM Calculator'!H45) | AA20: =IF('ASTM Calculator'!H46="","",'ASTM Calculator'!H46) | AB20: =IF('ASTM Calculator'!H48="","",'ASTM Calculator'!H48) | AC20: =IF('ASTM Calculator'!H49="","",'ASTM Calculator'!H49) | AD20: =IF('ASTM Calculator'!H51="","",'ASTM Calculator'!H51) | AE20: =IF('ASTM Calculator'!H52="","",'ASTM Calculator'!H52)
A21: WCF = Density @20°C − 0.0011 | B21: =IF(OR(B18="",B18=0),"",IFERROR(B18-0.0011,"")) -> 0.8372 | C21: =IF(OR(C18="",C18=0),"",IFERROR(C18-0.0011,"")) -> 0.8349 | F21: =IF(OR(F18="",F18=0),"",IFERROR(F18-0.0011,"")) -> 0.8358 | G21: =IF(OR(G18="",G18=0),"",IFERROR(G18-0.0011,"")) -> 0.83353 | H21: =IF(OR(H18="",H18=0),"",IFERROR(H18-0.0011,"")) | I21: =IF(OR(I18="",I18=0),"",IFERROR(I18-0.0011,"")) | J21: =IF(OR(J18="",J18=0),"",IFERROR(J18-0.0011,"")) | K21: =IF(OR(K18="",K18=0),"",IFERROR(K18-0.0011,"")) | L21: =IF(OR(L18="",L18=0),"",IFERROR(L18-0.0011,"")) | M21: =IF(OR(M18="",M18=0),"",IFERROR(M18-0.0011,"")) | ... AE21: =IF(OR(AE18="",AE18=0),"",IFERROR(AE18-0.0011,""))
A22: SECTION D – VOLUME CALCULATIONS
A23: Gross Observed Vol (m³) [from tank table] | B23: 1429.559 | C23: 5824.123 | D23: 313.592 | E23: 5834.353 | F23: 544.558 | G23: 5725.901
A24: Roof Displacement Vol (m³) [from tank table]
A25: Water Volume (m³) [from tank table]
A26: Net Observed Vol (m³) = GOV − Roof − Water Vol | B26: =IF(OR(B23="",B23=0),"",IFERROR(B23-IF(B24="",0,B24)-IF(B25="",0,B25),"")) -> 1429.559 | C26: =IF(OR(C23="",C23=0),"",IFERROR(C23-IF(C24="",0,C24)-IF(C25="",0,C25),"")) -> 5824.123 | D26: =IF(OR(D23="",D23=0),"",IFERROR(D23-IF(D24="",0,D24)-IF(D25="",0,D25),"")) -> 313.592 | E26: =IF(OR(E23="",E23=0),"",IFERROR(E23-IF(E24="",0,E24)-IF(E25="",0,E25),"")) -> 5834.353 | F26: =IF(OR(F23="",F23=0),"",IFERROR(F23-IF(F24="",0,F24)-IF(F25="",0,F25),"")) -> 544.558 | G26: =IF(OR(G23="",G23=0),"",IFERROR(G23-IF(G24="",0,G24)-IF(G25="",0,G25),"")) -> 5725.901 | H26: =IF(OR(H23="",H23=0),"",IFERROR(H23-IF(H24="",0,H24)-IF(H25="",0,H25),"")) | I26: =IF(OR(I23="",I23=0),"",IFERROR(I23-IF(I24="",0,I24)-IF(I25="",0,I25),"")) | ... AE26: =IF(OR(AE23="",AE23=0),"",IFERROR(AE23-IF(AE24="",0,AE24)-IF(AE25="",0,AE25),""))
A27: SECTION E – STANDARD VOLUME & WEIGHT IN AIR
A28: Standard Vol @20°C (m³) = NOV × VCF | B28: =IF(OR(B26="",B20=""),"",IFERROR(B26*B20,"")) -> 1417.5021 | C28: =IF(OR(C26="",C20=""),"",IFERROR(C26*C20,"")) -> 5769.7257 | D28: =IF(OR(D26="",D20=""),"",IFERROR(D26*D20,"")) -> 311.4671 | E28: =IF(OR(E26="",E20=""),"",IFERROR(E26*E20,"")) -> 5777.293 | F28: =IF(OR(F26="",F20=""),"",IFERROR(F26*F20,"")) -> 540.40248 | G28: =IF(OR(G26="",G20=""),"",IFERROR(G26*G20,"")) -> 5669.7448 | H28: =IF(OR(H26="",H20=""),"",IFERROR(H26*H20,"")) | I28: =IF(OR(I26="",I20=""),"",IFERROR(I26*I20,"")) | ... AE28: =IF(OR(AE26="",AE20=""),"",IFERROR(AE26*AE20,""))
A29: Std Vol Received (m³) = Final − Initial | B29: — | C29: =IF(OR(C28="",B28=""),"",IFERROR(C28-B28,"")) -> 4352.2236 | D29: — | E29: =IF(OR(E28="",D28=""),"",IFERROR(E28-D28,"")) -> 5465.8259 | F29: — | G29: =IF(OR(G28="",F28=""),"",IFERROR(G28-F28,"")) -> 5129.3423 | H29: — | I29: =IF(OR(I28="",H28=""),"",IFERROR(I28-H28,"")) | J29: — | K29: =IF(OR(K28="",J28=""),"",IFERROR(K28-J28,"")) | L29: — | M29: =IF(OR(M28="",L28=""),"",IFERROR(M28-L28,"")) | N29: — | O29: =IF(OR(O28="",N28=""),"",IFERROR(O28-N28,"")) | P29: — | Q29: =IF(OR(Q28="",P28=""),"",IFERROR(Q28-P28,"")) | R29: — | S29: =IF(OR(S28="",R28=""),"",IFERROR(S28-R28,"")) | T29: — | U29: =IF(OR(U28="",T28=""),"",IFERROR(U28-T28,"")) | V29: — | W29: =IF(OR(W28="",V28=""),"",IFERROR(W28-V28,"")) | X29: — | Y29: =IF(OR(Y28="",X28=""),"",IFERROR(Y28-X28,"")) | Z29: — | AA29: =IF(OR(AA28="",Z28=""),"",IFERROR(AA28-Z28,"")) | AB29: — | AC29: =IF(OR(AC28="",AB28=""),"",IFERROR(AC28-AB28,"")) | AD29: — | AE29: =IF(OR(AE28="",AD28=""),"",IFERROR(AE28-AD28,""))
A30: Weight in Air (MT) = Std Vol × WCF | B30: =IF(OR(B28="",B21=""),"",IFERROR(B28*B21,"")) -> 1186.7328 | C30: =IF(OR(C28="",C21=""),"",IFERROR(C28*C21,"")) -> 4817.144 | D30: =IF(OR(D28="",D21=""),"",IFERROR(D28*D21,"")) | E30: =IF(OR(E28="",E21=""),"",IFERROR(E28*E21,"")) | F30: =IF(OR(F28="",F21=""),"",IFERROR(F28*F21,"")) -> 451.66839 | G30: =IF(OR(G28="",G21=""),"",IFERROR(G28*G21,"")) -> 4725.9024 | H30: =IF(OR(H28="",H21=""),"",IFERROR(H28*H21,"")) | I30: =IF(OR(I28="",I21=""),"",IFERROR(I28*I21,"")) | ... AE30: =IF(OR(AE28="",AE21=""),"",IFERROR(AE28*AE21,""))
A31: Weight in Air Received (MT) = Final − Initial | B31: — | C31: =IF(OR(C30="",B30=""),"",IFERROR(C30-B30,"")) -> 3630.4112 | D31: — | E31: =IF(OR(E30="",D30=""),"",IFERROR(E30-D30,"")) | F31: — | G31: =IF(OR(G30="",F30=""),"",IFERROR(G30-F30,"")) -> 4274.234 | H31: — | I31: =IF(OR(I30="",H30=""),"",IFERROR(I30-H30,"")) | J31: — | K31: =IF(OR(K30="",J30=""),"",IFERROR(K30-J30,"")) | L31: — | M31: =IF(OR(M30="",L30=""),"",IFERROR(M30-L30,"")) | N31: — | O31: =IF(OR(O30="",N30=""),"",IFERROR(O30-N30,"")) | P31: — | Q31: =IF(OR(Q30="",P30=""),"",IFERROR(Q30-P30,"")) | R31: — | S31: =IF(OR(S30="",R30=""),"",IFERROR(S30-R30,"")) | T31: — | U31: =IF(OR(U30="",T30=""),"",IFERROR(U30-T30,"")) | V31: — | W31: =IF(OR(W30="",V30=""),"",IFERROR(W30-V30,"")) | X31: — | Y31: =IF(OR(Y30="",X30=""),"",IFERROR(Y30-X30,"")) | Z31: — | AA31: =IF(OR(AA30="",Z30=""),"",IFERROR(AA30-Z30,"")) | AB31: — | AC31: =IF(OR(AC30="",AB30=""),"",IFERROR(AC30-AB30,"")) | AD31: — | AE31: =IF(OR(AE30="",AD30=""),"",IFERROR(AE30-AD30,""))
A33: SECTION F – QUANTITY SUMMARY
A34: STATUS | B34: Obs Vol (m³) | C34: Std Vol (m³) | D34: Weight in Air (MT) | E34: Remarks
A35: TERMINAL (All Tanks) | B35: =IFERROR(IF(OR(C26="",B26=""),0,C26-B26)+IF(OR(E26="",D26=""),0,E26-D26)+IF(OR(G26="",F26=""),0,G26-F26)+IF(OR(I26="",H26=""),0,I26-H26)+IF(OR(K26="",J26=""),0,K26-J26)+IF(OR(M26="",L26=""),0,M26-L26)+IF(OR(O26="",N26=""),0,O26-N26)+IF(OR(Q26="",P26=""),0,Q26-P26)+IF(OR(S26="",R26=""),0,S26-R26)+IF(OR(U26="",T26=""),0,U26-T26)+IF(OR(W26="",V26=""),0,W26-V26)+IF(OR(Y26="",X26=""),0,Y26-X26)+IF(OR(AA26="",Z26=""),0,AA26-Z26)+IF(OR(AC26="",AB26=""),0,AC26-AB26)+IF(OR(AE26="",AD26=""),0,AE26-AD26),"") -> 15096.668 | C35: =IFERROR(IF(C29="",0,C29)+IF(E29="",0,E29)+IF(G29="",0,G29)+IF(I29="",0,I29)+IF(K29="",0,K29)+IF(M29="",0,M29)+IF(O29="",0,O29)+IF(Q29="",0,Q29)+IF(S29="",0,S29)+IF(U29="",0,U29)+IF(W29="",0,W29)+IF(Y29="",0,Y29)+IF(AA29="",0,AA29)+IF(AC29="",0,AC29)+IF(AE29="",0,AE29),"") -> 14947.392 | D35: =IFERROR(IF(C31="",0,C31)+IF(E31="",0,E31)+IF(G31="",0,G31)+IF(I31="",0,I31)+IF(K31="",0,K31)+IF(M31="",0,M31)+IF(O31="",0,O31)+IF(Q31="",0,Q31)+IF(S31="",0,S31)+IF(U31="",0,U31)+IF(W31="",0,W31)+IF(Y31="",0,Y31)+IF(AA31="",0,AA31)+IF(AC31="",0,AC31)+IF(AE31="",0,AE31),"") -> 7904.6452
A36: VESSEL (Bill of Lading) | B36: 297.7 | C36: 294.485 | D36: 245.836
A37: METER QUANTITY
A38: DIFFERENCE (Terminal − Vessel) | B38: =IFERROR(B35-B36,"") -> 14798.968 | C38: =IFERROR(C35-C36,"") -> 14652.907 | D38: =IFERROR(D35-D36,"") -> 7658.8092
A40: PBPA INSPECTOR
A41: STATUS | B41: INITIAL | C41: L/DISPL | D41: PROVISIONAL | E41: FINAL
A42: NAME
A43: SIGNATURE
A44: DATE
...

Sheet ASTM Calculator
A1: THE UNITED REPUBLIC OF TANZANIA – PETROLEUM BULK PROCUREMENT AGENCY
A2: ASTM CALCULATOR – Density @20°C & VCF Lookup
A3: ASTM D1250 / API MPMS Ch.11 – Table 59B (Density Correction) & Table 60B (VCF)
A5: Enter Sample Temperature (°C) per tank in the SHORE TANK sheet row 17 — it auto-flows here (grey). Enter Sample Density (kg/litre) below in yellow. Density @20°C and VCF are then auto-calculated and fed back to the Shore Tank sheet.
A7: Tank | B7: State | C7: Sample Temp (°C) | D7: Sample Density (kg/litre) | E7: Density @20°C [Table 59B] | F7: Tank Temp (°C) [from Shore] | G7: Corrected Density @20°C (override) | H7: VCF [Table 60B] | I7: Notes
A8: COLOUR KEY: | B8: Yellow = enter value | E8: Blue = auto-calc | F8: Grey = pulled from Shore | H8: Blue = auto-calc
A9: Tank 1 | B9: INITIAL | C9: ='Shore Tank Calculations'!B17 -> 30.5 | D9: 0.831 | E9: =IFERROR(IF((ROUNDUP(C9*2,0)/2-ROUNDDOWN(C9*2,0)/2)=0,IF((ROUND(ROUNDUP(D9,3),3)-ROUND(ROUNDDOWN(D9,3),3))=0,INDEX('Table 59B'!$D$10:$DT$420,MATCH(ROUND(ROUNDDOWN(D9,3),3),'Table 59B'!$C$10:$C$420,0),MATCH(ROUNDDOWN(C9*2,0)/2,'Table 59B'!$D$9:$DT$9,0)),INDEX('Table 59B'!$D$10:$DT$420,MATCH(ROUND(ROUNDUP(D9,3),3),'Table 59B'!$C$10:$C$420,0),MATCH(ROUNDDOWN(C9*2,0)/2,'Table 59B'!$D$9:$DT$9,0))-((INDEX('Table 59B'!$D$10:$DT$420,MATCH(ROUND(ROUNDUP(D9,3),3),'Table 59B'!$C$10:$C$420,0),MATCH(ROUNDDOWN(C9*2,0)/2,'Table 59B'!$D$9:$DT$9,0))-INDEX('Table 59B'!$D$10:$DT$420,MATCH(ROUND(ROUNDDOWN(D9,3),3),'Table 59B'!$C$10:$C$420,0),MATCH(ROUNDDOWN(C9*2,0)/2,'Table 59B'!$D$9:$DT$9,0)))*(ROUND(ROUNDUP(D9,3),3)-D9))/(ROUND(ROUNDUP(D9,3),3)-ROUND(ROUNDDOWN(D9,3),3))),IF((ROUND(ROUNDUP(D9,3),3)-ROUND(ROUNDDOWN(D9,3),3))=0,INDEX('Table 59B'!$D$10:$DT$420,MATCH(ROUND(ROUNDDOWN(D9,3),3),'Table 59B'!$C$10:$C$420,0),MATCH(ROUNDDOWN(C9*2,0)/2,'Table 59B'!$D$9:$DT$9,0)),INDEX('Table 59B'!$D$10:$DT$420,MATCH(ROUND(ROUNDUP(D9,3),3),'Table 59B'!$C$10:$C$420,0),MATCH(ROUNDDOWN(C9*2,0)/2,'Table 59B'!$D$9:$DT$9,0))-((INDEX('Table 59B'!$D$10:$DT$420,MATCH(ROUND(ROUNDUP(D9,3),3),'Table 59B'!$C$10:$C$420,0),MATCH(ROUNDDOWN(C9*2,0)/2,'Table 59B'!$D$9:$DT$9,0))-INDEX('Table 59B'!$D$10:$DT$420,MATCH(ROUND(ROUNDDOWN(D9,3),3),'Table 59B'!$C$10:$C$420,0),MATCH(ROUNDDOWN(C9*2,0)/2,'Table 59B'!$D$9:$DT$9,0)))*(ROUND(ROUNDUP(D9,3),3)-D9))/(ROUND(ROUNDUP(D9,3),3)-ROUND(ROUNDDOWN(D9,3),3)))+(C9-ROUNDDOWN(C9*2,0)/2)*(IF((ROUND(ROUNDUP(D9,3),3)-ROUND(ROUNDDOWN(D9,3),3))=0,INDEX('Table 59B'!$D$10:$DT$420,MATCH(ROUND(ROUNDDOWN(D9,3),3),'Table 59B'!$C$10:$C$420,0),MATCH(ROUNDUP(C9*2,0)/2,'Table 59B'!$D$9:$DT$9,0)),INDEX('Table 59B'!$D$10:$DT$420,MATCH(ROUND(ROUNDUP(D9,3),3),'Table 59B'!$C$10:$C$420,0),MATCH(ROUNDUP(C9*2,0)/2,'Table 59B'!$D$9:$DT$9,0))-((INDEX('Table 59B'!$D$10:$DT$420,MATCH(ROUND(ROUNDUP(D9,3),3),'Table 59B'!$C$10:$C$420,0),MATCH(ROUNDUP(C9*2,0)/2,'Table 59B'!$D$9:$DT$9,0))-INDEX('Table 59B'!$D$10:$DT$420,MATCH(ROUND(ROUNDDOWN(D9,3),3),'Table 59B'!$C$10:$C$420,0),MATCH(ROUNDUP(C9*2,0)/2,'Table 59B'!$D$9:$DT$9,0)))*(ROUND(ROUNDUP(D9,3),3)-D9))/(ROUND(ROUNDUP(D9,3),3)-ROUND(ROUNDDOWN(D9,3),3)))-IF((ROUND(ROUNDUP(D9,3),3)-ROUND(ROUNDDOWN(D9,3),3))=0,INDEX('Table 59B'!$D$10:$DT$420,MATCH(ROUND(ROUNDDOWN(D9,3),3),'Table 59B'!$C$10:$C$420,0),MATCH(ROUNDDOWN(C9*2,0)/2,'Table 59B'!$D$9:$DT$9,0)),INDEX('Table 59B'!$D$10:$DT$420,MATCH(ROUND(ROUNDUP(D9,3),3),'Table 59B'!$C$10:$C$420,0),MATCH(ROUNDDOWN(C9*2,0)/2,'Table 59B'!$D$9:$DT$9,0))-((INDEX('Table 59B'!$D$10:$DT$420,MATCH(ROUND(ROUNDUP(D9,3),3),'Table 59B'!$C$10:$C$420,0),MATCH(ROUNDDOWN(C9*2,0)/2,'Table 59B'!$D$9:$DT$9,0))-INDEX('Table 59B'!$D$10:$DT$420,MATCH(ROUND(ROUNDDOWN(D9,3),3),'Table 59B'!$C$10:$C$420,0),MATCH(ROUNDDOWN(C9*2,0)/2,'Table 59B'!$D$9:$DT$9,0)))*(ROUND(ROUNDUP(D9,3),3)-D9))/(ROUND(ROUNDUP(D9,3),3)-ROUND(ROUNDDOWN(D9,3),3))))/(ROUNDUP(C9*2,0)/2-ROUNDDOWN(C9*2,0)/2)),"") -> 0.83829 | F9: =IF('Shore Tank Calculations'!B16="","",'Shore Tank Calculations'!B16) -> 30 | G9: 0.8383 | H9: =IFERROR(IF((ROUNDUP(F9*2,0)/2-ROUNDDOWN(F9*2,0)/2)=0,IF((ROUND(ROUNDUP(G9,3),3)-ROUND(ROUNDDOWN(G9,3),3))=0,INDEX('Table 60B'!$D$10:$DT$420,MATCH(ROUND(ROUNDDOWN(G9,3),3),'Table 60B'!$C$10:$C$420,0),MATCH(ROUNDDOWN(F9*2,0)/2,'Table 60B'!$D$9:$DT$9,0)),INDEX('Table 60B'!$D$10:$DT$420,MATCH(ROUND(ROUNDUP(G9,3),3),'Table 60B'!$C$10:$C$420,0),MATCH(ROUNDDOWN(F9*2,0)/2,'Table 60B'!$D$9:$DT$9,0))-((INDEX('Table 60B'!$D$10:$DT$420,MATCH(ROUND(ROUNDUP(G9,3),3),'Table 60B'!$C$10:$C$420,0),MATCH(ROUNDDOWN(F9*2,0)/2,'Table 60B'!$D$9:$DT$9,0))-INDEX('Table 60B'!$D$10:$DT$420,MATCH(ROUND(ROUNDDOWN(G9,3),3),'Table 60B'!$C$10:$C$420,0),MATCH(ROUNDDOWN(F9*2,0)/2,'Table 60B'!$D$9:$DT$9,0)))*(ROUND(ROUNDUP(G9,3),3)-G9))/(ROUND(ROUNDUP(G9,3),3)-ROUND(ROUNDDOWN(G9,3),3))),IF((ROUND(ROUNDUP(G9,3),3)-ROUND(ROUNDDOWN(G9,3),3))=0,INDEX('Table 60B'!$D$10:$DT$420,MATCH(ROUND(ROUNDDOWN(G9,3),3),'Table 60B'!$C$10:$C$420,0),MATCH(ROUNDDOWN(F9*2,0)/2,'Table 60B'!$D$9:$DT$9,0)),INDEX('Table 60B'!$D$10:$DT$420,MATCH(ROUND(ROUNDUP(G9,3),3),'Table 60B'!$C$10:$C$420,0),MATCH(ROUNDDOWN(F9*2,0)/2,'Table 60B'!$D$9:$DT$9,0))-((INDEX('Table 60B'!$D$10:$DT$420,MATCH(ROUND(ROUNDUP(G9,3),3),'Table 60B'!$C$10:$C$420,0),MATCH(ROUNDDOWN(F9*2,0)/2,'Table 60B'!$D$9:$DT$9,0))-INDEX('Table 60B'!$D$10:$DT$420,MATCH(ROUND(ROUNDDOWN(G9,3),3),'Table 60B'!$C$10:$C$420,0),MATCH(ROUNDDOWN(F9*2,0)/2,'Table 60B'!$D$9:$DT$9,0)))*(ROUND(ROUNDUP(G9,3),3)-G9))/(ROUND(ROUNDUP(G9,3),3)-ROUND(ROUNDDOWN(G9,3),3)))+(F9-ROUNDDOWN(F9*2,0)/2)*(IF((ROUND(ROUNDUP(G9,3),3)-ROUND(ROUNDDOWN(G9,3),3))=0,INDEX('Table 60B'!$D$10:$DT$420,MATCH(ROUND(ROUNDDOWN(G9,3),3),'Table 60B'!$C$10:$C$420,0),MATCH(ROUNDUP(F9*2,0)/2,'Table 60B'!$D$9:$DT$9,0)),INDEX('Table 60B'!$D$10:$DT$420,MATCH(ROUND(ROUNDUP(G9,3),3),'Table 60B'!$C$10:$C$420,0),MATCH(ROUNDUP(F9*2,0)/2,'Table 60B'!$D$9:$DT$9,0))-((INDEX('Table 60B'!$D$10:$DT$420,MATCH(ROUND(ROUNDUP(G9,3),3),'Table 60B'!$C$10:$C$420,0),MATCH(ROUNDUP(F9*2,0)/2,'Table 60B'!$D$9:$DT$9,0))-INDEX('Table 60B'!$D$10:$DT$420,MATCH(ROUND(ROUNDDOWN(G9,3),3),'Table 60B'!$C$10:$C$420,0),MATCH(ROUNDUP(F9*2,0)/2,'Table 60B'!$D$9:$DT$9,0)))*(ROUND(ROUNDUP(G9,3),3)-G9))/(ROUND(ROUNDUP(G9,3),3)-ROUND(ROUNDDOWN(G9,3),3)))-IF((ROUND(ROUNDUP(G9,3),3)-ROUND(ROUNDDOWN(G9,3),3))=0,INDEX('Table 60B'!$D$10:$DT$420,MATCH(ROUND(ROUNDDOWN(G9,3),3),'Table 60B'!$C$10:$C$420,0),MATCH(ROUNDDOWN(F9*2,0)/2,'Table 60B'!$D$9:$DT$9,0)),INDEX('Table 60B'!$D$10:$DT$420,MATCH(ROUND(ROUNDUP(G9,3),3),'Table 60B'!$C$10:$C$420,0),MATCH(ROUNDDOWN(F9*2,0)/2,'Table 60B'!$D$9:$DT$9,0))-((INDEX('Table 60B'!$D$10:$DT$420,MATCH(ROUND(ROUNDUP(G9,3),3),'Table 60B'!$C$10:$C$420,0),MATCH(ROUNDDOWN(F9*2,0)/2,'Table 60B'!$D$9:$DT$9,0))-INDEX('Table 60B'!$D$10:$DT$420,MATCH(ROUND(ROUNDDOWN(G9,3),3),'Table 60B'!$C$10:$C$420,0),MATCH(ROUNDDOWN(F9*2,0)/2,'Table 60B'!$D$9:$DT$9,0)))*(ROUND(ROUNDUP(G9,3),3)-G9))/(ROUND(ROUNDUP(G9,3),3)-ROUND(ROUNDDOWN(G9,3),3))))/(ROUNDUP(F9*2,0)/2-ROUNDDOWN(F9*2,0)/2)),"") -> 0.991566 | I9: ← sample density corrected to 20°C via Table 59B; VCF from Table 60B
B10: FINAL | C10: ='Shore Tank Calculations'!C17 -> 31.5 | D10: 0.828 | E10: =IFERROR(IF((ROUNDUP(C10*2,0)/2-ROUNDDOWN(C10*2,0)/2)=0,IF((ROUND(ROUNDUP(D10,3),3)-ROUND(ROUNDDOWN(D10,3),3))=0,INDEX('Table 59B'!$D$10:$DT$420,MATCH(ROUND(ROUNDDOWN(D10,3),3),'Table 59B'!$C$10:$C$420,0),MATCH(ROUNDDOWN(C10*2,0)/2,'Table 59B'!$D$9:$DT$9,0)),INDEX('Table 59B'!$D$10:$DT$420,MATCH(ROUND(ROUNDUP(D10,3),3),'Table 59B'!$C$10:$C$420,0),MATCH(ROUNDDOWN(C10*2,0)/2,'Table 59B'!$D$9:$DT$9,0))-((INDEX('Table 59B'!$D$10:$DT$420,MATCH(ROUND(ROUNDUP(D10,3),3),'Table 59B'!$C$10:$C$420,0),MATCH(ROUNDDOWN(C10*2,0)/2,'Table 59B'!$D$9:$DT$9,0))-INDEX('Table 59B'!$D$10:$DT$420,MATCH(ROUND(ROUNDDOWN(D10,3),3),'Table 59B'!$C$10:$C$420,0),MATCH(ROUNDDOWN(C10*2,0)/2,'Table 59B'!$D$9:$DT$9,0)))*(ROUND(ROUNDUP(D10,3),3)-D10))/(ROUND(ROUNDUP(D10,3),3)-ROUND(ROUNDDOWN(D10,3),3))),IF((ROUND(ROUNDUP(D10,3),3)-ROUND(ROUNDDOWN(D10,3),3))=0,INDEX('Table 59B'!$D$10:$DT$420,MATCH(ROUND(ROUNDDOWN(D10,3),3),'Table 59B'!$C$10:$C$420,0),MATCH(ROUNDDOWN(C10*2,0)/2,'Table 59B'!$D$9:$DT$9,0)),INDEX('Table 59B'!$D$10:$DT$420,MATCH(ROUND(ROUNDUP(D10,3),3),'Table 59B'!$C$10:$C$420,0),MATCH(ROUNDDOWN(C10*2,0)/2,'Table 59B'!$D$9:$DT$9,0))-((INDEX('Table 59B'!$D$10:$DT$420,MATCH(ROUND(ROUNDUP(D10,3),3),'Table 59B'!$C$10:$C$420,0),MATCH(ROUNDDOWN(C10*2,0)/2,'Table 59B'!$D$9:$DT$9,0))-INDEX('Table 59B'!$D$10:$DT$420,MATCH(ROUND(ROUNDDOWN(D10,3),3),'Table 59B'!$C$10:$C$420,0),MATCH(ROUNDDOWN(C10*2,0)/2,'Table 59B'!$D$9:$DT$9,0)))*(ROUND(ROUNDUP(D10,3),3)-D10))/(ROUND(ROUNDUP(D10,3),3)-ROUND(ROUNDDOWN(D10,3),3)))+(C10-ROUNDDOWN(C10*2,0)/2)*(IF((ROUND(ROUNDUP(D10,3),3)-ROUND(ROUNDDOWN(D10,3),3))=0,INDEX('Table 59B'!$D$10:$DT$420,MATCH(ROUND(ROUNDDOWN(D10,3),3),'Table 59B'!$C$10:$C$420,0),MATCH(ROUNDUP(C10*2,0)/2,'Table 59B'!$D$9:$DT$9,0)),INDEX('Table 59B'!$D$10:$DT$420,MATCH(ROUND(ROUNDUP(D10,3),3),'Table 59B'!$C$10:$C$420,0),MATCH(ROUNDUP(C10*2,0)/2,'Table 59B'!$D$9:$DT$9,0))-((INDEX('Table 59B'!$D$10:$DT$420,MATCH(ROUND(ROUNDUP(D10,3),3),'Table 59B'!$C$10:$C$420,0),MATCH(ROUNDUP(C10*2,0)/2,'Table 59B'!$D$9:$DT$9,0))-INDEX('Table 59B'!$D$10:$DT$420,MATCH(ROUND(ROUNDDOWN(D10,3),3),'Table 59B'!$C$10:$C$420,0),MATCH(ROUNDUP(C10*2,0)/2,'Table 59B'!$D$9:$DT$9,0)))*(ROUND(ROUNDUP(D10,3),3)-D10))/(ROUND(ROUNDUP(D10,3),3)-ROUND(ROUNDDOWN(D10,3),3)))-IF((ROUND(ROUNDUP(D10,3),3)-ROUND(ROUNDDOWN(D10,3),3))=0,INDEX('Table 59B'!$D$10:$DT$420,MATCH(ROUND(ROUNDDOWN(D10,3),3),'Table 59B'!$C$10:$C$420,0),MATCH(ROUNDDOWN(C10*2,0)/2,'Table 59B'!$D$9:$DT$9,0)),INDEX('Table 59B'!$D$10:$DT$420,MATCH(ROUND(ROUNDUP(D10,3),3),'Table 59B'!$C$10:$C$420,0),MATCH(ROUNDDOWN(C10*2,0)/2,'Table 59B'!$D$9:$DT$9,0))-((INDEX('Table 59B'!$D$10:$DT$420,MATCH(ROUND(ROUNDUP(D10,3),3),'Table 59B'!$C$10:$C$420,0),MATCH(ROUNDDOWN(C10*2,0)/2,'Table 59B'!$D$9:$DT$9,0))-INDEX('Table 59B'!$D$10:$DT$420,MATCH(ROUND(ROUNDDOWN(D10,3),3),'Table 59B'!$C$10:$C$420,0),MATCH(ROUNDDOWN(C10*2,0)/2,'Table 59B'!$D$9:$DT$9,0)))*(ROUND(ROUNDUP(D10,3),3)-D10))/(ROUND(ROUNDUP(D10,3),3)-ROUND(ROUNDDOWN(D10,3),3))))/(ROUNDUP(C10*2,0)/2-ROUNDDOWN(C10*2,0)/2)),"") -> 0.836 | F10: =IF('Shore Tank Calculations'!C16="","",'Shore Tank Calculations'!C16) -> 31 | G10: 0.836 | H10: =IFERROR(IF((ROUNDUP(F10*2,0)/2-ROUNDDOWN(F10*2,0)/2)=0,IF((ROUND(ROUNDUP(G10,3),3)-ROUND(ROUNDDOWN(G10,3),3))=0,INDEX('Table 60B'!$D$10:$DT$420,MATCH(ROUND(ROUNDDOWN(G10,3),3),'Table 60B'!$C$10:$C$420,0),MATCH(ROUNDDOWN(F10*2,0)/2,'Table 60B'!$D$9:$DT$9,0)),INDEX('Table 60B'!$D$10:$DT$420,MATCH(ROUND(ROUNDUP(G10,3),3),'Table 60B'!$C$10:$C$420,0),MATCH(ROUNDDOWN(F10*2,0)/2,'Table 60B'!$D$9:$DT$9,0))-((INDEX('Table 60B'!$D$10:$DT$420,MATCH(ROUND(ROUNDUP(G10,3),3),'Table 60B'!$C$10:$C$420,0),MATCH(ROUNDDOWN(F10*2,0)/2,'Table 60B'!$D$9:$DT$9,0))-INDEX('Table 60B'!$D$10:$DT$420,MATCH(ROUND(ROUNDDOWN(G10,3),3),'Table 60B'!$C$10:$C$420,0),MATCH(ROUNDDOWN(F10*2,0)/2,'Table 60B'!$D$9:$DT$9,0)))*(ROUND(ROUNDUP(G10,3),3)-G10))/(ROUND(ROUNDUP(G10,3),3)-ROUND(ROUNDDOWN(G10,3),3))),IF((ROUND(ROUNDUP(G10,3),3)-ROUND(ROUNDDOWN(G10,3),3))=0,INDEX('Table 60B'!$D$10:$DT$420,MATCH(ROUND(ROUNDDOWN(G10,3),3),'Table 60B'!$C$10:$C$420,0),MATCH(ROUNDDOWN(F10*2,0)/2,'Table 60B'!$D$9:$DT$9,0)),INDEX('Table 60B'!$D$10:$DT$420,MATCH(ROUND(ROUNDUP(G10,3),3),'Table 60B'!$C$10:$C$420,0),MATCH(ROUNDDOWN(F10*2,0)/2,'Table 60B'!$D$9:$DT$9,0))-((INDEX('Table 60B'!$D$10:$DT$420,MATCH(ROUND(ROUNDUP(G10,3),3),'Table 60B'!$C$10:$C$420,0),MATCH(ROUNDDOWN(F10*2,0)/2,'Table 60B'!$D$9:$DT$9,0))-INDEX('Table 60B'!$D$10:$DT$420,MATCH(ROUND(ROUNDDOWN(G10,3),3),'Table 60B'!$C$10:$C$420,0),MATCH(ROUNDDOWN(F10*2,0)/2,'Table 60B'!$D$9:$DT$9,0)))*(ROUND(ROUNDUP(G10,3),3)-G10))/(ROUND(ROUNDUP(G10,3),3)-ROUND(ROUNDDOWN(G10,3),3)))+(F10-ROUNDDOWN(F10*2,0)/2)*(IF((ROUND(ROUNDUP(G10,3),3)-ROUND(ROUNDDOWN(G10,3),3))=0,INDEX('Table 60B'!$D$10:$DT$420,MATCH(ROUND(ROUNDDOWN(G10,3),3),'Table 60B'!$C$10:$C$420,0),MATCH(ROUNDUP(F10*2,0)/2,'Table 60B'!$D$9:$DT$9,0)),INDEX('Table 60B'!$D$10:$DT$420,MATCH(ROUND(ROUNDUP(G10,3),3),'Table 60B'!$C$10:$C$420,0),MATCH(ROUNDUP(F10*2,0)/2,'Table 60B'!$D$9:$DT$9,0))-((INDEX('Table 60B'!$D$10:$DT$420,MATCH(ROUND(ROUNDUP(G10,3),3),'Table 60B'!$C$10:$C$420,0),MATCH(ROUNDUP(F10*2,0)/2,'Table 60B'!$D$9:$DT$9,0))-INDEX('Table 60B'!$D$10:$DT$420,MATCH(ROUND(ROUNDDOWN(G10,3),3),'Table 60B'!$C$10:$C$420,0),MATCH(ROUNDUP(F10*2,0)/2,'Table 60B'!$D$9:$DT$9,0)))*(ROUND(ROUNDUP(G10,3),3)-G10))/(ROUND(ROUNDUP(G10,3),3)-ROUND(ROUNDDOWN(G10,3),3)))-IF((ROUND(ROUNDUP(G10,3),3)-ROUND(ROUNDDOWN(G10,3),3))=0,INDEX('Table 60B'!$D$10:$DT$420,MATCH(ROUND(ROUNDDOWN(G10,3),3),'Table 60B'!$C$10:$C$420,0),MATCH(ROUNDDOWN(F10*2,0)/2,'Table 60B'!$D$9:$DT$9,0)),INDEX('Table 60B'!$D$10:$DT$420,MATCH(ROUND(ROUNDUP(G10,3),3),'Table 60B'!$C$10:$C$420,0),MATCH(ROUNDDOWN(F10*2,0)/2,'Table 60B'!$D$9:$DT$9,0))-((INDEX('Table 60B'!$D$10:$DT$420,MATCH(ROUND(ROUNDUP(G10,3),3),'Table 60B'!$C$10:$C$420,0),MATCH(ROUNDDOWN(F10*2,0)/2,'Table 60B'!$D$9:$DT$9,0))-INDEX('Table 60B'!$D$10:$DT$420,MATCH(ROUND(ROUNDDOWN(G10,3),3),'Table 60B'!$C$10:$C$420,0),MATCH(ROUNDDOWN(F10*2,0)/2,'Table 60B'!$D$9:$DT$9,0)))*(ROUND(ROUNDUP(G10,3),3)-G10))/(ROUND(ROUNDUP(G10,3),3)-ROUND(ROUNDDOWN(G10,3),3))))/(ROUNDUP(F10*2,0)/2-ROUNDDOWN(F10*2,0)/2)),"") -> 0.99066
A12: Tank 2 | B12: INITIAL | C12: ='Shore Tank Calculations'!D17 -> 27.5 | D12: 0.831 | E12: =IFERROR(IF((ROUNDUP(C12*2,0)/2-ROUNDDOWN(C12*2,0)/2)=0,IF((ROUND(ROUNDUP(D12,3),3)-ROUND(ROUNDDOWN(D12,3),3))=0,INDEX('Table 59B'!$D$10:$DT$420,MATCH(ROUND(ROUNDDOWN(D12,3),3),'Table 59B'!$C$10:$C$420,0),MATCH(ROUNDDOWN(C12*2,0)/2,'Table 59B'!$D$9:$DT$9,0)),INDEX('Table 59B'!$D$10:$DT$420,MATCH(ROUND(ROUNDUP(D12,3),3),'Table 59B'!$C$10:$C$420,0),MATCH(ROUNDDOWN(C12*2,0)/2,'Table 59B'!$D$9:$DT$9,0))-((INDEX('Table 59B'!$D$10:$DT$420,MATCH(ROUND(ROUNDUP(D12,3),3),'Table 59B'!$C$10:$C$420,0),MATCH(ROUNDDOWN(C12*2,0)/2,'Table 59B'!$D$9:$DT$9,0))-INDEX('Table 59B'!$D$10:$DT$420,MATCH(ROUND(ROUNDDOWN(D12,3),3),'Table 59B'!$C$10:$C$420,0),MATCH(ROUNDDOWN(C12*2,0)/2,'Table 59B'!$D$9:$DT$9,0)))*(ROUND(ROUNDUP(D12,3),3)-D12))/(ROUND(ROUNDUP(D12,3),3)-ROUND(ROUNDDOWN(D12,3),3))),IF((ROUND(ROUNDUP(D12,3),3)-ROUND(ROUNDDOWN(D12,3),3))=0,INDEX('Table 59B'!$D$10:$DT$420,MATCH(ROUND(ROUNDDOWN(D12,3),3),'Table 59B'!$C$10:$C$420,0),MATCH(ROUNDDOWN(C12*2,0)/2,'Table 59B'!$D$9:$DT$9,0)),INDEX('Table 59B'!$D$10:$DT$420,MATCH(ROUND(ROUNDUP(D12,3),3),'Table 59B'!$C$10:$C$420,0),MATCH(ROUNDDOWN(C12*2,0)/2,'Table 59B'!$D$9:$DT$9,0))-((INDEX('Table 59B'!$D$10:$DT$420,MATCH(ROUND(ROUNDUP(D12,3),3),'Table 59B'!$C$10:$C$420,0),MATCH(ROUNDDOWN(C12*2,0)/2,'Table 59B'!$D$9:$DT$9,0))-INDEX('Table 59B'!$D$10:$DT$420,MATCH(ROUND(ROUNDDOWN(D12,3),3),'Table 59B'!$C$10:$C$420,0),MATCH(ROUNDDOWN(C12*2,0)/2,'Table 59B'!$D$9:$DT$9,0)))*(ROUND(ROUNDUP(D12,3),3)-D12))/(ROUND(ROUNDUP(D12,3),3)-ROUND(ROUNDDOWN(D12,3),3)))+(C12-ROUNDDOWN(C12*2,0)/2)*(IF((ROUND(ROUNDUP(D12,3),3)-ROUND(ROUNDDOWN(D12,3),3))=0,INDEX('Table 59B'!$D$10:$DT$420,MATCH(ROUND(ROUNDDOWN(D12,3),3),'Table 59B'!$C$10:$C$420,0),MATCH(ROUNDUP(C12*2,0)/2,'Table 59B'!$D$9:$DT$9,0)),INDEX('Table 59B'!$D$10:$DT$420,MATCH(ROUND(ROUNDUP(D12,3),3),'Table 59B'!$C$10:$C$420,0),MATCH(ROUNDUP(C12*2,0)/2,'Table 59B'!$D$9:$DT$9,0))-((INDEX('Table 59B'!$D$10:$DT$420,MATCH(ROUND(ROUNDUP(D12,3),3),'Table 59B'!$C$10:$C$420,0),MATCH(ROUNDUP(C12*2,0)/2,'Table 59B'!$D$9:$DT$9,0))-INDEX('Table 59B'!$D$10:$DT$420,MATCH(ROUND(ROUNDDOWN(D12,3),3),'Table 59B'!$C$10:$C$420,0),MATCH(ROUNDUP(C12*2,0)/2,'Table 59B'!$D$9:$DT$9,0)))*(ROUND(ROUNDUP(D12,3),3)-D12))/(ROUND(ROUNDUP(D12,3),3)-ROUND(ROUNDDOWN(D12,3),3)))-IF((ROUND(ROUNDUP(D12,3),3)-ROUND(ROUNDDOWN(D12,3),3))=0,INDEX('Table 59B'!$D$10:$DT$420,MATCH(ROUND(ROUNDDOWN(D12,3),3),'Table 59B'!$C$10:$C$420,0),MATCH(ROUNDDOWN(C12*2,0)/2,'Table 59B'!$D$9:$DT$9,0)),INDEX('Table 59B'!$D$10:$DT$420,MATCH(ROUND(ROUNDUP(D12,3),3),'Table 59B'!$C$10:$C$420,0),MATCH(ROUNDDOWN(C12*2,0)/2,'Table 59B'!$D$9:$DT$9,0))-((INDEX('Table 59B'!$D$10:$DT$420,MATCH(ROUND(ROUNDUP(D12,3),3),'Table 59B'!$C$10:$C$420,0),MATCH(ROUNDDOWN(C12*2,0)/2,'Table 59B'!$D$9:$DT$9,0))-INDEX('Table 59B'!$D$10:$DT$420,MATCH(ROUND(ROUNDDOWN(D12,3),3),'Table 59B'!$C$10:$C$420,0),MATCH(ROUNDDOWN(C12*2,0)/2,'Table 59B'!$D$9:$DT$9,0)))*(ROUND(ROUNDUP(D12,3),3)-D12))/(ROUND(ROUNDUP(D12,3),3)-ROUND(ROUNDDOWN(D12,3),3))))/(ROUNDUP(C12*2,0)/2-ROUNDDOWN(C12*2,0)/2)),"") -> 0.8362 | F12: =IF('Shore Tank Calculations'!D16="","",'Shore Tank Calculations'!D16) -> 28 | G12: 0.8362 | H12: =IFERROR(IF((ROUNDUP(F12*2,0)/2-ROUNDDOWN(F12*2,0)/2)=0,IF((ROUND(ROUNDUP(G12,3),3)-ROUND(ROUNDDOWN(G12,3),3))=0,INDEX('Table 60B'!$D$10:$DT$420,MATCH(ROUND(ROUNDDOWN(G12,3),3),'Table 60B'!$C$10:$C$420,0),MATCH(ROUNDDOWN(F12*2,0)/2,'Table 60B'!$D$9:$DT$9,0)),INDEX('Table 60B'!$D$10:$DT$420,MATCH(ROUND(ROUNDUP(G12,3),3),'Table 60B'!$C$10:$C$420,0),MATCH(ROUNDDOWN(F12*2,0)/2,'Table 60B'!$D$9:$DT$9,0))-((INDEX('Table 60B'!$D$10:$DT$420,MATCH(ROUND(ROUNDUP(G12,3),3),'Table 60B'!$C$10:$C$420,0),MATCH(ROUNDDOWN(F12*2,0)/2,'Table 60B'!$D$9:$DT$9,0))-INDEX('Table 60B'!$D$10:$DT$420,MATCH(ROUND(ROUNDDOWN(G12,3),3),'Table 60B'!$C$10:$C$420,0),MATCH(ROUNDDOWN(F12*2,0)/2,'Table 60B'!$D$9:$DT$9,0)))*(ROUND(ROUNDUP(G12,3),3)-G12))/(ROUND(ROUNDUP(G12,3),3)-ROUND(ROUNDDOWN(G12,3),3))),IF((ROUND(ROUNDUP(G12,3),3)-ROUND(ROUNDDOWN(G12,3),3))=0,INDEX('Table 60B'!$D$10:$DT$420,MATCH(ROUND(ROUNDDOWN(G12,3),3),'Table 60B'!$C$10:$C$420,0),MATCH(ROUNDDOWN(F12*2,0)/2,'Table 60B'!$D$9:$DT$9,0)),INDEX('Table 60B'!$D$10:$DT$420,MATCH(ROUND(ROUNDUP(G12,3),3),'Table 60B'!$C$10:$C$420,0),MATCH(ROUNDDOWN(F12*2,0)/2,'Table 60B'!$D$9:$DT$9,0))-((INDEX('Table 60B'!$D$10:$DT$420,MATCH(ROUND(ROUNDUP(G12,3),3),'Table 60B'!$C$10:$C$420,0),MATCH(ROUNDDOWN(F12*2,0)/2,'Table 60B'!$D$9:$DT$9,0))-INDEX('Table 60B'!$D$10:$DT$420,MATCH(ROUND(ROUNDDOWN(G12,3),3),'Table 60B'!$C$10:$C$420,0),MATCH(ROUNDDOWN(F12*2,0)/2,'Table 60B'!$D$9:$DT$9,0)))*(ROUND(ROUNDUP(G12,3),3)-G12))/(ROUND(ROUNDUP(G12,3),3)-ROUND(ROUNDDOWN(G12,3),3)))+(F12-ROUNDDOWN(F12*2,0)/2)*(IF((ROUND(ROUNDUP(G12,3),3)-ROUND(ROUNDDOWN(G12,3),3))=0,INDEX('Table 60B'!$D$10:$DT$420,MATCH(ROUND(ROUNDDOWN(G12,3),3),'Table 60B'!$C$10:$C$420,0),MATCH(ROUNDUP(F12*2,0)/2,'Table 60B'!$D$9:$DT$9,0)),INDEX('Table 60B'!$D$10:$DT$420,MATCH(ROUND(ROUNDUP(G12,3),3),'Table 60B'!$C$10:$C$420,0),MATCH(ROUNDUP(F12*2,0)/2,'Table 60B'!$D$9:$DT$9,0))-((INDEX('Table 60B'!$D$10:$DT$420,MATCH(ROUND(ROUNDUP(G12,3),3),'Table 60B'!$C$10:$C$420,0),MATCH(ROUNDUP(F12*2,0)/2,'Table 60B'!$D$9:$DT$9,0))-INDEX('Table 60B'!$D$10:$DT$420,MATCH(ROUND(ROUNDDOWN(G12,3),3),'Table 60B'!$C$10:$C$420,0),MATCH(ROUNDUP(F12*2,0)/2,'Table 60B'!$D$9:$DT$9,0)))*(ROUND(ROUNDUP(G12,3),3)-G12))/(ROUND(ROUNDUP(G12,3),3)-ROUND(ROUNDDOWN(G12,3),3)))-IF((ROUND(ROUNDUP(G12,3),3)-ROUND(ROUNDDOWN(G12,3),3))=0,INDEX('Table 60B'!$D$10:$DT$420,MATCH(ROUND(ROUNDDOWN(G12,3),3),'Table 60B'!$C$10:$C$420,0),MATCH(ROUNDDOWN(F12*2,0)/2,'Table 60B'!$D$9:$DT$9,0)),INDEX('Table 60B'!$D$10:$DT$420,MATCH(ROUND(ROUNDUP(G12,3),3),'Table 60B'!$C$10:$C$420,0),MATCH(ROUNDDOWN(F12*2,0)/2,'Table 60B'!$D$9:$DT$9,0))-((INDEX('Table 60B'!$D$10:$DT$420,MATCH(ROUND(ROUNDUP(G12,3),3),'Table 60B'!$C$10:$C$420,0),MATCH(ROUNDDOWN(F12*2,0)/2,'Table 60B'!$D$9:$DT$9,0))-INDEX('Table 60B'!$D$10:$DT$420,MATCH(ROUND(ROUNDDOWN(G12,3),3),'Table 60B'!$C$10:$C$420,0),MATCH(ROUNDDOWN(F12*2,0)/2,'Table 60B'!$D$9:$DT$9,0)))*(ROUND(ROUNDUP(G12,3),3)-G12))/(ROUND(ROUNDUP(G12,3),3)-ROUND(ROUNDDOWN(G12,3),3))))/(ROUNDUP(F12*2,0)/2-ROUNDDOWN(F12*2,0)/2)),"") -> 0.993224 | I12: ← sample density corrected to 20°C via Table 59B; VCF from Table 60B
B13: FINAL | C13: ='Shore Tank Calculations'!E17 -> 31.5 | D13: 0.828 | E13: =IFERROR(IF((ROUNDUP(C13*2,0)/2-ROUNDDOWN(C13*2,0)/2)=0,IF((ROUND(ROUNDUP(D13,3),3)-ROUND(ROUNDDOWN(D13,3),3))=0,INDEX('Table 59B'!$D$10:$DT$420,MATCH(ROUND(ROUNDDOWN(D13,3),3),'Table 59B'!$C$10:$C$420,0),MATCH(ROUNDDOWN(C13*2,0)/2,'Table 59B'!$D$9:$DT$9,0)),INDEX('Table 59B'!$D$10:$DT$420,MATCH(ROUND(ROUNDUP(D13,3),3),'Table 59B'!$C$10:$C$420,0),MATCH(ROUNDDOWN(C13*2,0)/2,'Table 59B'!$D$9:$DT$9,0))-((INDEX('Table 59B'!$D$10:$DT$420,MATCH(ROUND(ROUNDUP(D13,3),3),'Table 59B'!$C$10:$C$420,0),MATCH(ROUNDDOWN(C13*2,0)/2,'Table 59B'!$D$9:$DT$9,0))-INDEX('Table 59B'!$D$10:$DT$420,MATCH(ROUND(ROUNDDOWN(D13,3),3),'Table 59B'!$C$10:$C$420,0),MATCH(ROUNDDOWN(C13*2,0)/2,'Table 59B'!$D$9:$DT$9,0)))*(ROUND(ROUNDUP(D13,3),3)-D13))/(ROUND(ROUNDUP(D13,3),3)-ROUND(ROUNDDOWN(D13,3),3))),IF((ROUND(ROUNDUP(D13,3),3)-ROUND(ROUNDDOWN(D13,3),3))=0,INDEX('Table 59B'!$D$10:$DT$420,MATCH(ROUND(ROUNDDOWN(D13,3),3),'Table 59B'!$C$10:$C$420,0),MATCH(ROUNDDOWN(C13*2,0)/2,'Table 59B'!$D$9:$DT$9,0)),INDEX('Table 59B'!$D$10:$DT$420,MATCH(ROUND(ROUNDUP(D13,3),3),'Table 59B'!$C$10:$C$420,0),MATCH(ROUNDDOWN(C13*2,0)/2,'Table 59B'!$D$9:$DT$9,0))-((INDEX('Table 59B'!$D$10:$DT$420,MATCH(ROUND(ROUNDUP(D13,3),3),'Table 59B'!$C$10:$C$420,0),MATCH(ROUNDDOWN(C13*2,0)/2,'Table 59B'!$D$9:$DT$9,0))-INDEX('Table 59B'!$D$10:$DT$420,MATCH(ROUND(ROUNDDOWN(D13,3),3),'Table 59B'!$C$10:$C$420,0),MATCH(ROUNDDOWN(C13*2,0)/2,'Table 59B'!$D$9:$DT$9,0)))*(ROUND(ROUNDUP(D13,3),3)-D13))/(ROUND(ROUNDUP(D13,3),3)-ROUND(ROUNDDOWN(D13,3),3)))+(C13-ROUNDDOWN(C13*2,0)/2)*(IF((ROUND(ROUNDUP(D13,3),3)-ROUND(ROUNDDOWN(D13,3),3))=0,INDEX('Table 59B'!$D$10:$DT$420,MATCH(ROUND(ROUNDDOWN(D13,3),3),'Table 59B'!$C$10:$C$420,0),MATCH(ROUNDUP(C13*2,0)/2,'Table 59B'!$D$9:$DT$9,0)),INDEX('Table 59B'!$D$10:$DT$420,MATCH(ROUND(ROUNDUP(D13,3),3),'Table 59B'!$C$10:$C$420,0),MATCH(ROUNDUP(C13*2,0)/2,'Table 59B'!$D$9:$DT$9,0))-((INDEX('Table 59B'!$D$10:$DT$420,MATCH(ROUND(ROUNDUP(D13,3),3),'Table 59B'!$C$10:$C$420,0),MATCH(ROUNDUP(C13*2,0)/2,'Table 59B'!$D$9:$DT$9,0))-INDEX('Table 59B'!$D$10:$DT$420,MATCH(ROUND(ROUNDDOWN(D13,3),3),'Table 59B'!$C$10:$C$420,0),MATCH(ROUNDUP(C13*2,0)/2,'Table 59B'!$D$9:$DT$9,0)))*(ROUND(ROUNDUP(D13,3),3)-D13))/(ROUND(ROUNDUP(D13,3),3)-ROUND(ROUNDDOWN(D13,3),3)))-IF((ROUND(ROUNDUP(D13,3),3)-ROUND(ROUNDDOWN(D13,3),3))=0,INDEX('Table 59B'!$D$10:$DT$420,MATCH(ROUND(ROUNDDOWN(D13,3),3),'Table 59B'!$C$10:$C$420,0),MATCH(ROUNDDOWN(C13*2,0)/2,'Table 59B'!$D$9:$DT$9,0)),INDEX('Table 59B'!$D$10:$DT$420,MATCH(ROUND(ROUNDUP(D13,3),3),'Table 59B'!$C$10:$C$420,0),MATCH(ROUNDDOWN(C13*2,0)/2,'Table 59B'!$D$9:$DT$9,0))-((INDEX('Table 59B'!$D$10:$DT$420,MATCH(ROUND(ROUNDUP(D13,3),3),'Table 59B'!$C$10:$C$420,0),MATCH(ROUNDDOWN(C13*2,0)/2,'Table 59B'!$D$9:$DT$9,0))-INDEX('Table 59B'!$D$10:$DT$420,MATCH(ROUND(ROUNDDOWN(D13,3),3),'Table 59B'!$C$10:$C$420,0),MATCH(ROUNDDOWN(C13*2,0)/2,'Table 59B'!$D$9:$DT$9,0)))*(ROUND(ROUNDUP(D13,3),3)-D13))/(ROUND(ROUNDUP(D13,3),3)-ROUND(ROUNDDOWN(D13,3),3))))/(ROUNDUP(C13*2,0)/2-ROUNDDOWN(C13*2,0)/2)),"") -> 0.836 | F13: =IF('Shore Tank Calculations'!E16="","",'Shore Tank Calculations'!E16) -> 31.5 | G13: 0.836 | H13: =IFERROR(IF((ROUNDUP(F13*2,0)/2-ROUNDDOWN(F13*2,0)/2)=0,IF((ROUND(ROUNDUP(G13,3),3)-ROUND(ROUNDDOWN(G13,3),3))=0,INDEX('Table 60B'!$D$10:$DT$420,MATCH(ROUND(ROUNDDOWN(G13,3),3),'Table 60B'!$C$10:$C$420,0),MATCH(ROUNDDOWN(F13*2,0)/2,'Table 60B'!$D$9:$DT$9,0)),INDEX('Table 60B'!$D$10:$DT$420,MATCH(ROUND(ROUNDUP(G13,3),3),'Table 60B'!$C$10:$C$420,0),MATCH(ROUNDDOWN(F13*2,0)/2,'Table 60B'!$D$9:$DT$9,0))-((INDEX('Table 60B'!$D$10:$DT$420,MATCH(ROUND(ROUNDUP(G13,3),3),'Table 60B'!$C$10:$C$420,0),MATCH(ROUNDDOWN(F13*2,0)/2,'Table 60B'!$D$9:$DT$9,0))-INDEX('Table 60B'!$D$10:$DT$420,MATCH(ROUND(ROUNDDOWN(G13,3),3),'Table 60B'!$C$10:$C$420,0),MATCH(ROUNDDOWN(F13*2,0)/2,'Table 60B'!$D$9:$DT$9,0)))*(ROUND(ROUNDUP(G13,3),3)-G13))/(ROUND(ROUNDUP(G13,3),3)-ROUND(ROUNDDOWN(G13,3),3))),IF((ROUND(ROUNDUP(G13,3),3)-ROUND(ROUNDDOWN(G13,3),3))=0,INDEX('Table 60B'!$D$10:$DT$420,MATCH(ROUND(ROUNDDOWN(G13,3),3),'Table 60B'!$C$10:$C$420,0),MATCH(ROUNDDOWN(F13*2,0)/2,'Table 60B'!$D$9:$DT$9,0)),INDEX('Table 60B'!$D$10:$DT$420,MATCH(ROUND(ROUNDUP(G13,3),3),'Table 60B'!$C$10:$C$420,0),MATCH(ROUNDDOWN(F13*2,0)/2,'Table 60B'!$D$9:$DT$9,0))-((INDEX('Table 60B'!$D$10:$DT$420,MATCH(ROUND(ROUNDUP(G13,3),3),'Table 60B'!$C$10:$C$420,0),MATCH(ROUNDDOWN(F13*2,0)/2,'Table 60B'!$D$9:$DT$9,0))-INDEX('Table 60B'!$D$10:$DT$420,MATCH(ROUND(ROUNDDOWN(G13,3),3),'Table 60B'!$C$10:$C$420,0),MATCH(ROUNDDOWN(F13*2,0)/2,'Table 60B'!$D$9:$DT$9,0)))*(ROUND(ROUNDUP(G13,3),3)-G13))/(ROUND(ROUNDUP(G13,3),3)-ROUND(ROUNDDOWN(G13,3),3)))+(F13-ROUNDDOWN(F13*2,0)/2)*(IF((ROUND(ROUNDUP(G13,3),3)-ROUND(ROUNDDOWN(G13,3),3))=0,INDEX('Table 60B'!$D$10:$DT$420,MATCH(ROUND(ROUNDDOWN(G13,3),3),'Table 60B'!$C$10:$C$420,0),MATCH(ROUNDUP(F13*2,0)/2,'Table 60B'!$D$9:$DT$9,0)),INDEX('Table 60B'!$D$10:$DT$420,MATCH(ROUND(ROUNDUP(G13,3),3),'Table 60B'!$C$10:$C$420,0),MATCH(ROUNDUP(F13*2,0)/2,'Table 60B'!$D$9:$DT$9,0))-((INDEX('Table 60B'!$D$10:$DT$420,MATCH(ROUND(ROUNDUP(G13,3),3),'Table 60B'!$C$10:$C$420,0),MATCH(ROUNDUP(F13*2,0)/2,'Table 60B'!$D$9:$DT$9,0))-INDEX('Table 60B'!$D$10:$DT$420,MATCH(ROUND(ROUNDDOWN(G13,3),3),'Table 60B'!$C$10:$C$420,0),MATCH(ROUNDUP(F13*2,0)/2,'Table 60B'!$D$9:$DT$9,0)))*(ROUND(ROUNDUP(G13,3),3)-G13))/(ROUND(ROUNDUP(G13,3),3)-ROUND(ROUNDDOWN(G13,3),3)))-IF((ROUND(ROUNDUP(G13,3),3)-ROUND(ROUNDDOWN(G13,3),3))=0,INDEX('Table 60B'!$D$10:$DT$420,MATCH(ROUND(ROUNDDOWN(G13,3),3),'Table 60B'!$C$10:$C$420,0),MATCH(ROUNDDOWN(F13*2,0)/2,'Table 60B'!$D$9:$DT$9,0)),INDEX('Table 60B'!$D$10:$DT$420,MATCH(ROUND(ROUNDUP(G13,3),3),'Table 60B'!$C$10:$C$420,0),MATCH(ROUNDDOWN(F13*2,0)/2,'Table 60B'!$D$9:$DT$9,0))-((INDEX('Table 60B'!$D$10:$DT$420,MATCH(ROUND(ROUNDUP(G13,3),3),'Table 60B'!$C$10:$C$420,0),MATCH(ROUNDDOWN(F13*2,0)/2,'Table 60B'!$D$9:$DT$9,0))-INDEX('Table 60B'!$D$10:$DT$420,MATCH(ROUND(ROUNDDOWN(G13,3),3),'Table 60B'!$C$10:$C$420,0),MATCH(ROUNDDOWN(F13*2,0)/2,'Table 60B'!$D$9:$DT$9,0)))*(ROUND(ROUNDUP(G13,3),3)-G13))/(ROUND(ROUNDUP(G13,3),3)-ROUND(ROUNDDOWN(G13,3),3))))/(ROUNDUP(F13*2,0)/2-ROUNDDOWN(F13*2,0)/2)),"") -> 0.99022
A15: Tank 3 | B15: INITIAL | C15: ='Shore Tank Calculations'!F17 -> 28.5 | D15: 0.831 | E15: =IFERROR(IF((ROUNDUP(C15*2,0)/2-ROUNDDOWN(C15*2,0)/2)=0,IF((ROUND(ROUNDUP(D15,3),3)-ROUND(ROUNDDOWN(D15,3),3))=0,INDEX('Table 59B'!$D$10:$DT$420,MATCH(ROUND(ROUNDDOWN(D15,3),3),'Table 59B'!$C$10:$C$420,0),MATCH(ROUNDDOWN(C15*2,0)/2,'Table 59B'!$D$9:$DT$9,0)),INDEX('Table 59B'!$D$10:$DT$420,MATCH(ROUND(ROUNDUP(D15,3),3),'Table 59B'!$C$10:$C$420,0),MATCH(ROUNDDOWN(C15*2,0)/2,'Table 59B'!$D$9:$DT$9,0))-((INDEX('Table 59B'!$D$10:$DT$420,MATCH(ROUND(ROUNDUP(D15,3),3),'Table 59B'!$C$10:$C$420,0),MATCH(ROUNDDOWN(C15*2,0)/2,'Table 59B'!$D$9:$DT$9,0))-INDEX('Table 59B'!$D$10:$DT$420,MATCH(ROUND(ROUNDDOWN(D15,3),3),'Table 59B'!$C$10:$C$420,0),MATCH(ROUNDDOWN(C15*2,0)/2,'Table 59B'!$D$9:$DT$9,0)))*(ROUND(ROUNDUP(D15,3),3)-D15))/(ROUND(ROUNDUP(D15,3),3)-ROUND(ROUNDDOWN(D15,3),3))),IF((ROUND(ROUNDUP(D15,3),3)-ROUND(ROUNDDOWN(D15,3),3))=0,INDEX('Table 59B'!$D$10:$DT$420,MATCH(ROUND(ROUNDDOWN(D15,3),3),'Table 59B'!$C$10:$C$420,0),MATCH(ROUNDDOWN(C15*2,0)/2,'Table 59B'!$D$9:$DT$9,0)),INDEX('Table 59B'!$D$10:$DT$420,MATCH(ROUND(ROUNDUP(D15,3),3),'Table 59B'!$C$10:$C$420,0),MATCH(ROUNDDOWN(C15*2,0)/2,'Table 59B'!$D$9:$DT$9,0))-((INDEX('Table 59B'!$D$10:$DT$420,MATCH(ROUND(ROUNDUP(D15,3),3),'Table 59B'!$C$10:$C$420,0),MATCH(ROUNDDOWN(C15*2,0)/2,'Table 59B'!$D$9:$DT$9,0))-INDEX('Table 59B'!$D$10:$DT$420,MATCH(ROUND(ROUNDDOWN(D15,3),3),'Table 59B'!$C$10:$C$420,0),MATCH(ROUNDDOWN(C15*2,0)/2,'Table 59B'!$D$9:$DT$9,0)))*(ROUND(ROUNDUP(D15,3),3)-D15))/(ROUND(ROUNDUP(D15,3),3)-ROUND(ROUNDDOWN(D15,3),3)))+(C15-ROUNDDOWN(C15*2,0)/2)*(IF((ROUND(ROUNDUP(D15,3),3)-ROUND(ROUNDDOWN(D15,3),3))=0,INDEX('Table 59B'!$D$10:$DT$420,MATCH(ROUND(ROUNDDOWN(D15,3),3),'Table 59B'!$C$10:$C$420,0),MATCH(ROUNDUP(C15*2,0)/2,'Table 59B'!$D$9:$DT$9,0)),INDEX('Table 59B'!$D$10:$DT$420,MATCH(ROUND(ROUNDUP(D15,3),3),'Table 59B'!$C$10:$C$420,0),MATCH(ROUNDUP(C15*2,0)/2,'Table 59B'!$D$9:$DT$9,0))-((INDEX('Table 59B'!$D$10:$DT$420,MATCH(ROUND(ROUNDUP(D15,3),3),'Table 59B'!$C$10:$C$420,0),MATCH(ROUNDUP(C15*2,0)/2,'Table 59B'!$D$9:$DT$9,0))-INDEX('Table 59B'!$D$10:$DT$420,MATCH(ROUND(ROUNDDOWN(D15,3),3),'Table 59B'!$C$10:$C$420,0),MATCH(ROUNDUP(C15*2,0)/2,'Table 59B'!$D$9:$DT$9,0)))*(ROUND(ROUNDUP(D15,3),3)-D15))/(ROUND(ROUNDUP(D15,3),3)-ROUND(ROUNDDOWN(D15,3),3)))-IF((ROUND(ROUNDUP(D15,3),3)-ROUND(ROUNDDOWN(D15,3),3))=0,INDEX('Table 59B'!$D$10:$DT$420,MATCH(ROUND(ROUNDDOWN(D15,3),3),'Table 59B'!$C$10:$C$420,0),MATCH(ROUNDDOWN(C15*2,0)/2,'Table 59B'!$D$9:$DT$9,0)),INDEX('Table 59B'!$D$10:$DT$420,MATCH(ROUND(ROUNDUP(D15,3),3),'Table 59B'!$C$10:$C$420,0),MATCH(ROUNDDOWN(C15*2,0)/2,'Table 59B'!$D$9:$DT$9,0))-((INDEX('Table 59B'!$D$10:$DT$420,MATCH(ROUND(ROUNDUP(D15,3),3),'Table 59B'!$C$10:$C$420,0),MATCH(ROUNDDOWN(C15*2,0)/2,'Table 59B'!$D$9:$DT$9,0))-INDEX('Table 59B'!$D$10:$DT$420,MATCH(ROUND(ROUNDDOWN(D15,3),3),'Table 59B'!$C$10:$C$420,0),MATCH(ROUNDDOWN(C15*2,0)/2,'Table 59B'!$D$9:$DT$9,0)))*(ROUND(ROUNDUP(D15,3),3)-D15))/(ROUND(ROUNDUP(D15,3),3)-ROUND(ROUNDDOWN(D15,3),3))))/(ROUNDUP(C15*2,0)/2-ROUNDDOWN(C15*2,0)/2)),"") -> 0.8369 | F15: =IF('Shore Tank Calculations'!F16="","",'Shore Tank Calculations'!F16) -> 29 | G15: =IF(E15="","",E15) -> 0.8369 | H15: =IFERROR(IF((ROUNDUP(F15*2,0)/2-ROUNDDOWN(F15*2,0)/2)=0,IF((ROUND(ROUNDUP(G15,3),3)-ROUND(ROUNDDOWN(G15,3),3))=0,INDEX('Table 60B'!$D$10:$DT$420,MATCH(ROUND(ROUNDDOWN(G15,3),3),'Table 60B'!$C$10:$C$420,0),MATCH(ROUNDDOWN(F15*2,0)/2,'Table 60B'!$D$9:$DT$9,0)),INDEX('Table 60B'!$D$10:$DT$420,MATCH(ROUND(ROUNDUP(G15,3),3),'Table 60B'!$C$10:$C$420,0),MATCH(ROUNDDOWN(F15*2,0)/2,'Table 60B'!$D$9:$DT$9,0))-((INDEX('Table 60B'!$D$10:$DT$420,MATCH(ROUND(ROUNDUP(G15,3),3),'Table 60B'!$C$10:$C$420,0),MATCH(ROUNDDOWN(F15*2,0)/2,'Table 60B'!$D$9:$DT$9,0))-INDEX('Table 60B'!$D$10:$DT$420,MATCH(ROUND(ROUNDDOWN(G15,3),3),'Table 60B'!$C$10:$C$420,0),MATCH(ROUNDDOWN(F15*2,0)/2,'Table 60B'!$D$9:$DT$9,0)))*(ROUND(ROUNDUP(G15,3),3)-G15))/(ROUND(ROUNDUP(G15,3),3)-ROUND(ROUNDDOWN(G15,3),3))),IF((ROUND(ROUNDUP(G15,3),3)-ROUND(ROUNDDOWN(G15,3),3))=0,INDEX('Table 60B'!$D$10:$DT$420,MATCH(ROUND(ROUNDDOWN(G15,3),3),'Table 60B'!$C$10:$C$420,0),MATCH(ROUNDDOWN(F15*2,0)/2,'Table 60B'!$D$9:$DT$9,0)),INDEX('Table 60B'!$D$10:$DT$420,MATCH(ROUND(ROUNDUP(G15,3),3),'Table 60B'!$C$10:$C$420,0),MATCH(ROUNDDOWN(F15*2,0)/2,'Table 60B'!$D$9:$DT$9,0))-((INDEX('Table 60B'!$D$10:$DT$420,MATCH(ROUND(ROUNDUP(G15,3),3),'Table 60B'!$C$10:$C$420,0),MATCH(ROUNDDOWN(F15*2,0)/2,'Table 60B'!$D$9:$DT$9,0))-INDEX('Table 60B'!$D$10:$DT$420,MATCH(ROUND(ROUNDDOWN(G15,3),3),'Table 60B'!$C$10:$C$420,0),MATCH(ROUNDDOWN(F15*2,0)/2,'Table 60B'!$D$9:$DT$9,0)))*(ROUND(ROUNDUP(G15,3),3)-G15))/(ROUND(ROUNDUP(G15,3),3)-ROUND(ROUNDDOWN(G15,3),3)))+(F15-ROUNDDOWN(F15*2,0)/2)*(IF((ROUND(ROUNDUP(G15,3),3)-ROUND(ROUNDDOWN(G15,3),3))=0,INDEX('Table 60B'!$D$10:$DT$420,MATCH(ROUND(ROUNDDOWN(G15,3),3),'Table 60B'!$C$10:$C$420,0),MATCH(ROUNDUP(F15*2,0)/2,'Table 60B'!$D$9:$DT$9,0)),INDEX('Table 60B'!$D$10:$DT$420,MATCH(ROUND(ROUNDUP(G15,3),3),'Table 60B'!$C$10:$C$420,0),MATCH(ROUNDUP(F15*2,0)/2,'Table 60B'!$D$9:$DT$9,0))-((INDEX('Table 60B'!$D$10:$DT$420,MATCH(ROUND(ROUNDUP(G15,3),3),'Table 60B'!$C$10:$C$420,0),MATCH(ROUNDUP(F15*2,0)/2,'Table 60B'!$D$9:$DT$9,0))-INDEX('Table 60B'!$D$10:$DT$420,MATCH(ROUND(ROUNDDOWN(G15,3),3),'Table 60B'!$C$10:$C$420,0),MATCH(ROUNDUP(F15*2,0)/2,'Table 60B'!$D$9:$DT$9,0)))*(ROUND(ROUNDUP(G15,3),3)-G15))/(ROUND(ROUNDUP(G15,3),3)-ROUND(ROUNDDOWN(G15,3),3)))-IF((ROUND(ROUNDUP(G15,3),3)-ROUND(ROUNDDOWN(G15,3),3))=0,INDEX('Table 60B'!$D$10:$DT$420,MATCH(ROUND(ROUNDDOWN(G15,3),3),'Table 60B'!$C$10:$C$420,0),MATCH(ROUNDDOWN(F15*2,0)/2,'Table 60B'!$D$9:$DT$9,0)),INDEX('Table 60B'!$D$10:$DT$420,MATCH(ROUND(ROUNDUP(G15,3),3),'Table 60B'!$C$10:$C$420,0),MATCH(ROUNDDOWN(F15*2,0)/2,'Table 60B'!$D$9:$DT$9,0))-((INDEX('Table 60B'!$D$10:$DT$420,MATCH(ROUND(ROUNDUP(G15,3),3),'Table 60B'!$C$10:$C$420,0),MATCH(ROUNDDOWN(F15*2,0)/2,'Table 60B'!$D$9:$DT$9,0))-INDEX('Table 60B'!$D$10:$DT$420,MATCH(ROUND(ROUNDDOWN(G15,3),3),'Table 60B'!$C$10:$C$420,0),MATCH(ROUNDDOWN(F15*2,0)/2,'Table 60B'!$D$9:$DT$9,0)))*(ROUND(ROUNDUP(G15,3),3)-G15))/(ROUND(ROUNDUP(G15,3),3)-ROUND(ROUNDDOWN(G15,3),3))))/(ROUNDUP(F15*2,0)/2-ROUNDDOWN(F15*2,0)/2)),"") -> 0.992369 | I15: ← sample density corrected to 20°C via Table 59B; VCF from Table 60B
B16: FINAL | C16: ='Shore Tank Calculations'!G17 -> 31 | D16: 0.827 | E16: =IFERROR(IF((ROUNDUP(C16*2,0)/2-ROUNDDOWN(C16*2,0)/2)=0,IF((ROUND(ROUNDUP(D16,3),3)-ROUND(ROUNDDOWN(D16,3),3))=0,INDEX('Table 59B'!$D$10:$DT$420,MATCH(ROUND(ROUNDDOWN(D16,3),3),'Table 59B'!$C$10:$C$420,0),MATCH(ROUNDDOWN(C16*2,0)/2,'Table 59B'!$D$9:$DT$9,0)),INDEX('Table 59B'!$D$10:$DT$420,MATCH(ROUND(ROUNDUP(D16,3),3),'Table 59B'!$C$10:$C$420,0),MATCH(ROUNDDOWN(C16*2,0)/2,'Table 59B'!$D$9:$DT$9,0))-((INDEX('Table 59B'!$D$10:$DT$420,MATCH(ROUND(ROUNDUP(D16,3),3),'Table 59B'!$C$10:$C$420,0),MATCH(ROUNDDOWN(C16*2,0)/2,'Table 59B'!$D$9:$DT$9,0))-INDEX('Table 59B'!$D$10:$DT$420,MATCH(ROUND(ROUNDDOWN(D16,3),3),'Table 59B'!$C$10:$C$420,0),MATCH(ROUNDDOWN(C16*2,0)/2,'Table 59B'!$D$9:$DT$9,0)))*(ROUND(ROUNDUP(D16,3),3)-D16))/(ROUND(ROUNDUP(D16,3),3)-ROUND(ROUNDDOWN(D16,3),3))),IF((ROUND(ROUNDUP(D16,3),3)-ROUND(ROUNDDOWN(D16,3),3))=0,INDEX('Table 59B'!$D$10:$DT$420,MATCH(ROUND(ROUNDDOWN(D16,3),3),'Table 59B'!$C$10:$C$420,0),MATCH(ROUNDDOWN(C16*2,0)/2,'Table 59B'!$D$9:$DT$9,0)),INDEX('Table 59B'!$D$10:$DT$420,MATCH(ROUND(ROUNDUP(D16,3),3),'Table 59B'!$C$10:$C$420,0),MATCH(ROUNDDOWN(C16*2,0)/2,'Table 59B'!$D$9:$DT$9,0))-((INDEX('Table 59B'!$D$10:$DT$420,MATCH(ROUND(ROUNDUP(D16,3),3),'Table 59B'!$C$10:$C$420,0),MATCH(ROUNDDOWN(C16*2,0)/2,'Table 59B'!$D$9:$DT$9,0))-INDEX('Table 59B'!$D$10:$DT$420,MATCH(ROUND(ROUNDDOWN(D16,3),3),'Table 59B'!$C$10:$C$420,0),MATCH(ROUNDDOWN(C16*2,0)/2,'Table 59B'!$D$9:$DT$9,0)))*(ROUND(ROUNDUP(D16,3),3)-D16))/(ROUND(ROUNDUP(D16,3),3)-ROUND(ROUNDDOWN(D16,3),3)))+(C16-ROUNDDOWN(C16*2,0)/2)*(IF((ROUND(ROUNDUP(D16,3),3)-ROUND(ROUNDDOWN(D16,3),3))=0,INDEX('Table 59B'!$D$10:$DT$420,MATCH(ROUND(ROUNDDOWN(D16,3),3),'Table 59B'!$C$10:$C$420,0),MATCH(ROUNDUP(C16*2,0)/2,'Table 59B'!$D$9:$DT$9,0)),INDEX('Table 59B'!$D$10:$DT$420,MATCH(ROUND(ROUNDUP(D16,3),3),'Table 59B'!$C$10:$C$420,0),MATCH(ROUNDUP(C16*2,0)/2,'Table 59B'!$D$9:$DT$9,0))-((INDEX('Table 59B'!$D$10:$DT$420,MATCH(ROUND(ROUNDUP(D16,3),3),'Table 59B'!$C$10:$C$420,0),MATCH(ROUNDUP(C16*2,0)/2,'Table 59B'!$D$9:$DT$9,0))-INDEX('Table 59B'!$D$10:$DT$420,MATCH(ROUND(ROUNDDOWN(D16,3),3),'Table 59B'!$C$10:$C$420,0),MATCH(ROUNDUP(C16*2,0)/2,'Table 59B'!$D$9:$DT$9,0)))*(ROUND(ROUNDUP(D16,3),3)-D16))/(ROUND(ROUNDUP(D16,3),3)-ROUND(ROUNDDOWN(D16,3),3)))-IF((ROUND(ROUNDUP(D16,3),3)-ROUND(ROUNDDOWN(D16,3),3))=0,INDEX('Table 59B'!$D$10:$DT$420,MATCH(ROUND(ROUNDDOWN(D16,3),3),'Table 59B'!$C$10:$C$420,0),MATCH(ROUNDDOWN(C16*2,0)/2,'Table 59B'!$D$9:$DT$9,0)),INDEX('Table 59B'!$D$10:$DT$420,MATCH(ROUND(ROUNDUP(D16,3),3),'Table 59B'!$C$10:$C$420,0),MATCH(ROUNDDOWN(C16*2,0)/2,'Table 59B'!$D$9:$DT$9,0))-((INDEX('Table 59B'!$D$10:$DT$420,MATCH(ROUND(ROUNDUP(D16,3),3),'Table 59B'!$C$10:$C$420,0),MATCH(ROUNDDOWN(C16*2,0)/2,'Table 59B'!$D$9:$DT$9,0))-INDEX('Table 59B'!$D$10:$DT$420,MATCH(ROUND(ROUNDDOWN(D16,3),3),'Table 59B'!$C$10:$C$420,0),MATCH(ROUNDDOWN(C16*2,0)/2,'Table 59B'!$D$9:$DT$9,0)))*(ROUND(ROUNDUP(D16,3),3)-D16))/(ROUND(ROUNDUP(D16,3),3)-ROUND(ROUNDDOWN(D16,3),3))))/(ROUNDUP(C16*2,0)/2-ROUNDDOWN(C16*2,0)/2)),"") -> 0.83463 | F16: =IF('Shore Tank Calculations'!G16="","",'Shore Tank Calculations'!G16) -> 31.5 | G16: =IF(E16="","",E16) -> 0.83463 | H16: =IFERROR(IF((ROUNDUP(F16*2,0)/2-ROUNDDOWN(F16*2,0)/2)=0,IF((ROUND(ROUNDUP(G16,3),3)-ROUND(ROUNDDOWN(G16,3),3))=0,INDEX('Table 60B'!$D$10:$DT$420,MATCH(ROUND(ROUNDDOWN(G16,3),3),'Table 60B'!$C$10:$C$420,0),MATCH(ROUNDDOWN(F16*2,0)/2,'Table 60B'!$D$9:$DT$9,0)),INDEX('Table 60B'!$D$10:$DT$420,MATCH(ROUND(ROUNDUP(G16,3),3),'Table 60B'!$C$10:$C$420,0),MATCH(ROUNDDOWN(F16*2,0)/2,'Table 60B'!$D$9:$DT$9,0))-((INDEX('Table 60B'!$D$10:$DT$420,MATCH(ROUND(ROUNDUP(G16,3),3),'Table 60B'!$C$10:$C$420,0),MATCH(ROUNDDOWN(F16*2,0)/2,'Table 60B'!$D$9:$DT$9,0))-INDEX('Table 60B'!$D$10:$DT$420,MATCH(ROUND(ROUNDDOWN(G16,3),3),'Table 60B'!$C$10:$C$420,0),MATCH(ROUNDDOWN(F16*2,0)/2,'Table 60B'!$D$9:$DT$9,0)))*(ROUND(ROUNDUP(G16,3),3)-G16))/(ROUND(ROUNDUP(G16,3),3)-ROUND(ROUNDDOWN(G16,3),3))),IF((ROUND(ROUNDUP(G16,3),3)-ROUND(ROUNDDOWN(G16,3),3))=0,INDEX('Table 60B'!$D$10:$DT$420,MATCH(ROUND(ROUNDDOWN(G16,3),3),'Table 60B'!$C$10:$C$420,0),MATCH(ROUNDDOWN(F16*2,0)/2,'Table 60B'!$D$9:$DT$9,0)),INDEX('Table 60B'!$D$10:$DT$420,MATCH(ROUND(ROUNDUP(G16,3),3),'Table 60B'!$C$10:$C$420,0),MATCH(ROUNDDOWN(F16*2,0)/2,'Table 60B'!$D$9:$DT$9,0))-((INDEX('Table 60B'!$D$10:$DT$420,MATCH(ROUND(ROUNDUP(G16,3),3),'Table 60B'!$C$10:$C$420,0),MATCH(ROUNDDOWN(F16*2,0)/2,'Table 60B'!$D$9:$DT$9,0))-INDEX('Table 60B'!$D$10:$DT$420,MATCH(ROUND(ROUNDDOWN(G16,3),3),'Table 60B'!$C$10:$C$420,0),MATCH(ROUNDDOWN(F16*2,0)/2,'Table 60B'!$D$9:$DT$9,0)))*(ROUND(ROUNDUP(G16,3),3)-G16))/(ROUND(ROUNDUP(G16,3),3)-ROUND(ROUNDDOWN(G16,3),3)))+(F16-ROUNDDOWN(F16*2,0)/2)*(IF((ROUND(ROUNDUP(G16,3),3)-ROUND(ROUNDDOWN(G16,3),3))=0,INDEX('Table 60B'!$D$10:$DT$420,MATCH(ROUND(ROUNDDOWN(G16,3),3),'Table 60B'!$C$10:$C$420,0),MATCH(ROUNDUP(F16*2,0)/2,'Table 60B'!$D$9:$DT$9,0)),INDEX('Table 60B'!$D$10:$DT$420,MATCH(ROUND(ROUNDUP(G16,3),3),'Table 60B'!$C$10:$C$420,0),MATCH(ROUNDUP(F16*2,0)/2,'Table 60B'!$D$9:$DT$9,0))-((INDEX('Table 60B'!$D$10:$DT$420,MATCH(ROUND(ROUNDUP(G16,3),3),'Table 60B'!$C$10:$C$420,0),MATCH(ROUNDUP(F16*2,0)/2,'Table 60B'!$D$9:$DT$9,0))-INDEX('Table 60B'!$D$10:$DT$420,MATCH(ROUND(ROUNDDOWN(G16,3),3),'Table 60B'!$C$10:$C$420,0),MATCH(ROUNDUP(F16*2,0)/2,'Table 60B'!$D$9:$DT$9,0)))*(ROUND(ROUNDUP(G16,3),3)-G16))/(ROUND(ROUNDUP(G16,3),3)-ROUND(ROUNDDOWN(G16,3),3)))-IF((ROUND(ROUNDUP(G16,3),3)-ROUND(ROUNDDOWN(G16,3),3))=0,INDEX('Table 60B'!$D$10:$DT$420,MATCH(ROUND(ROUNDDOWN(G16,3),3),'Table 60B'!$C$10:$C$420,0),MATCH(ROUNDDOWN(F16*2,0)/2,'Table 60B'!$D$9:$DT$9,0)),INDEX('Table 60B'!$D$10:$DT$420,MATCH(ROUND(ROUNDUP(G16,3),3),'Table 60B'!$C$10:$C$420,0),MATCH(ROUNDDOWN(F16*2,0)/2,'Table 60B'!$D$9:$DT$9,0))-((INDEX('Table 60B'!$D$10:$DT$420,MATCH(ROUND(ROUNDUP(G16,3),3),'Table 60B'!$C$10:$C$420,0),MATCH(ROUNDDOWN(F16*2,0)/2,'Table 60B'!$D$9:$DT$9,0))-INDEX('Table 60B'!$D$10:$DT$420,MATCH(ROUND(ROUNDDOWN(G16,3),3),'Table 60B'!$C$10:$C$420,0),MATCH(ROUNDDOWN(F16*2,0)/2,'Table 60B'!$D$9:$DT$9,0)))*(ROUND(ROUNDUP(G16,3),3)-G16))/(ROUND(ROUNDUP(G16,3),3)-ROUND(ROUNDDOWN(G16,3),3))))/(ROUNDUP(F16*2,0)/2-ROUNDDOWN(F16*2,0)/2)),"") -> 0.9901926
A18: Tank 4 | B18: INITIAL | C18: ='Shore Tank Calculations'!H17 -> 0 | E18: =IFERROR(IF((ROUNDUP(C18*2,0)/2-ROUNDDOWN(C18*2,0)/2)=0,IF((ROUND(ROUNDUP(D18,3),3)-ROUND(ROUNDDOWN(D18,3),3))=0,INDEX('Table 59B'!$D$10:$DT$420,MATCH(ROUND(ROUNDDOWN(D18,3),3),'Table 59B'!$C$10:$C$420,0),MATCH(ROUNDDOWN(C18*2,0)/2,'Table 59B'!$D$9:$DT$9,0)),INDEX('Table 59B'!$D$10:$DT$420,MATCH(ROUND(ROUNDUP(D18,3),3),'Table 59B'!$C$10:$C$420,0),MATCH(ROUNDDOWN(C18*2,0)/2,'Table 59B'!$D$9:$DT$9,0))-((INDEX('Table 59B'!$D$10:$DT$420,MATCH(ROUND(ROUNDUP(D18,3),3),'Table 59B'!$C$10:$C$420,0),MATCH(ROUNDDOWN(C18*2,0)/2,'Table 59B'!$D$9:$DT$9,0))-INDEX('Table 59B'!$D$10:$DT$420,MATCH(ROUND(ROUNDDOWN(D18,3),3),'Table 59B'!$C$10:$C$420,0),MATCH(ROUNDDOWN(C18*2,0)/2,'Table 59B'!$D$9:$DT$9,0)))*(ROUND(ROUNDUP(D18,3),3)-D18))/(ROUND(ROUNDUP(D18,3),3)-ROUND(ROUNDDOWN(D18,3),3))),IF((ROUND(ROUNDUP(D18,3),3)-ROUND(ROUNDDOWN(D18,3),3))=0,INDEX('Table 59B'!$D$10:$DT$420,MATCH(ROUND(ROUNDDOWN(D18,3),3),'Table 59B'!$C$10:$C$420,0),MATCH(ROUNDDOWN(C18*2,0)/2,'Table 59B'!$D$9:$DT$9,0)),INDEX('Table 59B'!$D$10:$DT$420,MATCH(ROUND(ROUNDUP(D18,3),3),'Table 59B'!$C$10:$C$420,0),MATCH(ROUNDDOWN(C18*2,0)/2,'Table 59B'!$D$9:$DT$9,0))-((INDEX('Table 59B'!$D$10:$DT$420,MATCH(ROUND(ROUNDUP(D18,3),3),'Table 59B'!$C$10:$C$420,0),MATCH(ROUNDDOWN(C18*2,0)/2,'Table 59B'!$D$9:$DT$9,0))-INDEX('Table 59B'!$D$10:$DT$420,MATCH(ROUND(ROUNDDOWN(D18,3),3),'Table 59B'!$C$10:$C$420,0),MATCH(ROUNDDOWN(C18*2,0)/2,'Table 59B'!$D$9:$DT$9,0)))*(ROUND(ROUNDUP(D18,3),3)-D18))/(ROUND(ROUNDUP(D18,3),3)-ROUND(ROUNDDOWN(D18,3),3)))+(C18-ROUNDDOWN(C18*2,0)/2)*(IF((ROUND(ROUNDUP(D18,3),3)-ROUND(ROUNDDOWN(D18,3),3))=0,INDEX('Table 59B'!$D$10:$DT$420,MATCH(ROUND(ROUNDDOWN(D18,3),3),'Table 59B'!$C$10:$C$420,0),MATCH(ROUNDUP(C18*2,0)/2,'Table 59B'!$D$9:$DT$9,0)),INDEX('Table 59B'!$D$10:$DT$420,MATCH(ROUND(ROUNDUP(D18,3),3),'Table 59B'!$C$10:$C$420,0),MATCH(ROUNDUP(C18*2,0)/2,'Table 59B'!$D$9:$DT$9,0))-((INDEX('Table 59B'!$D$10:$DT$420,MATCH(ROUND(ROUNDUP(D18,3),3),'Table 59B'!$C$10:$C$420,0),MATCH(ROUNDUP(C18*2,0)/2,'Table 59B'!$D$9:$DT$9,0))-INDEX('Table 59B'!$D$10:$DT$420,MATCH(ROUND(ROUNDDOWN(D18,3),3),'Table 59B'!$C$10:$C$420,0),MATCH(ROUNDUP(C18*2,0)/2,'Table 59B'!$D$9:$DT$9,0)))*(ROUND(ROUNDUP(D18,3),3)-D18))/(ROUND(ROUNDUP(D18,3),3)-ROUND(ROUNDDOWN(D18,3),3)))-IF((ROUND(ROUNDUP(D18,3),3)-ROUND(ROUNDDOWN(D18,3),3))=0,INDEX('Table 59B'!$D$10:$DT$420,MATCH(ROUND(ROUNDDOWN(D18,3),3),'Table 59B'!$C$10:$C$420,0),MATCH(ROUNDDOWN(C18*2,0)/2,'Table 59B'!$D$9:$DT$9,0)),INDEX('Table 59B'!$D$10:$DT$420,MATCH(ROUND(ROUNDUP(D18,3),3),'Table 59B'!$C$10:$C$420,0),MATCH(ROUNDDOWN(C18*2,0)/2,'Table 59B'!$D$9:$DT$9,0))-((INDEX('Table 59B'!$D$10:$DT$420,MATCH(ROUND(ROUNDUP(D18,3),3),'Table 59B'!$C$10:$C$420,0),MATCH(ROUNDDOWN(C18*2,0)/2,'Table 59B'!$D$9:$DT$9,0))-INDEX('Table 59B'!$D$10:$DT$420,MATCH(ROUND(ROUNDDOWN(D18,3),3),'Table 59B'!$C$10:$C$420,0),MATCH(ROUNDDOWN(C18*2,0)/2,'Table 59B'!$D$9:$DT$9,0)))*(ROUND(ROUNDUP(D18,3),3)-D18))/(ROUND(ROUNDUP(D18,3),3)-ROUND(ROUNDDOWN(D18,3),3))))/(ROUNDUP(C18*2,0)/2-ROUNDDOWN(C18*2,0)/2)),"") | F18: =IF('Shore Tank Calculations'!H16="","",'Shore Tank Calculations'!H16) | G18: =IF(E18="","",E18) | H18: =IFERROR(IF((ROUNDUP(F18*2,0)/2-ROUNDDOWN(F18*2,0)/2)=0,IF((ROUND(ROUNDUP(G18,3),3)-ROUND(ROUNDDOWN(G18,3),3))=0,INDEX('Table 60B'!$D$10:$DT$420,MATCH(ROUND(ROUNDDOWN(G18,3),3),'Table 60B'!$C$10:$C$420,0),MATCH(ROUNDDOWN(F18*2,0)/2,'Table 60B'!$D$9:$DT$9,0)),INDEX('Table 60B'!$D$10:$DT$420,MATCH(ROUND(ROUNDUP(G18,3),3),'Table 60B'!$C$10:$C$420,0),MATCH(ROUNDDOWN(F18*2,0)/2,'Table 60B'!$D$9:$DT$9,0))-((INDEX('Table 60B'!$D$10:$DT$420,MATCH(ROUND(ROUNDUP(G18,3),3),'Table 60B'!$C$10:$C$420,0),MATCH(ROUNDDOWN(F18*2,0)/2,'Table 60B'!$D$9:$DT$9,0))-INDEX('Table 60B'!$D$10:$DT$420,MATCH(ROUND(ROUNDDOWN(G18,3),3),'Table 60B'!$C$10:$C$420,0),MATCH(ROUNDDOWN(F18*2,0)/2,'Table 60B'!$D$9:$DT$9,0)))*(ROUND(ROUNDUP(G18,3),3)-G18))/(ROUND(ROUNDUP(G18,3),3)-ROUND(ROUNDDOWN(G18,3),3))),IF((ROUND(ROUNDUP(G18,3),3)-ROUND(ROUNDDOWN(G18,3),3))=0,INDEX('Table 60B'!$D$10:$DT$420,MATCH(ROUND(ROUNDDOWN(G18,3),3),'Table 60B'!$C$10:$C$420,0),MATCH(ROUNDDOWN(F18*2,0)/2,'Table 60B'!$D$9:$DT$9,0)),INDEX('Table 60B'!$D$10:$DT$420,MATCH(ROUND(ROUNDUP(G18,3),3),'Table 60B'!$C$10:$C$420,0),MATCH(ROUNDDOWN(F18*2,0)/2,'Table 60B'!$D$9:$DT$9,0))-((INDEX('Table 60B'!$D$10:$DT$420,MATCH(ROUND(ROUNDUP(G18,3),3),'Table 60B'!$C$10:$C$420,0),MATCH(ROUNDDOWN(F18*2,0)/2,'Table 60B'!$D$9:$DT$9,0))-INDEX('Table 60B'!$D$10:$DT$420,MATCH(ROUND(ROUNDDOWN(G18,3),3),'Table 60B'!$C$10:$C$420,0),MATCH(ROUNDDOWN(F18*2,0)/2,'Table 60B'!$D$9:$DT$9,0)))*(ROUND(ROUNDUP(G18,3),3)-G18))/(ROUND(ROUNDUP(G18,3),3)-ROUND(ROUNDDOWN(G18,3),3)))+(F18-ROUNDDOWN(F18*2,0)/2)*(IF((ROUND(ROUNDUP(G18,3),3)-ROUND(ROUNDDOWN(G18,3),3))=0,INDEX('Table 60B'!$D$10:$DT$420,MATCH(ROUND(ROUNDDOWN(G18,3),3),'Table 60B'!$C$10:$C$420,0),MATCH(ROUNDUP(F18*2,0)/2,'Table 60B'!$D$9:$DT$9,0)),INDEX('Table 60B'!$D$10:$DT$420,MATCH(ROUND(ROUNDUP(G18,3),3),'Table 60B'!$C$10:$C$420,0),MATCH(ROUNDUP(F18*2,0)/2,'Table 60B'!$D$9:$DT$9,0))-((INDEX('Table 60B'!$D$10:$DT$420,MATCH(ROUND(ROUNDUP(G18,3),3),'Table 60B'!$C$10:$C$420,0),MATCH(ROUNDUP(F18*2,0)/2,'Table 60B'!$D$9:$DT$9,0))-INDEX('Table 60B'!$D$10:$DT$420,MATCH(ROUND(ROUNDDOWN(G18,3),3),'Table 60B'!$C$10:$C$420,0),MATCH(ROUNDUP(F18*2,0)/2,'Table 60B'!$D$9:$DT$9,0)))*(ROUND(ROUNDUP(G18,3),3)-G18))/(ROUND(ROUNDUP(G18,3),3)-ROUND(ROUNDDOWN(G18,3),3)))-IF((ROUND(ROUNDUP(G18,3),3)-ROUND(ROUNDDOWN(G18,3),3))=0,INDEX('Table 60B'!$D$10:$DT$420,MATCH(ROUND(ROUNDDOWN(G18,3),3),'Table 60B'!$C$10:$C$420,0),MATCH(ROUNDDOWN(F18*2,0)/2,'Table 60B'!$D$9:$DT$9,0)),INDEX('Table 60B'!$D$10:$DT$420,MATCH(ROUND(ROUNDUP(G18,3),3),'Table 60B'!$C$10:$C$420,0),MATCH(ROUNDDOWN(F18*2,0)/2,'Table 60B'!$D$9:$DT$9,0))-((INDEX('Table 60B'!$D$10:$DT$420,MATCH(ROUND(ROUNDUP(G18,3),3),'Table 60B'!$C$10:$C$420,0),MATCH(ROUNDDOWN(F18*2,0)/2,'Table 60B'!$D$9:$DT$9,0))-INDEX('Table 60B'!$D$10:$DT$420,MATCH(ROUND(ROUNDDOWN(G18,3),3),'Table 60B'!$C$10:$C$420,0),MATCH(ROUNDDOWN(F18*2,0)/2,'Table 60B'!$D$9:$DT$9,0)))*(ROUND(ROUNDUP(G18,3),3)-G18))/(ROUND(ROUNDUP(G18,3),3)-ROUND(ROUNDDOWN(G18,3),3))))/(ROUNDUP(F18*2,0)/2-ROUNDDOWN(F18*2,0)/2)),"") | I18: ← sample density corrected to 20°C via Table 59B; VCF from Table 60B
